Workbook

Sheet CHECKING
A3: StandardCommodityCode | B3: Translated Part Description (English)
A4: ALM- | B4: 5 275/14 RICAluminum Disc Alloy 99.5 275mm x 1.4mm Replacement Part [cite: 2] | C4: =_xlfn.TRANSLATE(B4,"it","yue") -> 5 275/14 RICAluminium Disc Alloy 99.5 275mm x 1.4mm 替換零件 [引用：2]
B5: 5 280/14 RICAluminum Disc Alloy 99.5 280mm x 1.4mm Replacement Part [cite: 2] | C5: =_xlfn.TRANSLATE(B5,"it","yue") -> 5 280/14 RICAluminium Disc Alloy 99.5 280mm x 1.4mm 替換零件 [引用：2]
B6: 5 315/14 RICAluminum Disc Alloy 99.5 315mm x 1.4mm Replacement Part [cite: 2] | C6: =_xlfn.TRANSLATE(B6,"it","yue") -> 5 315/14 RICAluminium Disc Alloy 99.5 315mm x 1.4mm 替換零件 [引用：2]
B7: 5 390/14 RICAluminum Disc Alloy 99.5 390mm x 1.4mm Replacement Part [cite: 2] | C7: =_xlfn.TRANSLATE(B7,"it","yue") -> 5 390/14 RICAluminium Disc Alloy 99.5 390mm x 1.4mm 替換零件 [引用：2]
B8: Aluminum Disc Alloy 1200 265mm x 2.2mm Replacement Part [cite: 1] | C8: =_xlfn.TRANSLATE(B8,"it","yue") -> 鋁碟合金 1200 265mm x 2.2mm 替換零件 [引用：1]
B9: Aluminum Disc Alloy 1200 410mm x 2.2mm Replacement Part [cite: 1] | C9: =_xlfn.TRANSLATE(B9,"it","yue") -> 鋁碟合金 1200 410mm x 2.2mm 替換零件 [引用：1]
B10: Aluminum Disc Alloy 4006 215mm x 3.6mm Replacement Part [cite: 1 2] | C10: =_xlfn.TRANSLATE(B10,"it","yue") -> 鋁碟合金 4006 215mm x 3.6mm 替換零件 [引用：1 2]
B11: Aluminum Disc Alloy 4006 225mm x 2.9mm Replacement Part [cite: 1] | C11: =_xlfn.TRANSLATE(B11,"it","yue") -> 鋁碟合金 4006 225mm x 2.9mm 替換零件 [引用：1]
B12: Aluminum Disc Alloy 4006 235mm x 2.9mm Replacement Part [cite: 1] | C12: =_xlfn.TRANSLATE(B12,"it","yue") -> 鋁碟合金 4006 235mm x 2.9mm 替換零件 [引用：1]
B13: Aluminum Disc Alloy 4006 235mm x 3.6mm Replacement Part [cite: 2] | C13: =_xlfn.TRANSLATE(B13,"it","yue") -> 鋁碟合金 4006 235mm x 3.6mm 替換零件 [引用：2]
B14: Aluminum Disc Alloy 4006 260mm x 3.6mm Replacement Part [cite: 2] | C14: =_xlfn.TRANSLATE(B14,"it","yue") -> 鋁碟合金 4006 260mm x 3.6mm 替換零件 [引用：2]
B15: Aluminum Disc Alloy 4006 265mm x 2.9mm Replacement Part [cite: 2] | C15: =_xlfn.TRANSLATE(B15,"it","yue") -> 鋁碟合金 4006 265mm x 2.9mm 替換零件 [引用：2]
B16: Aluminum Disc Alloy 4006 265mm x 3.2mm Replacement Part [cite: 2] | C16: =_xlfn.TRANSLATE(B16,"it","yue") -> 鋁碟合金 4006 265mm x 3.2mm 替換零件 [引用：2]
... B64: SHAPED AL. 99.5 324x324x26 ANNEALED | C64: =_xlfn.TRANSLATE(B64,"it","yue") -> 形狀 AL. 99.5 324x324x26 退火
A65: ALM- Total | C65: =_xlfn.TRANSLATE(B65,"it","yue")
A66: BAG- | B66: BAG TYPE 40X55 C/WARNING 35 LINGUE | C66: =_xlfn.TRANSLATE(B66,"it","yue") -> 袋型 40X55 C/警告 35種語言
B67: POLY BAG 26X40 PERFORATED RED PRINT MEYER HESTAN | C67: =_xlfn.TRANSLATE(B67,"it","yue") -> POLY BAG 26X40 PERFORATED RED PRINT MEYER HESTAN
B68: POLY BAG 26X40 PERFORATED REGENERATED 100% MADE IN | C68: =_xlfn.TRANSLATE(B68,"it","yue") -> POLY BAG 26X40 穿孔再生 100% 製造
B69: POLY BAG 40X50 PERFORATED RED PRINT MEYER HESTAN | C69: =_xlfn.TRANSLATE(B69,"it","yue") -> POLY BAG 40X50 PERFORATED RED PRINT MEYER HESTAN
B70: POLY BAG 40X50 PERFORATED REGENERATED 100% MADE IN | C70: =_xlfn.TRANSLATE(B70,"it","yue") -> POLY BAG 40X50 穿孔再生 100% 製造
B71: POLY BAG 40X60 PERFORATED RED PRINT MEYER HESTAN | C71: =_xlfn.TRANSLATE(B71,"it","yue") -> POLY BAG 40X60 穿孔紅色印花 MEYER HESTAN
B72: POLY BAG 40X60 PERFORATED REGENERATED 100% MADE IN | C72: =_xlfn.TRANSLATE(B72,"it","yue") -> POLY BAG 40X60 穿孔再生 100% 製造
B73: POLY BAG 40X80 PERFORATED REGENERATED 100% MADE IN | C73: =_xlfn.TRANSLATE(B73,"it","yue") -> POLY BAG 40X80 穿孔再生 100% 製造
B74: POLY BAG 50X54 PERFORATED RED PRINT MEYER HESTAN | C74: =_xlfn.TRANSLATE(B74,"it","yue") -> POLY BAG 50X54 穿孔紅色印花 MEYER HESTAN
B75: POLY BAG 50X54 PERFORATED REGENERATED 100% MADE IN | C75: =_xlfn.TRANSLATE(B75,"it","yue") -> POLY BAG 50X54 穿孔再生 100% 製造
B76: POLY BAG 50X70 PERFORATED RED PRINT MEYER HESTAN | C76: =_xlfn.TRANSLATE(B76,"it","yue") -> POLY BAG 50X70 PERFORATED RED PRINT MEYER HESTAN
B77: POLY BAG 50X70 PERFORATED REGENERATED 100% MADE IN | C77: =_xlfn.TRANSLATE(B77,"it","yue") -> POLY BAG 50X70 穿孔再生 100% 製造
B78: POLY BAG 60X60 PERFORATED RED PRINT MEYER HESTAN | C78: =_xlfn.TRANSLATE(B78,"it","yue") -> POLY BAG 60X60 PERFORATED RED PRINT MEYER HESTAN
... B89: Punched Bag 45x45 cm Punched on Both Sides | C89: =_xlfn.TRANSLATE(B89,"it","yue") -> 沙袋 45x45 厘米，兩面打孔
A90: BAG- Total | C90: =_xlfn.TRANSLATE(B90,"it","yue")
A91: BHRE | B91: LEAFLET MEHRZER PREMIUM DIA.BLACK IND.56X90 W/WIRE ELASTIC | C91: =_xlfn.TRANSLATE(B91,"it","yue") -> LEAFLET MEHRZER PREMIUM DIA. 黑色 IND.56X90 帶鋼絲
A92: BHRE Total | C92: =_xlfn.TRANSLATE(B92,"it","yue")
A93: BOX- | B93: BOX 0147/027 CM59X25,5X26 | C93: =_xlfn.TRANSLATE(B93,"it","yue") -> BOX 0147/027 CM59X25,5X26
B94: BOX 0195/007 CM48X32,5X27 | C94: =_xlfn.TRANSLATE(B94,"it","yue") -> BOX 0195/007 CM48X32,5X27
B95: BOX 0346/016*CM47X30,5X18 | C95: =_xlfn.TRANSLATE(B95,"it","yue") -> BOX 0346/016*CM47X30,5X18
B96: BOX 0567/000 CM39X38,5X19 | C96: =_xlfn.TRANSLATE(B96,"it","yue") -> BOX 0567/000 CM39X38,5X19
B97: BOX 0696/035*CM39X22,5X11 | C97: =_xlfn.TRANSLATE(B97,"it","yue") -> BOX 0696/035*CM39X22,5X11
B98: BOX 0709/065*CM45X28,5X12 | C98: =_xlfn.TRANSLATE(B98,"it","yue") -> BOX 0709/065*CM45X28,5X12
B99: BOX 1235/162 CM39X22,5X24 | C99: =_xlfn.TRANSLATE(B99,"it","yue") -> BOX 1235/162 CM39X22,5X24
...

Sheet Sheet1
A3: Row Labels | B3: Sum of Quantity | C3: Count of Quantity2
A4: Jan | B4: 1615590.4 | C4: 339
A5: Feb | B5: 1904686.6 | C5: 264
A6: Grand Total | B6: 3520277 | C6: 603

Sheet TVS order 28022026
A1: Purchase Order Number | B1: Purchase Order Date | C1: Purchase order issue date | D1: Vendor ID | E1: VendorName | F1: Vendor_Invoice_No | G1: Invoice Date | H1: REF_NO | I1: Item Code | J1: Part Description | K1: Commodity Italian | L1: Commodity English | M1: Division | N1: Quantity | O1: Unit | P1: PO_Price_PO CUR | Q1: PO UNIT PRICE PO_CUR | R1: Total_PO_Price_PO CUR | S1: Translated Part Description (English) | T1: Unified Commodity Code
A2: OF0040028 | B2: 45635.7 | D2: F600456 | E2: ALMESAN ALUMINYUM SAN.VE TIC. A.S | F2: 26AFF000045 | G2: 46081 | I2: 000040235029R | J2: DISCO AL.4006 235/29 RIC | K2: alluminio | L2: =VLOOKUP(K2,'COMM ITY- ENG'!A:B,2,FALSE) -> aluminium | N2: 1006 | O2: kg | Q2: =+R2/N2 -> 3.455 | R2: 3475.73 | S2: =IFERROR(VLOOKUP(J2,'DESC ITY - ENG'!B:C,2,FALSE),VLOOKUP(I2,'DESC ITY - ENG'!A:C,3,FALSE)) -> Aluminum Disc Alloy 4006 235mm x 2.9mm Replacement Part [cite: 1] | T2: =VLOOKUP(S2,'DESC ITY - ENG'!C:D,2,FALSE) -> ALM- | U2: =_xlfn.TRANSLATE(S2,"en","zh-cht") -> 鋁製圓盤合金 4006 235mm x 2.9mm 替換零件 [引用：1] | V2: =VLOOKUP(T2,'STANDARD COMM'!A:D,3,FALSE) -> Metal | W2: =_xlfn.TRANSLATE(O2,"it","en") -> kg
A3: OF0040028 | B3: 45635.7 | D3: F600456 | E3: ALMESAN ALUMINYUM SAN.VE TIC. A.S | F3: 26AFF000045 | G3: 46081 | I3: 000040265029R | J3: DISCO AL.4006 265/29 RIC | K3: alluminio | L3: =VLOOKUP(K3,'COMM ITY- ENG'!A:B,2,FALSE) -> aluminium | N3: 1050 | O3: kg | Q3: =+R3/N3 -> 3.455 | R3: 3627.75 | S3: =IFERROR(VLOOKUP(J3,'DESC ITY - ENG'!B:C,2,FALSE),VLOOKUP(I3,'DESC ITY - ENG'!A:C,3,FALSE)) -> Aluminum Disc Alloy 4006 265mm x 2.9mm Replacement Part [cite: 2] | T3: =VLOOKUP(S3,'DESC ITY - ENG'!C:D,2,FALSE) -> ALM- | U3: =_xlfn.TRANSLATE(S3,"en","zh-cht") -> 鋁製圓盤合金 4006 265mm x 2.9mm 替換零件 [引用：2] | V3: =VLOOKUP(T3,'STANDARD COMM'!A:D,3,FALSE) -> Metal | W3: =_xlfn.TRANSLATE(O3,"it","en") -> kg
A4: OF0040028 | B4: 45635.7 | D4: F600456 | E4: ALMESAN ALUMINYUM SAN.VE TIC. A.S | F4: 26AFF000045 | G4: 46081 | I4: 000040265032R | J4: DISCO AL.4006 265/32 RIC | K4: alluminio | L4: =VLOOKUP(K4,'COMM ITY- ENG'!A:B,2,FALSE) -> aluminium | N4: 3050 | O4: kg | Q4: =+R4/N4 -> 3.455 | R4: 10537.75 | S4: =IFERROR(VLOOKUP(J4,'DESC ITY - ENG'!B:C,2,FALSE),VLOOKUP(I4,'DESC ITY - ENG'!A:C,3,FALSE)) -> Aluminum Disc Alloy 4006 265mm x 3.2mm Replacement Part [cite: 2] | T4: =VLOOKUP(S4,'DESC ITY - ENG'!C:D,2,FALSE) -> ALM- | U4: =_xlfn.TRANSLATE(S4,"en","zh-cht") -> 鋁碟合金 4006 265mm x 3.2mm 替換零件 [引用：2] | V4: =VLOOKUP(T4,'STANDARD COMM'!A:D,3,FALSE) -> Metal | W4: =_xlfn.TRANSLATE(O4,"it","en") -> kg
A5: OF0040028 | B5: 45670.414 | D5: F600456 | E5: ALMESAN ALUMINYUM SAN.VE TIC. A.S | F5: 26AFF000045 | G5: 46081 | I5: 000040300029R | J5: DISCO AL.4006 300/29 RIC | K5: alluminio | L5: =VLOOKUP(K5,'COMM ITY- ENG'!A:B,2,FALSE) -> aluminium | N5: 3050 | O5: kg | Q5: =+R5/N5 -> 3.455 | R5: 10537.75 | S5: =IFERROR(VLOOKUP(J5,'DESC ITY - ENG'!B:C,2,FALSE),VLOOKUP(I5,'DESC ITY - ENG'!A:C,3,FALSE)) -> Aluminum Disc Alloy 4006 300mm x 2.9mm Replacement Part [cite: 2] | T5: =VLOOKUP(S5,'DESC ITY - ENG'!C:D,2,FALSE) -> ALM- | U5: =_xlfn.TRANSLATE(S5,"en","zh-cht") -> 鋁製圓盤合金 4006 300mm x 2.9mm 替換零件 [引用：2] | V5: =VLOOKUP(T5,'STANDARD COMM'!A:D,3,FALSE) -> Metal | W5: =_xlfn.TRANSLATE(O5,"it","en") -> kg
A6: OF0040028 | B6: 45642.711 | D6: F600456 | E6: ALMESAN ALUMINYUM SAN.VE TIC. A.S | F6: 26AFF000045 | G6: 46081 | I6: 000040325036R | J6: DISCO AL.4006 325/36 RIC | K6: alluminio | L6: =VLOOKUP(K6,'COMM ITY- ENG'!A:B,2,FALSE) -> aluminium | N6: 2100 | O6: kg | Q6: =+R6/N6 -> 3.455 | R6: 7255.5 | S6: =IFERROR(VLOOKUP(J6,'DESC ITY - ENG'!B:C,2,FALSE),VLOOKUP(I6,'DESC ITY - ENG'!A:C,3,FALSE)) -> Aluminum Disc Alloy 4006 325mm x 3.6mm Replacement Part [cite: 2] | T6: =VLOOKUP(S6,'DESC ITY - ENG'!C:D,2,FALSE) -> ALM- | U6: =_xlfn.TRANSLATE(S6,"en","zh-cht") -> 鋁碟合金 4006 325mm x 3.6mm 替換零件 [引用：2] | V6: =VLOOKUP(T6,'STANDARD COMM'!A:D,3,FALSE) -> Metal | W6: =_xlfn.TRANSLATE(O6,"it","en") -> kg
A7: OF0040028 | B7: 45629.658 | D7: F600456 | E7: ALMESAN ALUMINYUM SAN.VE TIC. A.S | F7: 26AFF000045 | G7: 46081 | I7: 000040335024R | J7: DISCO AL.4006 335/24 RIC | K7: alluminio | L7: =VLOOKUP(K7,'COMM ITY- ENG'!A:B,2,FALSE) -> aluminium | N7: 6100 | O7: kg | Q7: =+R7/N7 -> 3.455 | R7: 21075.5 | S7: =IFERROR(VLOOKUP(J7,'DESC ITY - ENG'!B:C,2,FALSE),VLOOKUP(I7,'DESC ITY - ENG'!A:C,3,FALSE)) -> Aluminum Disc Alloy 4006 335mm x 2.4mm Replacement Part [cite: 2] | T7: =VLOOKUP(S7,'DESC ITY - ENG'!C:D,2,FALSE) -> ALM- | U7: =_xlfn.TRANSLATE(S7,"en","zh-cht") -> 鋁製圓盤合金 4006 335mm x 2.4mm 替換零件 [引用：2] | V7: =VLOOKUP(T7,'STANDARD COMM'!A:D,3,FALSE) -> Metal | W7: =_xlfn.TRANSLATE(O7,"it","en") -> kg
A8: OF0040028 | B8: 45629.658 | D8: F600456 | E8: ALMESAN ALUMINYUM SAN.VE TIC. A.S | F8: 26AFF000045 | G8: 46081 | I8: 000040335029R | J8: DISCO AL.4006 335/29 RIC | K8: alluminio | L8: =VLOOKUP(K8,'COMM ITY- ENG'!A:B,2,FALSE) -> aluminium | N8: 950 | O8: kg | Q8: =+R8/N8 -> 3.455 | R8: 3282.25 | S8: =IFERROR(VLOOKUP(J8,'DESC ITY - ENG'!B:C,2,FALSE),VLOOKUP(I8,'DESC ITY - ENG'!A:C,3,FALSE)) -> Aluminum Disc Alloy 4006 335mm x 2.9mm Replacement Part [cite: 2] | T8: =VLOOKUP(S8,'DESC ITY - ENG'!C:D,2,FALSE) -> ALM- | U8: =_xlfn.TRANSLATE(S8,"en","zh-cht") -> 鋁製圓盤合金 4006 335mm x 2.9mm 替換零件 [引用：2] | V8: =VLOOKUP(T8,'STANDARD COMM'!A:D,3,FALSE) -> Metal | W8: =_xlfn.TRANSLATE(O8,"it","en") -> kg
A9: OF0040028 | B9: 45642.711 | D9: F600456 | E9: ALMESAN ALUMINYUM SAN.VE TIC. A.S | F9: 26AFF000045 | G9: 46081 | I9: 000040335032R | J9: DISCO AL.4006 335/32 RIC | K9: alluminio | L9: =VLOOKUP(K9,'COMM ITY- ENG'!A:B,2,FALSE) -> aluminium | N9: 1550 | O9: kg | Q9: =+R9/N9 -> 3.455 | R9: 5355.25 | S9: =IFERROR(VLOOKUP(J9,'DESC ITY - ENG'!B:C,2,FALSE),VLOOKUP(I9,'DESC ITY - ENG'!A:C,3,FALSE)) -> Aluminum Disc Alloy 4006 335mm x 3.2mm Replacement Part [cite: 2] | T9: =VLOOKUP(S9,'DESC ITY - ENG'!C:D,2,FALSE) -> ALM- | U9: =_xlfn.TRANSLATE(S9,"en","zh-cht") -> 鋁製圓盤合金 4006 335mm x 3.2mm 替換零件 [引用：2] | V9: =VLOOKUP(T9,'STANDARD COMM'!A:D,3,FALSE) -> Metal | W9: =_xlfn.TRANSLATE(O9,"it","en") -> kg
A10: OF0040028 | B10: 45607.417 | D10: F600456 | E10: ALMESAN ALUMINYUM SAN.VE TIC. A.S | F10: 26AFF000045 | G10: 46081 | I10: 000040355032R | J10: DISCO AL.4006 355/32 RIC | K10: alluminio | L10: =VLOOKUP(K10,'COMM ITY- ENG'!A:B,2,FALSE) -> aluminium | N10: 1526 | O10: kg | Q10: =+R10/N10 -> 3.455 | R10: 5272.33 | S10: =IFERROR(VLOOKUP(J10,'DESC ITY - ENG'!B:C,2,FALSE),VLOOKUP(I10,'DESC ITY - ENG'!A:C,3,FALSE)) -> Aluminum Disc Alloy 4006 355mm x 3.2mm Replacement Part [cite: 2] | T10: =VLOOKUP(S10,'DESC ITY - ENG'!C:D,2,FALSE) -> ALM- | U10: =_xlfn.TRANSLATE(S10,"en","zh-cht") -> 鋁製圓盤合金 4006 355mm x 3.2mm 替換零件 [引用：2] | V10: =VLOOKUP(T10,'STANDARD COMM'!A:D,3,FALSE) -> Metal | W10: =_xlfn.TRANSLATE(O10,"it","en") -> kg
A11: OF0040028 | B11: 45624.677 | D11: F600456 | E11: ALMESAN ALUMINYUM SAN.VE TIC. A.S | F11: 26AFF000045 | G11: 46081 | I11: 000040355036R | J11: DISCO AL.4006 355/36 RIC | K11: alluminio | L11: =VLOOKUP(K11,'COMM ITY- ENG'!A:B,2,FALSE) -> aluminium | N11: 2016 | O11: kg | Q11: =+R11/N11 -> 3.455 | R11: 6965.28 | S11: =IFERROR(VLOOKUP(J11,'DESC ITY - ENG'!B:C,2,FALSE),VLOOKUP(I11,'DESC ITY - ENG'!A:C,3,FALSE)) -> Aluminum Disc Alloy 4006 355mm x 3.6mm Replacement Part [cite: 2] | T11: =VLOOKUP(S11,'DESC ITY - ENG'!C:D,2,FALSE) -> ALM- | U11: =_xlfn.TRANSLATE(S11,"en","zh-cht") -> 鋁製圓盤合金 4006 355mm x 3.6mm 替換零件 [引用：2] | V11: =VLOOKUP(T11,'STANDARD COMM'!A:D,3,FALSE) -> Metal | W11: =_xlfn.TRANSLATE(O11,"it","en") -> kg
A12: OF0040028 | B12: 45642.711 | D12: F600456 | E12: ALMESAN ALUMINYUM SAN.VE TIC. A.S | F12: 26AFF000045 | G12: 46081 | I12: 000040370036R | J12: DISCO AL.4006 370/36 RIC | K12: alluminio | L12: =VLOOKUP(K12,'COMM ITY- ENG'!A:B,2,FALSE) -> aluminium | N12: 1550 | O12: kg | Q12: =+R12/N12 -> 3.455 | R12: 5355.25 | S12: =IFERROR(VLOOKUP(J12,'DESC ITY - ENG'!B:C,2,FALSE),VLOOKUP(I12,'DESC ITY - ENG'!A:C,3,FALSE)) -> Aluminum Disc Alloy 4006 370mm x 3.6mm Replacement Part [cite: 2] | T12: =VLOOKUP(S12,'DESC ITY - ENG'!C:D,2,FALSE) -> ALM- | U12: =_xlfn.TRANSLATE(S12,"en","zh-cht") -> 鋁製圓盤合金 4006 370mm x 3.6mm 替換零件 [引用：2] | V12: =VLOOKUP(T12,'STANDARD COMM'!A:D,3,FALSE) -> Metal | W12: =_xlfn.TRANSLATE(O12,"it","en") -> kg
A13: OF0040028 | B13: 45629.658 | D13: F600456 | E13: ALMESAN ALUMINYUM SAN.VE TIC. A.S | F13: 26AFF000045 | G13: 46081 | I13: 000040385036R | J13: DISCO AL.4006 385/36 RIC | K13: alluminio | L13: =VLOOKUP(K13,'COMM ITY- ENG'!A:B,2,FALSE) -> aluminium | N13: 1550 | O13: kg | Q13: =+R13/N13 -> 3.455 | R13: 5355.25 | S13: =IFERROR(VLOOKUP(J13,'DESC ITY - ENG'!B:C,2,FALSE),VLOOKUP(I13,'DESC ITY - ENG'!A:C,3,FALSE)) -> Aluminum Disc Alloy 4006 385mm x 3.6mm Replacement Part [cite: 2] | T13: =VLOOKUP(S13,'DESC ITY - ENG'!C:D,2,FALSE) -> ALM- | U13: =_xlfn.TRANSLATE(S13,"en","zh-cht") -> 鋁製圓盤合金 4006 385mm x 3.6mm 替換零件 [引用：2] | V13: =VLOOKUP(T13,'STANDARD COMM'!A:D,3,FALSE) -> Metal | W13: =_xlfn.TRANSLATE(O13,"it","en") -> kg
... A72: OF0039875 | B72: 45632.698 | D72: F600780 | E72: GULBAK BAKALIT METAL VE TEKSTIL SAN. ve TIC. LTD. STI | F72: 26AFF000056 | G72: 46081 | I72: 000281710001 | J72: MANICO AC.SOLE CORTO C/LOGO MC AISI 430 SABBIATO PAD.279 20 | K72: manigliame | L72: =VLOOKUP(K72,'COMM ITY- ENG'!A:B,2,FALSE) -> handles | N72: 5000 | O72: NR | Q72: =+R72/N72 -> 1.137 | R72: 5685 | S72: =IFERROR(VLOOKUP(J72,'DESC ITY - ENG'!B:C,2,FALSE),VLOOKUP(I72,'DESC ITY - ENG'!A:C,3,FALSE)) -> Steel Handle AC.SOLE Short w/Logo MC AISI 430 Pan 279-20 Sandblasted [cite: 4] | T72: =VLOOKUP(S72,'DESC ITY - ENG'!C:D,2,FALSE) -> SHDL | U72: =_xlfn.TRANSLATE(S72,"en","zh-cht") -> 鋼柄冷氣。鞋底短管附標誌 MC AISI 430 Pan 279-20 噴砂處理 [引用：4] | V72: =VLOOKUP(T72,'STANDARD COMM'!A:D,3,FALSE) -> Fittings | W72: =_xlfn.TRANSLATE(O72,"it","en") -> NR
B73: 45645.653 | D73: F600780 | E73: GULBAK BAKALIT METAL VE TEKSTIL SAN. ve TIC. LTD. STI | F73: 26AFF000056 | G73: 46081 | I73: 000281710001 | J73: MANICO AC.SOLE CORTO C/LOGO MC AISI 430 SABBIATO PAD.279 20 | K73: manigliame | L73: =VLOOKUP(K73,'COMM ITY- ENG'!A:B,2,FALSE) -> handles | N73: 2000 | O73: NR | Q73: =+R73/N73 -> 1.137 | R73: 2274 | S73: =IFERROR(VLOOKUP(J73,'DESC ITY - ENG'!B:C,2,FALSE),VLOOKUP(I73,'DESC ITY - ENG'!A:C,3,FALSE)) -> Steel Handle AC.SOLE Short w/Logo MC AISI 430 Pan 279-20 Sandblasted [cite: 4] | T73: =VLOOKUP(S73,'DESC ITY - ENG'!C:D,2,FALSE) -> SHDL | U73: =_xlfn.TRANSLATE(S73,"en","zh-cht") -> 鋼柄冷氣。鞋底短管附標誌 MC AISI 430 Pan 279-20 噴砂處理 [引用：4] | V73: =VLOOKUP(T73,'STANDARD COMM'!A:D,3,FALSE) -> Fittings | W73: =_xlfn.TRANSLATE(O73,"it","en") -> NR
A74: OF0039875 | B74: 45667.611 | D74: F600780 | E74: GULBAK BAKALIT METAL VE TEKSTIL SAN. ve TIC. LTD. STI | F74: 26AFF000056 | G74: 46081 | I74: 000281710003 | J74: MANICO AC.SOLE CORTO C/LOGO MC AISI 430 SABBIATO CAS.433 16 | K74: manigliame | L74: =VLOOKUP(K74,'COMM ITY- ENG'!A:B,2,FALSE) -> handles | N74: 10000 | O74: NR | Q74: =+R74/N74 -> 1.137 | R74: 11370 | S74: =IFERROR(VLOOKUP(J74,'DESC ITY - ENG'!B:C,2,FALSE),VLOOKUP(I74,'DESC ITY - ENG'!A:C,3,FALSE)) -> Steel Handle AC.SOLE Short w/Logo MC AISI 430 Casserole 433-16 Sandblasted [cite: 4] | T74: =VLOOKUP(S74,'DESC ITY - ENG'!C:D,2,FALSE) -> SHDL | U74: =_xlfn.TRANSLATE(S74,"en","zh-cht") -> 鋼柄冷氣。獨角短褲附標誌 MC AISI 430 砂鍋 433-16 砂磨 [引用：4] | V74: =VLOOKUP(T74,'STANDARD COMM'!A:D,3,FALSE) -> Fittings | W74: =_xlfn.TRANSLATE(O74,"it","en") -> NR
B75: 45635.558 | D75: F600780 | E75: GULBAK BAKALIT METAL VE TEKSTIL SAN. ve TIC. LTD. STI | F75: 26AFF000056 | G75: 46081 | I75: 000281710003 | J75: MANICO AC.SOLE CORTO C/LOGO MC AISI 430 SABBIATO CAS.433 16 | K75: manigliame | L75: =VLOOKUP(K75,'COMM ITY- ENG'!A:B,2,FALSE) -> handles | N75: 6000 | O75: NR | Q75: =+R75/N75 -> 1.137 | R75: 6822 | S75: =IFERROR(VLOOKUP(J75,'DESC ITY - ENG'!B:C,2,FALSE),VLOOKUP(I75,'DESC ITY - ENG'!A:C,3,FALSE)) -> Steel Handle AC.SOLE Short w/Logo MC AISI 430 Casserole 433-16 Sandblasted [cite: 4] | T75: =VLOOKUP(S75,'DESC ITY - ENG'!C:D,2,FALSE) -> SHDL | U75: =_xlfn.TRANSLATE(S75,"en","zh-cht") -> 鋼柄冷氣。獨角短褲附標誌 MC AISI 430 砂鍋 433-16 砂磨 [引用：4] | V75: =VLOOKUP(T75,'STANDARD COMM'!A:D,3,FALSE) -> Fittings | W75: =_xlfn.TRANSLATE(O75,"it","en") -> NR
A76: OF0039875 | B76: 45635.558 | D76: F600780 | E76: GULBAK BAKALIT METAL VE TEKSTIL SAN. ve TIC. LTD. STI | F76: 26AFF000056 | G76: 46081 | I76: 000281710005 | J76: MANICO AC.SOLE LUNGO C/LOGO MC AISI 430 SABBIATO PAD.279 30 | K76: manigliame | L76: =VLOOKUP(K76,'COMM ITY- ENG'!A:B,2,FALSE) -> handles | N76: 20000 | O76: NR | Q76: =+R76/N76 -> 1.227 | R76: 24540 | S76: =IFERROR(VLOOKUP(J76,'DESC ITY - ENG'!B:C,2,FALSE),VLOOKUP(I76,'DESC ITY - ENG'!A:C,3,FALSE)) -> Steel Handle AC.SOLE Long w/Logo MC AISI 430 Pan 279-30 Sandblasted [cite: 4] | T76: =VLOOKUP(S76,'DESC ITY - ENG'!C:D,2,FALSE) -> HDL- | U76: =_xlfn.TRANSLATE(S76,"en","zh-cht") -> 鋼柄冷氣。鞋底長款，附 MC 標誌 AISI 430 Pan 279-30 噴砂處理 [引用：4] | V76: =VLOOKUP(T76,'STANDARD COMM'!A:D,3,FALSE) -> Fittings | W76: =_xlfn.TRANSLATE(O76,"it","en") -> NR
B77: 45666.665 | D77: F600780 | E77: GULBAK BAKALIT METAL VE TEKSTIL SAN. ve TIC. LTD. STI | F77: 26AFF000056 | G77: 46081 | I77: 000281710005 | J77: MANICO AC.SOLE LUNGO C/LOGO MC AISI 430 SABBIATO PAD.279 30 | K77: manigliame | L77: =VLOOKUP(K77,'COMM ITY- ENG'!A:B,2,FALSE) -> handles | N77: 15000 | O77: NR | Q77: =+R77/N77 -> 1.227 | R77: 18405 | S77: =IFERROR(VLOOKUP(J77,'DESC ITY - ENG'!B:C,2,FALSE),VLOOKUP(I77,'DESC ITY - ENG'!A:C,3,FALSE)) -> Steel Handle AC.SOLE Long w/Logo MC AISI 430 Pan 279-30 Sandblasted [cite: 4] | T77: =VLOOKUP(S77,'DESC ITY - ENG'!C:D,2,FALSE) -> HDL- | U77: =_xlfn.TRANSLATE(S77,"en","zh-cht") -> 鋼柄冷氣。鞋底長款，附 MC 標誌 AISI 430 Pan 279-30 噴砂處理 [引用：4] | V77: =VLOOKUP(T77,'STANDARD COMM'!A:D,3,FALSE) -> Fittings | W77: =_xlfn.TRANSLATE(O77,"it","en") -> NR
A78: OF0039114 | B78: 45674.484 | D78: F506075 | E78: HEBEI BOZHENG GLASSWORK CO.LTD. | F78: 26AFF000036 | G78: 46081 | I78: 000700042002 | J78: COP.VET.20 PIAT.BOR./SF.VAP.SIL.STD | K78: accessori finiti | L78: =VLOOKUP(K78,'COMM ITY- ENG'!A:B,2,FALSE) -> finished accessories | N78: 4020 | O78: NR | Q78: =+R78/N78 -> 0.88849254 | R78: 3571.74 | S78: =IFERROR(VLOOKUP(J78,'DESC ITY - ENG'!B:C,2,FALSE),VLOOKUP(I78,'DESC ITY - ENG'!A:C,3,FALSE)) -> Glass Lid 20cm Flat Rim Silicone Steam Vent StandardGlass Lid | T78: =VLOOKUP(S78,'DESC ITY - ENG'!C:D,2,FALSE) -> GLID | U78: =_xlfn.TRANSLATE(S78,"en","zh-cht") -> 玻璃蓋 20公分平緣矽膠蒸汽通風口 標準玻璃蓋 | V78: =VLOOKUP(T78,'STANDARD COMM'!A:D,3,FALSE) -> Lid | W78: =_xlfn.TRANSLATE(O78,"it","en") -> NR
A79: OF0039114 | B79: 45667.693 | D79: F506075 | E79: HEBEI BOZHENG GLASSWORK CO.LTD. | F79: 26AFF000036 | G79: 46081 | I79: 000700044002 | J79: COP.VET.24 PIAT.BOR./SF.VAP.SIL.STD | K79: accessori finiti | L79: =VLOOKUP(K79,'COMM ITY- ENG'!A:B,2,FALSE) -> finished accessories | N79: 3000 | O79: NR | Q79: =+R79/N79 -> 1.0316033 | R79: 3094.81 | S79: =IFERROR(VLOOKUP(J79,'DESC ITY - ENG'!B:C,2,FALSE),VLOOKUP(I79,'DESC ITY - ENG'!A:C,3,FALSE)) -> Glass Lid 24cm Flat Rim Silicone Steam Vent StandardGlass Lid | T79: =VLOOKUP(S79,'DESC ITY - ENG'!C:D,2,FALSE) -> GLID | U79: =_xlfn.TRANSLATE(S79,"en","zh-cht") -> 玻璃蓋 24公分平緣矽膠蒸汽排氣口 標準玻璃蓋 | V79: =VLOOKUP(T79,'STANDARD COMM'!A:D,3,FALSE) -> Lid | W79: =_xlfn.TRANSLATE(O79,"it","en") -> NR
A80: OF0039114 | B80: 45667.693 | D80: F506075 | E80: HEBEI BOZHENG GLASSWORK CO.LTD. | F80: 26AFF000036 | G80: 46081 | I80: 000700046002 | J80: COP.VET.28 PIAT.BOR./SF.VAP.SIL.STD | K80: accessori finiti | L80: =VLOOKUP(K80,'COMM ITY- ENG'!A:B,2,FALSE) -> finished accessories | N80: 3000 | O80: NR | Q80: =+R80/N80 -> 1.1772733 | R80: 3531.82 | S80: =IFERROR(VLOOKUP(J80,'DESC ITY - ENG'!B:C,2,FALSE),VLOOKUP(I80,'DESC ITY - ENG'!A:C,3,FALSE)) -> Glass Lid 28cm Flat Rim Silicone Steam Vent StandardGlass Lid | T80: =VLOOKUP(S80,'DESC ITY - ENG'!C:D,2,FALSE) -> GLID | U80: =_xlfn.TRANSLATE(S80,"en","zh-cht") -> 玻璃蓋 28公分平緣矽膠蒸汽通風口 標準玻璃蓋 | V80: =VLOOKUP(T80,'STANDARD COMM'!A:D,3,FALSE) -> Lid | W80: =_xlfn.TRANSLATE(O80,"it","en") -> NR
A81: OF0039114 | B81: 45629.658 | D81: F506075 | E81: HEBEI BOZHENG GLASSWORK CO.LTD. | F81: 26AFF000036 | G81: 46081 | I81: 000700050002 | J81: COP.VET.32 PIAT.BOR./SF.VAP.SIL.STD | K81: accessori finiti | L81: =VLOOKUP(K81,'COMM ITY- ENG'!A:B,2,FALSE) -> finished accessories | N81: 1005 | O81: NR | Q81: =+R81/N81 -> 1.396209 | R81: 1403.19 | S81: =IFERROR(VLOOKUP(J81,'DESC ITY - ENG'!B:C,2,FALSE),VLOOKUP(I81,'DESC ITY - ENG'!A:C,3,FALSE)) -> Glass Lid 32cm Flat Rim Silicone Steam Vent StandardGlass Lid | T81: =VLOOKUP(S81,'DESC ITY - ENG'!C:D,2,FALSE) -> GLID | U81: =_xlfn.TRANSLATE(S81,"en","zh-cht") -> 玻璃蓋 32公分平緣矽膠蒸汽通風口 標準玻璃蓋 | V81: =VLOOKUP(T81,'STANDARD COMM'!A:D,3,FALSE) -> Lid | W81: =_xlfn.TRANSLATE(O81,"it","en") -> NR
A82: OF0039114 | B82: 45642.711 | D82: F506075 | E82: HEBEI BOZHENG GLASSWORK CO.LTD. | F82: 26AFF000036 | G82: 46081 | I82: 000700704005 | J82: COP.VET 18 C/BORDO AC.304 C/F.VAP.A | K82: accessori finiti | L82: =VLOOKUP(K82,'COMM ITY- ENG'!A:B,2,FALSE) -> finished accessories | N82: 5010 | O82: NR | Q82: =+R82/N82 -> 0.32626347 | R82: 1634.58 | S82: =IFERROR(VLOOKUP(J82,'DESC ITY - ENG'!B:C,2,FALSE),VLOOKUP(I82,'DESC ITY - ENG'!A:C,3,FALSE)) -> Glass Lid 18cm SS304 Rim with Steam Vent Type AGlass Lid | T82: =VLOOKUP(S82,'DESC ITY - ENG'!C:D,2,FALSE) -> GLID | U82: =_xlfn.TRANSLATE(S82,"en","zh-cht") -> 玻璃蓋 18公分 SS304 輪圈，配有蒸汽通風型玻璃蓋 | V82: =VLOOKUP(T82,'STANDARD COMM'!A:D,3,FALSE) -> Lid | W82: =_xlfn.TRANSLATE(O82,"it","en") -> NR
A83: OF0039114 | B83: 45607.417 | D83: F506075 | E83: HEBEI BOZHENG GLASSWORK CO.LTD. | F83: 26AFF000036 | G83: 46081 | I83: 000700705005 | J83: COP.VET 20 C/BORDO AC.304 C/F.VAP.A | K83: accessori finiti | L83: =VLOOKUP(K83,'COMM ITY- ENG'!A:B,2,FALSE) -> finished accessories | N83: 4020 | O83: NR | Q83: =+R83/N83 -> 0.36289303 | R83: 1458.83 | S83: =IFERROR(VLOOKUP(J83,'DESC ITY - ENG'!B:C,2,FALSE),VLOOKUP(I83,'DESC ITY - ENG'!A:C,3,FALSE)) -> Glass Lid 20cm SS304 Rim with Steam Vent Type AGlass Lid | T83: =VLOOKUP(S83,'DESC ITY - ENG'!C:D,2,FALSE) -> GLID | U83: =_xlfn.TRANSLATE(S83,"en","zh-cht") -> 玻璃蓋 20公分 SS304 輪緣，配有蒸汽通風式 AGlass 蓋 | V83: =VLOOKUP(T83,'STANDARD COMM'!A:D,3,FALSE) -> Lid | W83: =_xlfn.TRANSLATE(O83,"it","en") -> NR
A84: OF0039114 | B84: 45629.658 | D84: F506075 | E84: HEBEI BOZHENG GLASSWORK CO.LTD. | F84: 26AFF000036 | G84: 46081 | I84: 000700707006 | J84: COP.VET 24 C/BORDO AC.304 C/F.VAP.A | K84: accessori finiti | L84: =VLOOKUP(K84,'COMM ITY- ENG'!A:B,2,FALSE) -> finished accessories | N84: 16000 | O84: NR | Q84: =+R84/N84 -> 0.43615312 | R84: 6978.45 | S84: =IFERROR(VLOOKUP(J84,'DESC ITY - ENG'!B:C,2,FALSE),VLOOKUP(I84,'DESC ITY - ENG'!A:C,3,FALSE)) -> Glass Lid 24cm SS304 Rim with Steam Vent Type AGlass Lid | T84: =VLOOKUP(S84,'DESC ITY - ENG'!C:D,2,FALSE) -> GLID | U84: =_xlfn.TRANSLATE(S84,"en","zh-cht") -> 玻璃蓋 24cm SS304 輪緣，配有蒸汽通風型玻璃蓋 | V84: =VLOOKUP(T84,'STANDARD COMM'!A:D,3,FALSE) -> Lid | W84: =_xlfn.TRANSLATE(O84,"it","en") -> NR
A85: OF0039114 | B85: 45642.711 | D85: F506075 | E85: HEBEI BOZHENG GLASSWORK CO.LTD. | F85: 26AFF000036 | G85: 46081 | I85: 000700708005 | J85: COP.VET 26 C/BORDO AC.304 C/F.VAP.A | K85: accessori finiti | L85: =VLOOKUP(K85,'COMM ITY- ENG'!A:B,2,FALSE) -> finished accessories | N85: 2000 | O85: NR | Q85: =+R85/N85 -> 0.49834 | R85: 996.68 | S85: =IFERROR(VLOOKUP(J85,'DESC ITY - ENG'!B:C,2,FALSE),VLOOKUP(I85,'DESC ITY - ENG'!A:C,3,FALSE)) -> Glass Lid 26cm SS304 Rim with Steam Vent Type AGlass Lid | T85: =VLOOKUP(S85,'DESC ITY - ENG'!C:D,2,FALSE) -> GLID | U85: =_xlfn.TRANSLATE(S85,"en","zh-cht") -> 玻璃蓋 26cm SS304 輪緣，配有蒸汽通風型玻璃蓋 | V85: =VLOOKUP(T85,'STANDARD COMM'!A:D,3,FALSE) -> Lid | W85: =_xlfn.TRANSLATE(O85,"it","en") -> NR
A86: OF0039114 | B86: 45629.658 | D86: F506075 | E86: HEBEI BOZHENG GLASSWORK CO.LTD. | F86: 26AFF000036 | G86: 46081 | I86: 000700709005 | J86: COP.VET.28 C/BORDO AC.304.C/F.VAP.A | K86: accessori finiti | L86: =VLOOKUP(K86,'COMM ITY- ENG'!A:B,2,FALSE) -> finished accessories | N86: 7000 | O86: NR | Q86: =+R86/N86 -> 0.54093143 | R86: 3786.52 | S86: =IFERROR(VLOOKUP(J86,'DESC ITY - ENG'!B:C,2,FALSE),VLOOKUP(I86,'DESC ITY - ENG'!A:C,3,FALSE)) -> Glass Lid 28cm SS304 Rim with Steam Vent Type AGlass Lid | T86: =VLOOKUP(S86,'DESC ITY - ENG'!C:D,2,FALSE) -> GLID | U86: =_xlfn.TRANSLATE(S86,"en","zh-cht") -> 玻璃蓋 28cm SS304 輪圈，配有蒸汽通風型玻璃蓋 | V86: =VLOOKUP(T86,'STANDARD COMM'!A:D,3,FALSE) -> Lid | W86: =_xlfn.TRANSLATE(O86,"it","en") -> NR
A87: OF0039114 | B87: 45642.711 | D87: F506075 | E87: HEBEI BOZHENG GLASSWORK CO.LTD. | F87: 26AFF000036 | G87: 46081 | I87: 000700710005 | J87: COP.VET.30 C/BORDO AC.304.C/F.VAP.A | K87: accessori finiti | L87: =VLOOKUP(K87,'COMM ITY- ENG'!A:B,2,FALSE) -> finished accessories | N87: 1005 | O87: NR | Q87: =+R87/N87 -> 0.61930348 | R87: 622.4 | S87: =IFERROR(VLOOKUP(J87,'DESC ITY - ENG'!B:C,2,FALSE),VLOOKUP(I87,'DESC ITY - ENG'!A:C,3,FALSE)) -> Glass Lid 30cm SS304 Rim with Steam Vent Type AGlass Lid | T87: =VLOOKUP(S87,'DESC ITY - ENG'!C:D,2,FALSE) -> GLID | U87: =_xlfn.TRANSLATE(S87,"en","zh-cht") -> 玻璃蓋 30cm SS304 輪圈，配有蒸汽通風型 AGlass 蓋 | V87: =VLOOKUP(T87,'STANDARD COMM'!A:D,3,FALSE) -> Lid | W87: =_xlfn.TRANSLATE(O87,"it","en") -> NR
A88: OF0040239 | B88: 45583.663 | D88: F502408 | E88: ILAG INDUSTRIELACK AG | F88: 26AFF000050 | G88: 46081 | I88: 003040104002 | J88: PRIMER 1213-009 DURIT PROTECT PRO BLACK | K88: prodotti chimici | L88: =VLOOKUP(K88,'COMM ITY- ENG'!A:B,2,FALSE) -> chemical products | N88: 502 | O88: kg | Q88: =+R88/N88 -> 16.2 | R88: 8132.4 | S88: =IFERROR(VLOOKUP(J88,'DESC ITY - ENG'!B:C,2,FALSE),VLOOKUP(I88,'DESC ITY - ENG'!A:C,3,FALSE)) -> Coating Durit Protect Pro Black Primer 1213-009 | T88: =VLOOKUP(S88,'DESC ITY - ENG'!C:D,2,FALSE) -> INM- | U88: =_xlfn.TRANSLATE(S88,"en","zh-cht") -> 塗層 Durit Protect Pro 黑色底漆 1213-009 | V88: =VLOOKUP(T88,'STANDARD COMM'!A:D,3,FALSE) -> Coating | W88: =_xlfn.TRANSLATE(O88,"it","en") -> kg
A89: OF0040035 | B89: 45666.5 | D89: F600467 | E89: IMF INDUSTRIE MARCHIGIANE FILTRI SRL | F89: 26AFI000496 | G89: 46081 | I89: 0002A0127TS4 | J89: DISCO AC.127/040 C/F 3MM+TAGLI STRETTI+FORO CENTRALE 38mm | K89: acciaio | L89: =VLOOKUP(K89,'COMM ITY- ENG'!A:B,2,FALSE) -> steel | N89: 9700 | O89: NR | Q89: =+R89/N89 -> 0.1449 | R89: 1405.53 | S89: =IFERROR(VLOOKUP(J89,'DESC ITY - ENG'!B:C,2,FALSE),VLOOKUP(I89,'DESC ITY - ENG'!A:C,3,FALSE)) -> Steel Disc AC.127/040 3.0mm Narrow Slots + 38mm Center Hole [cite: 1] | T89: =VLOOKUP(S89,'DESC ITY - ENG'!C:D,2,FALSE) -> SM-- | U89: =_xlfn.TRANSLATE(S89,"en","zh-cht") -> 鋼盤 AC.127/040 3.0mm 窄槽 + 38mm 中心孔 [引用：1] | V89: =VLOOKUP(T89,'STANDARD COMM'!A:D,3,FALSE) -> Metal | W89: =_xlfn.TRANSLATE(O89,"it","en") -> NR
... A135: OF0039874 | B135: 45642.711 | D135: F600732 | E135: MUTLU METAL DIS TICARET LTD.STI | F135: 26AFF000046 | G135: 46081 | I135: 000281710002 | J135: MANICO AC.SOLE CORTO C/LOGO MC AISI 430 SABBIATO PAD.279 24 | K135: manigliame | L135: =VLOOKUP(K135,'COMM ITY- ENG'!A:B,2,FALSE) -> handles | N135: 10000 | O135: NR | Q135: =+R135/N135 -> 1.19 | R135: 11900 | S135: =IFERROR(VLOOKUP(J135,'DESC ITY - ENG'!B:C,2,FALSE),VLOOKUP(I135,'DESC ITY - ENG'!A:C,3,FALSE)) -> Steel Handle AC.SOLE Short w/Logo MC AISI 430 Pan 279-24 Sandblasted [cite: 4] | T135: =VLOOKUP(S135,'DESC ITY - ENG'!C:D,2,FALSE) -> SHDL | U135: =_xlfn.TRANSLATE(S135,"en","zh-cht") -> 鋼柄冷氣。獨短帶標誌 MC AISI 430 Pan 279-24 噴砂處理 [引用：4] | V135: =VLOOKUP(T135,'STANDARD COMM'!A:D,3,FALSE) -> Fittings | W135: =_xlfn.TRANSLATE(O135,"it","en") -> NR
B136: 45642.711 | D136: F600732 | E136: MUTLU METAL DIS TICARET LTD.STI | F136: 26AFF000046 | G136: 46081 | I136: 000281710002 | J136: MANICO AC.SOLE CORTO C/LOGO MC AISI 430 SABBIATO PAD.279 24 | K136: manigliame | L136: =VLOOKUP(K136,'COMM ITY- ENG'!A:B,2,FALSE) -> handles | N136: 9292 | O136: NR | Q136: =+R136/N136 -> 1.19 | R136: 11057.48 | S136: =IFERROR(VLOOKUP(J136,'DESC ITY - ENG'!B:C,2,FALSE),VLOOKUP(I136,'DESC ITY - ENG'!A:C,3,FALSE)) -> Steel Handle AC.SOLE Short w/Logo MC AISI 430 Pan 279-24 Sandblasted [cite: 4] | T136: =VLOOKUP(S136,'DESC ITY - ENG'!C:D,2,FALSE) -> SHDL | U136: =_xlfn.TRANSLATE(S136,"en","zh-cht") -> 鋼柄冷氣。獨短帶標誌 MC AISI 430 Pan 279-24 噴砂處理 [引用：4] | V136: =VLOOKUP(T136,'STANDARD COMM'!A:D,3,FALSE) -> Fittings | W136: =_xlfn.TRANSLATE(O136,"it","en") -> NR
A137: OF0039874 | B137: 45629.658 | D137: F600732 | E137: MUTLU METAL DIS TICARET LTD.STI | F137: 26AFF000046 | G137: 46081 | I137: 000281710006 | J137: MANICO AC.SOLE LUNGO C/LOGO MC AISI 430 SABBIATO TEG.379 26 | K137: manigliame | L137: =VLOOKUP(K137,'COMM ITY- ENG'!A:B,2,FALSE) -> handles | N137: 10010 | O137: NR | Q137: =+R137/N137 -> 1.29 | R137: 12912.9 | S137: =IFERROR(VLOOKUP(J137,'DESC ITY - ENG'!B:C,2,FALSE),VLOOKUP(I137,'DESC ITY - ENG'!A:C,3,FALSE)) -> Steel Handle AC.SOLE Long w/Logo MC AISI 430 Skillet 379-26 Sandblasted [cite: 4 5] | T137: =VLOOKUP(S137,'DESC ITY - ENG'!C:D,2,FALSE) -> HDL- | U137: =_xlfn.TRANSLATE(S137,"en","zh-cht") -> 鋼柄冷氣。鞋底長款，配 MC 標誌 MC AISI 430 Skillet 379-26 噴砂 [引用：4 5] | V137: =VLOOKUP(T137,'STANDARD COMM'!A:D,3,FALSE) -> Fittings | W137: =_xlfn.TRANSLATE(O137,"it","en") -> NR
A138: OF0039874 | B138: 45642.711 | D138: F600732 | E138: MUTLU METAL DIS TICARET LTD.STI | F138: 26AFF000046 | G138: 46081 | I138: 000320380001 | J138: POMOLO AC.SOLE C/LOGO MC AISI 430 SABBIATO | K138: manigliame | L138: =VLOOKUP(K138,'COMM ITY- ENG'!A:B,2,FALSE) -> handles | N138: 3960 | O138: NR | Q138: =+R138/N138 -> 1.15 | R138: 4554 | S138: =IFERROR(VLOOKUP(J138,'DESC ITY - ENG'!B:C,2,FALSE),VLOOKUP(I138,'DESC ITY - ENG'!A:C,3,FALSE)) -> Steel Knob AC.SOLE w/Logo MC AISI 430 Sandblasted [cite: 5] | T138: =VLOOKUP(S138,'DESC ITY - ENG'!C:D,2,FALSE) -> KNOB | U138: =_xlfn.TRANSLATE(S138,"en","zh-cht") -> 鋼旋鈕冷氣。唯一配件 MC 標誌 AISI 430 砂燒 [引用：5] | V138: =VLOOKUP(T138,'STANDARD COMM'!A:D,3,FALSE) -> Fittings | W138: =_xlfn.TRANSLATE(O138,"it","en") -> NR
A139: OF0039874 | B139: 45601.461 | D139: F600732 | E139: MUTLU METAL DIS TICARET LTD.STI | F139: 26AFF000052 | G139: 46081 | I139: 000281710002 | J139: MANICO AC.SOLE CORTO C/LOGO MC AISI 430 SABBIATO PAD.279 24 | K139: manigliame | L139: =VLOOKUP(K139,'COMM ITY- ENG'!A:B,2,FALSE) -> handles | N139: 708 | O139: NR | Q139: =+R139/N139 -> 1.19 | R139: 842.52 | S139: =IFERROR(VLOOKUP(J139,'DESC ITY - ENG'!B:C,2,FALSE),VLOOKUP(I139,'DESC ITY - ENG'!A:C,3,FALSE)) -> Steel Handle AC.SOLE Short w/Logo MC AISI 430 Pan 279-24 Sandblasted [cite: 4] | T139: =VLOOKUP(S139,'DESC ITY - ENG'!C:D,2,FALSE) -> SHDL | U139: =_xlfn.TRANSLATE(S139,"en","zh-cht") -> 鋼柄冷氣。獨短帶標誌 MC AISI 430 Pan 279-24 噴砂處理 [引用：4] | V139: =VLOOKUP(T139,'STANDARD COMM'!A:D,3,FALSE) -> Fittings | W139: =_xlfn.TRANSLATE(O139,"it","en") -> NR
A140: OF0040251 | B140: 45601.461 | D140: F600732 | E140: MUTLU METAL DIS TICARET LTD.STI | F140: 26AFF000052 | G140: 46081 | I140: 000281710002 | J140: MANICO AC.SOLE CORTO C/LOGO MC AISI 430 SABBIATO PAD.279 24 | K140: manigliame | L140: =VLOOKUP(K140,'COMM ITY- ENG'!A:B,2,FALSE) -> handles | N140: 3387 | O140: NR | Q140: =+R140/N140 -> 1.19 | R140: 4030.53 | S140: =IFERROR(VLOOKUP(J140,'DESC ITY - ENG'!B:C,2,FALSE),VLOOKUP(I140,'DESC ITY - ENG'!A:C,3,FALSE)) -> Steel Handle AC.SOLE Short w/Logo MC AISI 430 Pan 279-24 Sandblasted [cite: 4] | T140: =VLOOKUP(S140,'DESC ITY - ENG'!C:D,2,FALSE) -> SHDL | U140: =_xlfn.TRANSLATE(S140,"en","zh-cht") -> 鋼柄冷氣。獨短帶標誌 MC AISI 430 Pan 279-24 噴砂處理 [引用：4] | V140: =VLOOKUP(T140,'STANDARD COMM'!A:D,3,FALSE) -> Fittings | W140: =_xlfn.TRANSLATE(O140,"it","en") -> NR
A141: OF0039874 | B141: 45593.687 | D141: F600732 | E141: MUTLU METAL DIS TICARET LTD.STI | F141: 26AFF000052 | G141: 46081 | I141: 000281710006 | J141: MANICO AC.SOLE LUNGO C/LOGO MC AISI 430 SABBIATO TEG.379 26 | K141: manigliame | L141: =VLOOKUP(K141,'COMM ITY- ENG'!A:B,2,FALSE) -> handles | N141: 15015 | O141: NR | Q141: =+R141/N141 -> 1.29 | R141: 19369.35 | S141: =IFERROR(VLOOKUP(J141,'DESC ITY - ENG'!B:C,2,FALSE),VLOOKUP(I141,'DESC ITY - ENG'!A:C,3,FALSE)) -> Steel Handle AC.SOLE Long w/Logo MC AISI 430 Skillet 379-26 Sandblasted [cite: 4 5] | T141: =VLOOKUP(S141,'DESC ITY - ENG'!C:D,2,FALSE) -> HDL- | U141: =_xlfn.TRANSLATE(S141,"en","zh-cht") -> 鋼柄冷氣。鞋底長款，配 MC 標誌 MC AISI 430 Skillet 379-26 噴砂 [引用：4 5] | V141: =VLOOKUP(T141,'STANDARD COMM'!A:D,3,FALSE) -> Fittings | W141: =_xlfn.TRANSLATE(O141,"it","en") -> NR
A142: OF0040154 | B142: 45618.468 | D142: F600732 | E142: MUTLU METAL DIS TICARET LTD.STI | F142: 26AFF000052 | G142: 46081 | I142: 000281710007 | J142: MANIGLIA AC.SOLE C/LOGO MC AISI 430 SABBIATA CAS.480 20 | K142: manigliame | L142: =VLOOKUP(K142,'COMM ITY- ENG'!A:B,2,FALSE) -> handles | N142: 6552 | O142: NR | Q142: =+R142/N142 -> 0.91 | R142: 5962.32 | S142: =IFERROR(VLOOKUP(J142,'DESC ITY - ENG'!B:C,2,FALSE),VLOOKUP(I142,'DESC ITY - ENG'!A:C,3,FALSE)) -> Steel Side Handle AC.SOLE w/Logo MC AISI 430 Casserole 480-20 Sandblasted [cite: 5] | T142: =VLOOKUP(S142,'DESC ITY - ENG'!C:D,2,FALSE) -> SHDL | U142: =_xlfn.TRANSLATE(S142,"en","zh-cht") -> 鋼製側把冷氣。鞋底配標誌 MC AISI 430 砂鍋 480-20 砂磨 [引用：5] | V142: =VLOOKUP(T142,'STANDARD COMM'!A:D,3,FALSE) -> Fittings | W142: =_xlfn.TRANSLATE(O142,"it","en") -> NR
A143: OF0039874 | B143: 45639.624 | D143: F600732 | E143: MUTLU METAL DIS TICARET LTD.STI | F143: 26AFF000052 | G143: 46081 | I143: 000320380001 | J143: POMOLO AC.SOLE C/LOGO MC AISI 430 SABBIATO | K143: manigliame | L143: =VLOOKUP(K143,'COMM ITY- ENG'!A:B,2,FALSE) -> handles | N143: 4670 | O143: NR | Q143: =+R143/N143 -> 1.15 | R143: 5370.5 | S143: =IFERROR(VLOOKUP(J143,'DESC ITY - ENG'!B:C,2,FALSE),VLOOKUP(I143,'DESC ITY - ENG'!A:C,3,FALSE)) -> Steel Knob AC.SOLE w/Logo MC AISI 430 Sandblasted [cite: 5] | T143: =VLOOKUP(S143,'DESC ITY - ENG'!C:D,2,FALSE) -> KNOB | U143: =_xlfn.TRANSLATE(S143,"en","zh-cht") -> 鋼旋鈕冷氣。唯一配件 MC 標誌 AISI 430 砂燒 [引用：5] | V143: =VLOOKUP(T143,'STANDARD COMM'!A:D,3,FALSE) -> Fittings | W143: =_xlfn.TRANSLATE(O143,"it","en") -> NR
...

Sheet STANDARD COMM
A1: Commodity Code | B1: Commodity Description | C1: Commodity Group (MIL) | D1: Commodity Group (MIL)
A2: EXM- | B2: EXTR TREAT MATERIAL | C2: Coating | D2: =_xlfn.TRANSLATE(C2,"en","zh-cht") -> 塗層
A3: INM- | B3: INTR TREAT MATERIAL | C3: Coating | D3: =_xlfn.TRANSLATE(C3,"en","zh-cht") -> 塗層
A4: SILK | B4: SILK SCREEN MATERIAL | C4: Coating | D4: =_xlfn.TRANSLATE(C4,"en","zh-cht") -> 塗層
A5: BFIT | B5: ELE BULK FITG | C5: Electric Material | D5: =_xlfn.TRANSLATE(C5,"en","zh-cht") -> 電材料
A6: CORD | B6: POWER CORD | C6: Electric Material | D6: =_xlfn.TRANSLATE(C6,"en","zh-cht") -> 電材料
A7: ELCO | B7: ELE COMPONENT | C7: Electric Material | D7: =_xlfn.TRANSLATE(C7,"en","zh-cht") -> 電材料
A8: HS-- | B8: HEAT SHIELD | C8: Electric Material | D8: =_xlfn.TRANSLATE(C8,"en","zh-cht") -> 電材料
A9: HTEL | B9: HEAT ELEMENT | C9: Electric Material | D9: =_xlfn.TRANSLATE(C9,"en","zh-cht") -> 電材料
A10: LAMP | B10: LAMP (LED/NEON) | C10: Electric Material | D10: =_xlfn.TRANSLATE(C10,"en","zh-cht") -> 電材料
A11: PROB | B11: PROBE MATERIAL | C11: Electric Material | D11: =_xlfn.TRANSLATE(C11,"en","zh-cht") -> 電材料
A12: RUCO | B12: RUBBER COMPONENTS | C12: Electric Material | D12: =_xlfn.TRANSLATE(C12,"en","zh-cht") -> 電材料
A13: SIRM | B13: SILICONE RUBBER MATL | C13: Electric Material | D13: =_xlfn.TRANSLATE(C13,"en","zh-cht") -> 電材料
... A79: WIP- | B79: WORK IN PROGRESS | C79: Work In Progress | D79: =_xlfn.TRANSLATE(C79,"en","zh-cht") -> 進行中
A80: Showing 1 to 78 of 78 entries
A81: Previous
A82: 1
A83: Next
A84: Copyright © 2026 Meyer Manufacturing Company Ltd. All rights reserved.

Sheet COMM ITY- ENG
A2: Italian | B2: English
A3: accessori di confez. | B3: packaging accessories
A4: accessori finiti | B4: finished accessories
A5: accessori x manigl. | B5: accessories for handles
A6: acciaio | B6: steel
A7: Acciaio multistrato (5PLY) | B7: multilayer steel (5PLY)
A8: alluminio | B8: aluminium
A9: cartoni e casse | B9: cartons and boxes
A10: manigliame | B10: handles
A11: mater. di confezion. | B11: packaging material
A12: mater.aus.varie acq. | B12: various auxiliary materials purchased
A13: materiali di consumo | B13: consumable materials
... A16: semilavorato | B16: semi-finished product

Sheet DESC ITY - ENG
A1: Item Code | B1: Part Description | C1: Translated Part Description (English) | D1: StandardCommodityCode
A2: 000288100051 | B2: 1-5-HSI103C-Y SI HANDLE 16CM SAUCEPAN... | C2: 1-5 SI Handle 16cm Saucepan (6.5mm hole) | D2: HDL-
A3: 000288100051 | B3: 1-5-HSI103C-Y SI HANDLE 16CM SAUCEPAN... | C3: 1-5 SI Handle 16cm Saucepan (6.5mm hole) | D3: HDL-
A4: 000288100052 | B4: 1-5-HSI105C-Y SI HANDLE 20CM SAUCEPAN... | C4: 1-5 SI Handle 20cm Saucepan (6.5mm hole) | D4: HDL-
A5: 000288100052 | B5: 1-5-HSI105C-Y SI HANDLE 20CM SAUCEPAN... | C5: 1-5 SI Handle 20cm Saucepan (6.5mm hole) | D5: HDL-
A6: 000288100055 | B6: 1-5-HSI203C-Y SI HANDLE 20CM SKILLET... | C6: 1-5 SI Handle 20cm Skillet (6.5mm hole) | D6: HDL-
A7: 000288100055 | B7: 1-5-HSI203C-Y SI HANDLE 20CM SKILLET... | C7: 1-5 SI Handle 20cm Skillet (6.5mm hole) | D7: HDL-
A8: 000288100053 | B8: 1-5-HSI107C-Y SI HANDLE 24CM SAUCIER... | C8: 1-5 SI Handle 24cm Saucier (6.5mm hole) | D8: HDL-
A9: 000288100053 | B9: 1-5-HSI107C-Y SI HANDLE 24CM SAUCIER... | C9: 1-5 SI Handle 24cm Saucier (6.5mm hole) | D9: HDL-
A10: 000288100054 | B10: 1-5-HSI108C-Y SI HANDLE 26CM SAUTE'... | C10: 1-5 SI Handle 26cm Saute (6.5mm hole) | D10: HDL-
A11: 000288100054 | B11: 1-5-HSI108C-Y SI HANDLE 26CM SAUTE'... | C11: 1-5 SI Handle 26cm Saute (6.5mm hole) | D11: HDL-
A12: 000288100056 | B12: 1-5-HSI206C-Y SI HANDLE 26CM SKILLET... | C12: 1-5 SI Handle 26cm Skillet (6.5mm hole) | D12: HDL-
... A63: 000030385027 | B63: DISCO 5PLY 385/27 SS304 0,4 + Al1,8 + SS439 0,5 TOT 27/10 | C63: 5-Ply Disc SS304/AL/SS439 385mm x 2.7mm Total Thickness 2.7mm [cite: 1] | D63: CDM-
A64: 000030470023 | B64: DISCO 5PLY 470/23 SS304 0,4 + Al1,4 + SS439 0,5 TOT 23/10 | C64: 5-Ply Disc SS304/AL/SS439 470mm x 2.3mm Total Thickness 2.3mm [cite: 1] | D64: CDM- | E64: CDM- [cite: 6]
A65: 000030470023 | B65: DISCO 5PLY 470/23 SS304 0,4 + Al1,4 + SS439 0,5 TOT 23/10 | C65: 5-Ply Disc SS304/AL/SS439 470mm x 2.3mm Total Thickness 2.3mm [cite: 1] | D65: CDM- | E65: CDM- [cite: 6]
A66: 000030470023 | B66: DISCO 5PLY 470/23 SS304 0,4 + Al1,4 + SS439 0,5 TOT 23/10 | C66: 5-Ply Disc SS304/AL/SS439 470mm x 2.3mm Total Thickness 2.3mm [cite: 1] | D66: CDM- | E66: CDM- [cite: 6]
A67: 000390103024 | B67: VITE 5MAX14 AC.AUTOM.ZIG.C/TORX T25 | C67: 5x14 Auto Steel Knurled Screw w/ Torx T25 | D67: SCR-
A68: 002340514003 | B68: ACEMATT OK-390 opacizzante | C68: Acematt OK-390 Matting Agent | D68: INM-
A69: 000070265022R | B69: DISCO AL.1200 265/22 RIC | C69: Aluminum Disc Alloy 1200 265mm x 2.2mm Replacement Part [cite: 1] | D69: ALM-
A70: 000070410022R | B70: DISCO AL.1200 410/22 RIC | C70: Aluminum Disc Alloy 1200 410mm x 2.2mm Replacement Part [cite: 1] | D70: ALM-
A71: 000040215036R | B71: DISCO AL.4006 215/36 RIC | C71: Aluminum Disc Alloy 4006 215mm x 3.6mm Replacement Part [cite: 1 2] | D71: ALM-
A72: 000040215036R | B72: DISCO AL.4006 215/36 RIC | C72: Aluminum Disc Alloy 4006 215mm x 3.6mm Replacement Part [cite: 1 2] | D72: ALM-
A73: 000040225029R | B73: DISCO AL.4006 225/29 RIC | C73: Aluminum Disc Alloy 4006 225mm x 2.9mm Replacement Part [cite: 1] | D73: ALM-
A74: 000040235029R | B74: DISCO AL.4006 235/29 RIC | C74: Aluminum Disc Alloy 4006 235mm x 2.9mm Replacement Part [cite: 1] | D74: ALM-
A75: 000040235036R | B75: DISCO AL.4006 235/36 RIC | C75: Aluminum Disc Alloy 4006 235mm x 3.6mm Replacement Part [cite: 2] | D75: ALM-
A76: 000040235036R | B76: DISCO AL.4006 235/36 RIC | C76: Aluminum Disc Alloy 4006 235mm x 3.6mm Replacement Part [cite: 2] | D76: ALM-
A77: 000040235036R | B77: DISCO AL.4006 235/36 RIC | C77: Aluminum Disc Alloy 4006 235mm x 3.6mm Replacement Part [cite: 2] | D77: ALM-
A78: 000040235036R | B78: DISCO AL.4006 235/36 RIC | C78: Aluminum Disc Alloy 4006 235mm x 3.6mm Replacement Part [cite: 2] | D78: ALM-
... A788: 000390115006 | B788: VITE 5MAX18 AC.AUTOM.ZIG.C/TORX T25 | C788: Screw 5x18 mm Steel Self-Locking Knurled Torx T25 | D788: SCW-
