Workbook

Sheet TVS order 31052026
A1: Purchase Order Number | B1: Purchase Order Date | C1: Purchase order issue date | D1: Vendor ID | E1: VendorName | F1: Vendor_Invoice_No | G1: Invoice Date | H1: REF_NO | I1: Item Code | J1: Part Description | K1: Commodity Italian | L1: Commodity English | M1: Division | N1: Quantity | O1: Unit | P1: PO_Price_PO CUR | Q1: PO UNIT PRICE PO_CUR | R1: Total_PO_Price_PO CUR | S1: Translated Part Description (English) | T1: Unified Commodity Code | U1: Standard Comm code description | V1: T Code Validation
A2: OF0039689 | B2: 45442.524 | D2: F600361 | E2: ARCONIC- KOFEM MILL PRODUCTS HUNGARY KFT. | F2: 26AFC000002 | G2: 46037 | I2: 000050235032R | J2: DISCO AL.L.GREEN 235/32 RIC | K2: alluminio | L2: =VLOOKUP(K2,'COMM ITY- ENG'!A:B,2,FALSE) -> aluminium | N2: 2861 | O2: kg | Q2: =+R2/N2 -> 3.427001 | R2: 9804.65 | S2: =IFERROR(VLOOKUP(J2,'DESC ITY - ENG'!B:C,2,FALSE),VLOOKUP(I2,'DESC ITY - ENG'!A:C,3,FALSE)) -> Aluminum Disc L. Green Series 235mm x 3.2mm Replacement Part [cite: 3] | T2: =IFERROR(VLOOKUP(S2,'DESC ITY - ENG'!C:D,2,FALSE),VLOOKUP(J2,'DESC ITY - ENG'!B:D,3,FALSE)) -> ALM- | U2: =VLOOKUP(T2,'STANDARD COMM'!A:B,2,FALSE) -> ALUM MATERIAL | V2: =IF(T2="","(blank)",IF(COUNTIF('STANDARD COMM'!A:A,T2)>0,"OK","OUT OF SCOPE")) -> OK
A3: OF0039508 | B3: 45580.308 | D3: F505839 | E3: CHEMOURS BELGIUM BVBA | F3: 26AFC000001 | G3: 46037 | I3: 003010503004 | J3: 459G-R0185 ROLLER PRIMER GRAY | K3: prodotti chimici | L3: =VLOOKUP(K3,'COMM ITY- ENG'!A:B,2,FALSE) -> chemical products | N3: 460 | O3: kg | Q3: =+R3/N3 -> 8.98 | R3: 4130.8 | S3: =IFERROR(VLOOKUP(J3,'DESC ITY - ENG'!B:C,2,FALSE),VLOOKUP(I3,'DESC ITY - ENG'!A:C,3,FALSE)) -> 459G-R0185 ROLLER PRIMER GRAY | T3: =IFERROR(VLOOKUP(S3,'DESC ITY - ENG'!C:D,2,FALSE),VLOOKUP(J3,'DESC ITY - ENG'!B:D,3,FALSE)) -> INM- | U3: =VLOOKUP(T3,'STANDARD COMM'!A:B,2,FALSE) -> INTR TREAT MATERIAL | V3: =IF(T3="","(blank)",IF(COUNTIF('STANDARD COMM'!A:A,T3)>0,"OK","OUT OF SCOPE")) -> OK
A4: OF0039689 | B4: 45596.39 | D4: F600361 | E4: ARCONIC- KOFEM MILL PRODUCTS HUNGARY KFT. | F4: 26AFC000002 | G4: 46037 | I4: 000050315032R | J4: DISCO AL.L.GREEN 315/32 RIC | K4: alluminio | L4: =VLOOKUP(K4,'COMM ITY- ENG'!A:B,2,FALSE) -> aluminium | N4: 6720 | O4: kg | Q4: =+R4/N4 -> 3.427 | R4: 23029.44 | S4: =IFERROR(VLOOKUP(J4,'DESC ITY - ENG'!B:C,2,FALSE),VLOOKUP(I4,'DESC ITY - ENG'!A:C,3,FALSE)) -> Aluminum Disc L. Green Series 315mm x 3.2mm Replacement Part [cite: 3] | T4: =IFERROR(VLOOKUP(S4,'DESC ITY - ENG'!C:D,2,FALSE),VLOOKUP(J4,'DESC ITY - ENG'!B:D,3,FALSE)) -> ALM- | U4: =VLOOKUP(T4,'STANDARD COMM'!A:B,2,FALSE) -> ALUM MATERIAL | V4: =IF(T4="","(blank)",IF(COUNTIF('STANDARD COMM'!A:A,T4)>0,"OK","OUT OF SCOPE")) -> OK
A5: OF0039689 | B5: 45596.39 | D5: F600361 | E5: ARCONIC- KOFEM MILL PRODUCTS HUNGARY KFT. | F5: 26AFC000002 | G5: 46037 | I5: 000050330032R | J5: DISCO AL.L.GREEN 330/32 RIC | K5: alluminio | L5: =VLOOKUP(K5,'COMM ITY- ENG'!A:B,2,FALSE) -> aluminium | N5: 6735 | O5: kg | Q5: =+R5/N5 -> 3.4270007 | R5: 23080.85 | S5: =IFERROR(VLOOKUP(J5,'DESC ITY - ENG'!B:C,2,FALSE),VLOOKUP(I5,'DESC ITY - ENG'!A:C,3,FALSE)) -> Aluminum Disc L. Green Series 330mm x 3.2mm Replacement Part [cite: 3] | T5: =IFERROR(VLOOKUP(S5,'DESC ITY - ENG'!C:D,2,FALSE),VLOOKUP(J5,'DESC ITY - ENG'!B:D,3,FALSE)) -> ALM- | U5: =VLOOKUP(T5,'STANDARD COMM'!A:B,2,FALSE) -> ALUM MATERIAL | V5: =IF(T5="","(blank)",IF(COUNTIF('STANDARD COMM'!A:A,T5)>0,"OK","OUT OF SCOPE")) -> OK
A6: OF0039508 | B6: 45600.392 | D6: F505839 | E6: CHEMOURS BELGIUM BVBA | F6: 26AFC000001 | G6: 46037 | I6: 003010505005 | J6: 478G-R1090 ROLLER SEALER | K6: prodotti chimici | L6: =VLOOKUP(K6,'COMM ITY- ENG'!A:B,2,FALSE) -> chemical products | N6: 320 | O6: kg | Q6: =+R6/N6 -> 13 | R6: 4160 | S6: =IFERROR(VLOOKUP(J6,'DESC ITY - ENG'!B:C,2,FALSE),VLOOKUP(I6,'DESC ITY - ENG'!A:C,3,FALSE)) -> 478G-R1090 ROLLER SEALER | T6: =IFERROR(VLOOKUP(S6,'DESC ITY - ENG'!C:D,2,FALSE),VLOOKUP(J6,'DESC ITY - ENG'!B:D,3,FALSE)) -> INM- | U6: =VLOOKUP(T6,'STANDARD COMM'!A:B,2,FALSE) -> INTR TREAT MATERIAL | V6: =IF(T6="","(blank)",IF(COUNTIF('STANDARD COMM'!A:A,T6)>0,"OK","OUT OF SCOPE")) -> OK
A7: OF0039508 | B7: 45600.392 | D7: F505839 | E7: CHEMOURS BELGIUM BVBA | F7: 26AFC000001 | G7: 46037 | I7: 003130002004 | J7: 455G-R0385 ROLLER TOPCOAT PEWTER | K7: prodotti chimici | L7: =VLOOKUP(K7,'COMM ITY- ENG'!A:B,2,FALSE) -> chemical products | N7: 660 | O7: kg | Q7: =+R7/N7 -> 8.98 | R7: 5926.8 | S7: =IFERROR(VLOOKUP(J7,'DESC ITY - ENG'!B:C,2,FALSE),VLOOKUP(I7,'DESC ITY - ENG'!A:C,3,FALSE)) -> 455G-R0385 ROLLER TOPCOAT PEWTER | T7: =IFERROR(VLOOKUP(S7,'DESC ITY - ENG'!C:D,2,FALSE),VLOOKUP(J7,'DESC ITY - ENG'!B:D,3,FALSE)) -> INM- | U7: =VLOOKUP(T7,'STANDARD COMM'!A:B,2,FALSE) -> INTR TREAT MATERIAL | V7: =IF(T7="","(blank)",IF(COUNTIF('STANDARD COMM'!A:A,T7)>0,"OK","OUT OF SCOPE")) -> OK
A8: OF0039689 | B8: 45624.677 | D8: F600361 | E8: ARCONIC- KOFEM MILL PRODUCTS HUNGARY KFT. | F8: 26AFC000002 | G8: 46037 | I8: 000050265032R | J8: DISCO AL.L.GREEN 265/32 RIC | K8: alluminio | L8: =VLOOKUP(K8,'COMM ITY- ENG'!A:B,2,FALSE) -> aluminium | N8: 6741 | O8: kg | Q8: =+R8/N8 -> 3.4270004 | R8: 23101.41 | S8: =IFERROR(VLOOKUP(J8,'DESC ITY - ENG'!B:C,2,FALSE),VLOOKUP(I8,'DESC ITY - ENG'!A:C,3,FALSE)) -> Aluminum Disc L. Green Series 265mm x 3.2mm Replacement Part [cite: 3] | T8: =IFERROR(VLOOKUP(S8,'DESC ITY - ENG'!C:D,2,FALSE),VLOOKUP(J8,'DESC ITY - ENG'!B:D,3,FALSE)) -> ALM- | U8: =VLOOKUP(T8,'STANDARD COMM'!A:B,2,FALSE) -> ALUM MATERIAL | V8: =IF(T8="","(blank)",IF(COUNTIF('STANDARD COMM'!A:A,T8)>0,"OK","OUT OF SCOPE")) -> OK
A9: OF0038738 | B9: 45611.483 | D9: F505466 | E9: YUHUAN SUNNAR RUBBER&PLASTIC PRODUCTS CO.LTD | F9: 26AFF000001 | G9: 46049 | I9: 000250042001 | J9: MANICO BIS/1 NERO SATINATO | K9: manigliame | L9: =VLOOKUP(K9,'COMM ITY- ENG'!A:B,2,FALSE) -> handles | N9: 5000 | O9: NR | Q9: =+R9/N9 -> 0.239246 | R9: 1196.23 | S9: =IFERROR(VLOOKUP(J9,'DESC ITY - ENG'!B:C,2,FALSE),VLOOKUP(I9,'DESC ITY - ENG'!A:C,3,FALSE)) -> Handle Bis/1 Black Satin Finish [cite: 5] | T9: =IFERROR(VLOOKUP(S9,'DESC ITY - ENG'!C:D,2,FALSE),VLOOKUP(J9,'DESC ITY - ENG'!B:D,3,FALSE)) -> HDL-- | U9: =VLOOKUP(T9,'STANDARD COMM'!A:B,2,FALSE) -> #N/A | V9: =IF(T9="","(blank)",IF(COUNTIF('STANDARD COMM'!A:A,T9)>0,"OK","OUT OF SCOPE")) -> OUT OF SCOPE
A10: OF0038738 | B10: 45611.483 | D10: F505466 | E10: YUHUAN SUNNAR RUBBER&PLASTIC PRODUCTS CO.LTD | F10: 26AFF000001 | G10: 46049 | I10: 000250044001 | J10: MANICO CIGNO/1 NERO SATINATO | K10: manigliame | L10: =VLOOKUP(K10,'COMM ITY- ENG'!A:B,2,FALSE) -> handles | N10: 10000 | O10: NR | Q10: =+R10/N10 -> 0.207856 | R10: 2078.56 | S10: =IFERROR(VLOOKUP(J10,'DESC ITY - ENG'!B:C,2,FALSE),VLOOKUP(I10,'DESC ITY - ENG'!A:C,3,FALSE)) -> Handle Cigno/1 Black Satin Finish [cite: 5] | T10: =IFERROR(VLOOKUP(S10,'DESC ITY - ENG'!C:D,2,FALSE),VLOOKUP(J10,'DESC ITY - ENG'!B:D,3,FALSE)) -> HDL-- | U10: =VLOOKUP(T10,'STANDARD COMM'!A:B,2,FALSE) -> #N/A | V10: =IF(T10="","(blank)",IF(COUNTIF('STANDARD COMM'!A:A,T10)>0,"OK","OUT OF SCOPE")) -> OUT OF SCOPE
A11: OF0038738 | B11: 45611.483 | D11: F505466 | E11: YUHUAN SUNNAR RUBBER&PLASTIC PRODUCTS CO.LTD | F11: 26AFF000001 | G11: 46049 | I11: 000250045001 | J11: MANICO CIGNO/2 NERO SATINATO | K11: manigliame | L11: =VLOOKUP(K11,'COMM ITY- ENG'!A:B,2,FALSE) -> handles | N11: 30000 | O11: NR | Q11: =+R11/N11 -> 0.25451767 | R11: 7635.53 | S11: =IFERROR(VLOOKUP(J11,'DESC ITY - ENG'!B:C,2,FALSE),VLOOKUP(I11,'DESC ITY - ENG'!A:C,3,FALSE)) -> Handle Cigno/2 Black Satin Finish [cite: 5] | T11: =IFERROR(VLOOKUP(S11,'DESC ITY - ENG'!C:D,2,FALSE),VLOOKUP(J11,'DESC ITY - ENG'!B:D,3,FALSE)) -> HDL-- | U11: =VLOOKUP(T11,'STANDARD COMM'!A:B,2,FALSE) -> #N/A | V11: =IF(T11="","(blank)",IF(COUNTIF('STANDARD COMM'!A:A,T11)>0,"OK","OUT OF SCOPE")) -> OUT OF SCOPE
A12: OF0038893 | B12: 45611.483 | D12: F505466 | E12: YUHUAN SUNNAR RUBBER&PLASTIC PRODUCTS CO.LTD | F12: 26AFF000001 | G12: 46049 | I12: 000250516105 | J12: MANICO TITANO/1 EFFET.LEGNO V.0013 | K12: manigliame | L12: =VLOOKUP(K12,'COMM ITY- ENG'!A:B,2,FALSE) -> handles | N12: 3000 | O12: NR | Q12: =+R12/N12 -> 0.65835333 | R12: 1975.06 | S12: =IFERROR(VLOOKUP(J12,'DESC ITY - ENG'!B:C,2,FALSE),VLOOKUP(I12,'DESC ITY - ENG'!A:C,3,FALSE)) -> Handle Titano/1 Wood Effect V.0013 [cite: 5] | T12: =IFERROR(VLOOKUP(S12,'DESC ITY - ENG'!C:D,2,FALSE),VLOOKUP(J12,'DESC ITY - ENG'!B:D,3,FALSE)) -> HDL-- | U12: =VLOOKUP(T12,'STANDARD COMM'!A:B,2,FALSE) -> #N/A | V12: =IF(T12="","(blank)",IF(COUNTIF('STANDARD COMM'!A:A,T12)>0,"OK","OUT OF SCOPE")) -> OUT OF SCOPE
A13: OF0038893 | B13: 45611.483 | D13: F505466 | E13: YUHUAN SUNNAR RUBBER&PLASTIC PRODUCTS CO.LTD | F13: 26AFF000001 | G13: 46049 | I13: 000250517107 | J13: MANICO TITANO/2 EFFET.LEGNO V.0013 | K13: manigliame | L13: =VLOOKUP(K13,'COMM ITY- ENG'!A:B,2,FALSE) -> handles | N13: 3000 | O13: NR | Q13: =+R13/N13 -> 0.70162 | R13: 2104.86 | S13: =IFERROR(VLOOKUP(J13,'DESC ITY - ENG'!B:C,2,FALSE),VLOOKUP(I13,'DESC ITY - ENG'!A:C,3,FALSE)) -> Titano/2 Handle Wood Effect V.0013 | T13: =IFERROR(VLOOKUP(S13,'DESC ITY - ENG'!C:D,2,FALSE),VLOOKUP(J13,'DESC ITY - ENG'!B:D,3,FALSE)) -> HDL-- | U13: =VLOOKUP(T13,'STANDARD COMM'!A:B,2,FALSE) -> #N/A | V13: =IF(T13="","(blank)",IF(COUNTIF('STANDARD COMM'!A:A,T13)>0,"OK","OUT OF SCOPE")) -> OUT OF SCOPE
... A339: OF0039811 | B339: 45698.437 | D339: F012680 | E339: PROFILGLASS SPA | F339: 26AFI000256 | G339: 46053 | I339: 000050280032R | J339: DISCO AL.L.GREEN 280/32 RIC | K339: alluminio | L339: =VLOOKUP(K339,'COMM ITY- ENG'!A:B,2,FALSE) -> aluminium | N339: 895 | O339: kg | Q339: =+R339/N339 -> 3.33 | R339: 2980.35 | S339: =IFERROR(VLOOKUP(J339,'DESC ITY - ENG'!B:C,2,FALSE),VLOOKUP(I339,'DESC ITY - ENG'!A:C,3,FALSE)) -> Aluminum Disc L. Green Series 280mm x 3.2mm Replacement Part [cite: 3] | T339: =IFERROR(VLOOKUP(S339,'DESC ITY - ENG'!C:D,2,FALSE),VLOOKUP(J339,'DESC ITY - ENG'!B:D,3,FALSE)) -> ALM- | U339: =VLOOKUP(T339,'STANDARD COMM'!A:B,2,FALSE) -> ALUM MATERIAL | V339: =IF(T339="","(blank)",IF(COUNTIF('STANDARD COMM'!A:A,T339)>0,"OK","OUT OF SCOPE")) -> OK
A340: OF0038444 | D340: F600043 | E340: MEYER MANUFACTURING COMPANY LIMITED | F340: 26AFF000009 | G340: 46053 | I340: 000730415002 | J340: REC2008AS-002 COP.AC.MADE IN 20CM ASSEMBLED W/DEY.PVD GOLD | K340: accessori finiti | L340: =VLOOKUP(K340,'COMM ITY- ENG'!A:B,2,FALSE) -> finished accessories | N340: 980 | O340: NR | Q340: =+R340/N340 -> 4.2674082 | R340: 4182.06 | S340: =IFERROR(VLOOKUP(J340,'DESC ITY - ENG'!B:C,2,FALSE),VLOOKUP(I340,'DESC ITY - ENG'!A:C,3,FALSE)) -> SS Lid 20cm Assembled with DEY.PVD Gold Handle | T340: =IFERROR(VLOOKUP(S340,'DESC ITY - ENG'!C:D,2,FALSE),VLOOKUP(J340,'DESC ITY - ENG'!B:D,3,FALSE)) -> LID- | U340: =VLOOKUP(T340,'STANDARD COMM'!A:B,2,FALSE) -> LID | V340: =IF(T340="","(blank)",IF(COUNTIF('STANDARD COMM'!A:A,T340)>0,"OK","OUT OF SCOPE")) -> OK
A341: OF0039830 | B341: 45503.383 | D341: F505839 | E341: CHEMOURS BELGIUM BVBA | F341: 26AFC000029 | G341: 46069 | I341: 003130002004 | J341: 455G-R0385 ROLLER TOPCOAT PEWTER | K341: prodotti chimici | L341: =VLOOKUP(K341,'COMM ITY- ENG'!A:B,2,FALSE) -> chemical products | N341: 460 | O341: kg | Q341: =+R341/N341 -> 8.98 | R341: 4130.8 | S341: =IFERROR(VLOOKUP(J341,'DESC ITY - ENG'!B:C,2,FALSE),VLOOKUP(I341,'DESC ITY - ENG'!A:C,3,FALSE)) -> 455G-R0385 ROLLER TOPCOAT PEWTER | T341: =IFERROR(VLOOKUP(S341,'DESC ITY - ENG'!C:D,2,FALSE),VLOOKUP(J341,'DESC ITY - ENG'!B:D,3,FALSE)) -> INM- | U341: =VLOOKUP(T341,'STANDARD COMM'!A:B,2,FALSE) -> INTR TREAT MATERIAL | V341: =IF(T341="","(blank)",IF(COUNTIF('STANDARD COMM'!A:A,T341)>0,"OK","OUT OF SCOPE")) -> OK
A342: OF0040017 | B342: 45559.363 | D342: F505532 | E342: PEMCO BELGIUM BV | F342: 26AFC000020 | G342: 46069 | I342: 002490189001 | J342: FB 280 ROSSO FERRO | K342: prodotti chimici | L342: =VLOOKUP(K342,'COMM ITY- ENG'!A:B,2,FALSE) -> chemical products | N342: 50 | O342: kg | Q342: =+R342/N342 -> 22.3892 | R342: 1119.46 | S342: =IFERROR(VLOOKUP(J342,'DESC ITY - ENG'!B:C,2,FALSE),VLOOKUP(I342,'DESC ITY - ENG'!A:C,3,FALSE)) -> Pigment FB 280 Iron Red | T342: =IFERROR(VLOOKUP(S342,'DESC ITY - ENG'!C:D,2,FALSE),VLOOKUP(J342,'DESC ITY - ENG'!B:D,3,FALSE)) -> INM- | U342: =VLOOKUP(T342,'STANDARD COMM'!A:B,2,FALSE) -> INTR TREAT MATERIAL | V342: =IF(T342="","(blank)",IF(COUNTIF('STANDARD COMM'!A:A,T342)>0,"OK","OUT OF SCOPE")) -> OK
A343: OF0039842 | B343: 45566.608 | D343: F600361 | E343: ARCONIC- KOFEM MILL PRODUCTS HUNGARY KFT. | F343: 26AFC000024 | G343: 46069 | I343: 000050265032R | J343: DISCO AL.L.GREEN 265/32 RIC | K343: alluminio | L343: =VLOOKUP(K343,'COMM ITY- ENG'!A:B,2,FALSE) -> aluminium | N343: 10198 | O343: kg | Q343: =+R343/N343 -> 3.6420004 | R343: 37141.12 | S343: =IFERROR(VLOOKUP(J343,'DESC ITY - ENG'!B:C,2,FALSE),VLOOKUP(I343,'DESC ITY - ENG'!A:C,3,FALSE)) -> Aluminum Disc L. Green Series 265mm x 3.2mm Replacement Part [cite: 3] | T343: =IFERROR(VLOOKUP(S343,'DESC ITY - ENG'!C:D,2,FALSE),VLOOKUP(J343,'DESC ITY - ENG'!B:D,3,FALSE)) -> ALM- | U343: =VLOOKUP(T343,'STANDARD COMM'!A:B,2,FALSE) -> ALUM MATERIAL | V343: =IF(T343="","(blank)",IF(COUNTIF('STANDARD COMM'!A:A,T343)>0,"OK","OUT OF SCOPE")) -> OK
A344: OF0039955 | B344: 45566.608 | D344: F600361 | E344: ARCONIC- KOFEM MILL PRODUCTS HUNGARY KFT. | F344: 26AFC000025 | G344: 46069 | I344: 000050315032R | J344: DISCO AL.L.GREEN 315/32 RIC | K344: alluminio | L344: =VLOOKUP(K344,'COMM ITY- ENG'!A:B,2,FALSE) -> aluminium | N344: 6654 | O344: kg | Q344: =+R344/N344 -> 3.6420003 | R344: 24233.87 | S344: =IFERROR(VLOOKUP(J344,'DESC ITY - ENG'!B:C,2,FALSE),VLOOKUP(I344,'DESC ITY - ENG'!A:C,3,FALSE)) -> Aluminum Disc L. Green Series 315mm x 3.2mm Replacement Part [cite: 3] | T344: =IFERROR(VLOOKUP(S344,'DESC ITY - ENG'!C:D,2,FALSE),VLOOKUP(J344,'DESC ITY - ENG'!B:D,3,FALSE)) -> ALM- | U344: =VLOOKUP(T344,'STANDARD COMM'!A:B,2,FALSE) -> ALUM MATERIAL | V344: =IF(T344="","(blank)",IF(COUNTIF('STANDARD COMM'!A:A,T344)>0,"OK","OUT OF SCOPE")) -> OK
A345: OF0039955 | B345: 45566.608 | D345: F600361 | E345: ARCONIC- KOFEM MILL PRODUCTS HUNGARY KFT. | F345: 26AFC000025 | G345: 46069 | I345: 000050330032R | J345: DISCO AL.L.GREEN 330/32 RIC | K345: alluminio | L345: =VLOOKUP(K345,'COMM ITY- ENG'!A:B,2,FALSE) -> aluminium | N345: 6528 | O345: kg | Q345: =+R345/N345 -> 3.6420006 | R345: 23774.98 | S345: =IFERROR(VLOOKUP(J345,'DESC ITY - ENG'!B:C,2,FALSE),VLOOKUP(I345,'DESC ITY - ENG'!A:C,3,FALSE)) -> Aluminum Disc L. Green Series 330mm x 3.2mm Replacement Part [cite: 3] | T345: =IFERROR(VLOOKUP(S345,'DESC ITY - ENG'!C:D,2,FALSE),VLOOKUP(J345,'DESC ITY - ENG'!B:D,3,FALSE)) -> ALM- | U345: =VLOOKUP(T345,'STANDARD COMM'!A:B,2,FALSE) -> ALUM MATERIAL | V345: =IF(T345="","(blank)",IF(COUNTIF('STANDARD COMM'!A:A,T345)>0,"OK","OUT OF SCOPE")) -> OK
A346: OF0039842 | B346: 45566.608 | D346: F600361 | E346: ARCONIC- KOFEM MILL PRODUCTS HUNGARY KFT. | F346: 26AFC000026 | G346: 46069 | I346: 000050315032R | J346: DISCO AL.L.GREEN 315/32 RIC | K346: alluminio | L346: =VLOOKUP(K346,'COMM ITY- ENG'!A:B,2,FALSE) -> aluminium | N346: 3409 | O346: kg | Q346: =+R346/N346 -> 3.6420006 | R346: 12415.58 | S346: =IFERROR(VLOOKUP(J346,'DESC ITY - ENG'!B:C,2,FALSE),VLOOKUP(I346,'DESC ITY - ENG'!A:C,3,FALSE)) -> Aluminum Disc L. Green Series 315mm x 3.2mm Replacement Part [cite: 3] | T346: =IFERROR(VLOOKUP(S346,'DESC ITY - ENG'!C:D,2,FALSE),VLOOKUP(J346,'DESC ITY - ENG'!B:D,3,FALSE)) -> ALM- | U346: =VLOOKUP(T346,'STANDARD COMM'!A:B,2,FALSE) -> ALUM MATERIAL | V346: =IF(T346="","(blank)",IF(COUNTIF('STANDARD COMM'!A:A,T346)>0,"OK","OUT OF SCOPE")) -> OK
A347: OF0039842 | B347: 45566.608 | D347: F600361 | E347: ARCONIC- KOFEM MILL PRODUCTS HUNGARY KFT. | F347: 26AFC000026 | G347: 46069 | I347: 000050330032R | J347: DISCO AL.L.GREEN 330/32 RIC | K347: alluminio | L347: =VLOOKUP(K347,'COMM ITY- ENG'!A:B,2,FALSE) -> aluminium | N347: 6520 | O347: kg | Q347: =+R347/N347 -> 3.642 | R347: 23745.84 | S347: =IFERROR(VLOOKUP(J347,'DESC ITY - ENG'!B:C,2,FALSE),VLOOKUP(I347,'DESC ITY - ENG'!A:C,3,FALSE)) -> Aluminum Disc L. Green Series 330mm x 3.2mm Replacement Part [cite: 3] | T347: =IFERROR(VLOOKUP(S347,'DESC ITY - ENG'!C:D,2,FALSE),VLOOKUP(J347,'DESC ITY - ENG'!B:D,3,FALSE)) -> ALM- | U347: =VLOOKUP(T347,'STANDARD COMM'!A:B,2,FALSE) -> ALUM MATERIAL | V347: =IF(T347="","(blank)",IF(COUNTIF('STANDARD COMM'!A:A,T347)>0,"OK","OUT OF SCOPE")) -> OK
A348: OF0039955 | B348: 45566.608 | D348: F600361 | E348: ARCONIC- KOFEM MILL PRODUCTS HUNGARY KFT. | F348: 26AFC000027 | G348: 46069 | I348: 000050225032R | J348: DISCO AL.L.GREEN 225/32 RIC | K348: alluminio | L348: =VLOOKUP(K348,'COMM ITY- ENG'!A:B,2,FALSE) -> aluminium | N348: 2224 | O348: kg | Q348: =+R348/N348 -> 3.6420009 | R348: 8099.81 | S348: =IFERROR(VLOOKUP(J348,'DESC ITY - ENG'!B:C,2,FALSE),VLOOKUP(I348,'DESC ITY - ENG'!A:C,3,FALSE)) -> Aluminum Disc L. Green Series 225mm x 3.2mm Replacement Part [cite: 3] | T348: =IFERROR(VLOOKUP(S348,'DESC ITY - ENG'!C:D,2,FALSE),VLOOKUP(J348,'DESC ITY - ENG'!B:D,3,FALSE)) -> ALM- | U348: =VLOOKUP(T348,'STANDARD COMM'!A:B,2,FALSE) -> ALUM MATERIAL | V348: =IF(T348="","(blank)",IF(COUNTIF('STANDARD COMM'!A:A,T348)>0,"OK","OUT OF SCOPE")) -> OK
A349: OF0039955 | B349: 45566.608 | D349: F600361 | E349: ARCONIC- KOFEM MILL PRODUCTS HUNGARY KFT. | F349: 26AFC000027 | G349: 46069 | I349: 000050235032R | J349: DISCO AL.L.GREEN 235/32 RIC | K349: alluminio | L349: =VLOOKUP(K349,'COMM ITY- ENG'!A:B,2,FALSE) -> aluminium | N349: 2213 | O349: kg | Q349: =+R349/N349 -> 3.6420018 | R349: 8059.75 | S349: =IFERROR(VLOOKUP(J349,'DESC ITY - ENG'!B:C,2,FALSE),VLOOKUP(I349,'DESC ITY - ENG'!A:C,3,FALSE)) -> Aluminum Disc L. Green Series 235mm x 3.2mm Replacement Part [cite: 3] | T349: =IFERROR(VLOOKUP(S349,'DESC ITY - ENG'!C:D,2,FALSE),VLOOKUP(J349,'DESC ITY - ENG'!B:D,3,FALSE)) -> ALM- | U349: =VLOOKUP(T349,'STANDARD COMM'!A:B,2,FALSE) -> ALUM MATERIAL | V349: =IF(T349="","(blank)",IF(COUNTIF('STANDARD COMM'!A:A,T349)>0,"OK","OUT OF SCOPE")) -> OK
A350: OF0039955 | B350: 45566.608 | D350: F600361 | E350: ARCONIC- KOFEM MILL PRODUCTS HUNGARY KFT. | F350: 26AFC000027 | G350: 46069 | I350: 000050265032R | J350: DISCO AL.L.GREEN 265/32 RIC | K350: alluminio | L350: =VLOOKUP(K350,'COMM ITY- ENG'!A:B,2,FALSE) -> aluminium | N350: 2219 | O350: kg | Q350: =+R350/N350 -> 3.6420009 | R350: 8081.6 | S350: =IFERROR(VLOOKUP(J350,'DESC ITY - ENG'!B:C,2,FALSE),VLOOKUP(I350,'DESC ITY - ENG'!A:C,3,FALSE)) -> Aluminum Disc L. Green Series 265mm x 3.2mm Replacement Part [cite: 3] | T350: =IFERROR(VLOOKUP(S350,'DESC ITY - ENG'!C:D,2,FALSE),VLOOKUP(J350,'DESC ITY - ENG'!B:D,3,FALSE)) -> ALM- | U350: =VLOOKUP(T350,'STANDARD COMM'!A:B,2,FALSE) -> ALUM MATERIAL | V350: =IF(T350="","(blank)",IF(COUNTIF('STANDARD COMM'!A:A,T350)>0,"OK","OUT OF SCOPE")) -> OK
A351: OF0039830 | B351: 45566.608 | D351: F505839 | E351: CHEMOURS BELGIUM BVBA | F351: 26AFC000029 | G351: 46069 | I351: 003010503004 | J351: 459G-R0185 ROLLER PRIMER GRAY | K351: prodotti chimici | L351: =VLOOKUP(K351,'COMM ITY- ENG'!A:B,2,FALSE) -> chemical products | N351: 300 | O351: kg | Q351: =+R351/N351 -> 8.98 | R351: 2694 | S351: =IFERROR(VLOOKUP(J351,'DESC ITY - ENG'!B:C,2,FALSE),VLOOKUP(I351,'DESC ITY - ENG'!A:C,3,FALSE)) -> 459G-R0185 ROLLER PRIMER GRAY | T351: =IFERROR(VLOOKUP(S351,'DESC ITY - ENG'!C:D,2,FALSE),VLOOKUP(J351,'DESC ITY - ENG'!B:D,3,FALSE)) -> INM- | U351: =VLOOKUP(T351,'STANDARD COMM'!A:B,2,FALSE) -> INTR TREAT MATERIAL | V351: =IF(T351="","(blank)",IF(COUNTIF('STANDARD COMM'!A:A,T351)>0,"OK","OUT OF SCOPE")) -> OK
A352: OF0039830 | B352: 45566.608 | D352: F505839 | E352: CHEMOURS BELGIUM BVBA | F352: 26AFC000029 | G352: 46069 | I352: 003040090024 | J352: 479G-81190 PRIMER BLACK PROFES (ex 81197) | K352: prodotti chimici | L352: =VLOOKUP(K352,'COMM ITY- ENG'!A:B,2,FALSE) -> chemical products | N352: 320 | O352: kg | Q352: =+R352/N352 -> 22.79 | R352: 7292.8 | S352: =IFERROR(VLOOKUP(J352,'DESC ITY - ENG'!B:C,2,FALSE),VLOOKUP(I352,'DESC ITY - ENG'!A:C,3,FALSE)) -> 479G-81190 PRIMER BLACK PROFES (ex 81197) | T352: =IFERROR(VLOOKUP(S352,'DESC ITY - ENG'!C:D,2,FALSE),VLOOKUP(J352,'DESC ITY - ENG'!B:D,3,FALSE)) -> INM- | U352: =VLOOKUP(T352,'STANDARD COMM'!A:B,2,FALSE) -> INTR TREAT MATERIAL | V352: =IF(T352="","(blank)",IF(COUNTIF('STANDARD COMM'!A:A,T352)>0,"OK","OUT OF SCOPE")) -> OK
... A429: OF0040138 | B429: 45714.681 | D429: F010036 | E429: BBC PLASTIK SRL | F429: 26AFI000263 | G429: 46071 | I429: 001150300006 | J429: BUSTA POL.50X70 FORATA RIGENERATA 100% MADE IN | K429: accessori di confez. | L429: =VLOOKUP(K429,'COMM ITY- ENG'!A:B,2,FALSE) -> packaging accessories | N429: 2000 | O429: NR | Q429: =+R429/N429 -> 0.065 | R429: 130 | S429: =IFERROR(VLOOKUP(J429,'DESC ITY - ENG'!B:C,2,FALSE),VLOOKUP(I429,'DESC ITY - ENG'!A:C,3,FALSE)) -> POLY BAG 50X70 PERFORATED REGENERATED 100% MADE IN | T429: =IFERROR(VLOOKUP(S429,'DESC ITY - ENG'!C:D,2,FALSE),VLOOKUP(J429,'DESC ITY - ENG'!B:D,3,FALSE)) -> BAG- | U429: =VLOOKUP(T429,'STANDARD COMM'!A:B,2,FALSE) -> BAG PACK | V429: =IF(T429="","(blank)",IF(COUNTIF('STANDARD COMM'!A:A,T429)>0,"OK","OUT OF SCOPE")) -> OK
A430: OF0039884 | D430: F600439 | E430: CARTON SRL | F430: 26AFI000267 | G430: 46071 | I430: 002030160001 | J430: STRISCIA CARTA BUL.52X27,5 GR90 STD FSC+LOGHI | K430: accessori di confez. | L430: =VLOOKUP(K430,'COMM ITY- ENG'!A:B,2,FALSE) -> packaging accessories | N430: 25000 | O430: NR | Q430: =+R430/N430 -> 0.017 | R430: 425 | S430: =IFERROR(VLOOKUP(J430,'DESC ITY - ENG'!B:C,2,FALSE),VLOOKUP(I430,'DESC ITY - ENG'!A:C,3,FALSE)) -> 5 GR90 STD FSC+LOGHIPaper Strip 52x27.5 cm 90g Standard FSC with Logos | T430: =IFERROR(VLOOKUP(S430,'DESC ITY - ENG'!C:D,2,FALSE),VLOOKUP(J430,'DESC ITY - ENG'!B:D,3,FALSE)) -> PAP- | U430: =VLOOKUP(T430,'STANDARD COMM'!A:B,2,FALSE) -> PAPER FOR BOX | V430: =IF(T430="","(blank)",IF(COUNTIF('STANDARD COMM'!A:A,T430)>0,"OK","OUT OF SCOPE")) -> OK
A431: OF0039884 | D431: F600439 | E431: CARTON SRL | F431: 26AFI000267 | G431: 46071 | I431: 002030161001 | J431: STRISCIA CARTA BUL.60X36,5 GR90 STD FSC+LOGHI | K431: accessori di confez. | L431: =VLOOKUP(K431,'COMM ITY- ENG'!A:B,2,FALSE) -> packaging accessories | N431: 30000 | O431: NR | Q431: =+R431/N431 -> 0.025 | R431: 750 | S431: =IFERROR(VLOOKUP(J431,'DESC ITY - ENG'!B:C,2,FALSE),VLOOKUP(I431,'DESC ITY - ENG'!A:C,3,FALSE)) -> 5 GR90 STD FSC+LOGHIPaper Strip 61X36.5 cm 90g Standard FSC with Logos | T431: =IFERROR(VLOOKUP(S431,'DESC ITY - ENG'!C:D,2,FALSE),VLOOKUP(J431,'DESC ITY - ENG'!B:D,3,FALSE)) -> PAP- | U431: =VLOOKUP(T431,'STANDARD COMM'!A:B,2,FALSE) -> PAPER FOR BOX | V431: =IF(T431="","(blank)",IF(COUNTIF('STANDARD COMM'!A:A,T431)>0,"OK","OUT OF SCOPE")) -> OK
A432: OF0039767 | D432: F014441 | E432: COOPERATIVA ALBANESI SCRL | F432: 26AFI000268 | G432: 46071 | I432: 000390111001 | J432: VITE 5MAX16 AC TCB T9,5 C./TORX T25 | K432: accessori x manigl. | L432: =VLOOKUP(K432,'COMM ITY- ENG'!A:B,2,FALSE) -> accessories for handles | N432: 20000 | O432: NR | Q432: =+R432/N432 -> 0.0354 | R432: 708 | S432: =IFERROR(VLOOKUP(J432,'DESC ITY - ENG'!B:C,2,FALSE),VLOOKUP(I432,'DESC ITY - ENG'!A:C,3,FALSE)) -> Screw 5x16 mm Steel Cylindrical Button Head Torx T25 | T432: =IFERROR(VLOOKUP(S432,'DESC ITY - ENG'!C:D,2,FALSE),VLOOKUP(J432,'DESC ITY - ENG'!B:D,3,FALSE)) -> SCR- | U432: =VLOOKUP(T432,'STANDARD COMM'!A:B,2,FALSE) -> SCREW | V432: =IF(T432="","(blank)",IF(COUNTIF('STANDARD COMM'!A:A,T432)>0,"OK","OUT OF SCOPE")) -> OK
A433: OF0039502 | D433: F014441 | E433: COOPERATIVA ALBANESI SCRL | F433: 26AFI000268 | G433: 46071 | I433: 000390111024 | J433: VITE 5MAX16 ZN B.AUTOM.ZIG.C/TO.T25 | K433: accessori x manigl. | L433: =VLOOKUP(K433,'COMM ITY- ENG'!A:B,2,FALSE) -> accessories for handles | N433: 4044 | O433: NR | Q433: =+R433/N433 -> 0.01810089 | R433: 73.2 | S433: =IFERROR(VLOOKUP(J433,'DESC ITY - ENG'!B:C,2,FALSE),VLOOKUP(I433,'DESC ITY - ENG'!A:C,3,FALSE)) -> Screw 5x16 mm Steel Cylindrical Button Head Torx T25 | T433: =IFERROR(VLOOKUP(S433,'DESC ITY - ENG'!C:D,2,FALSE),VLOOKUP(J433,'DESC ITY - ENG'!B:D,3,FALSE)) -> SCR- | U433: =VLOOKUP(T433,'STANDARD COMM'!A:B,2,FALSE) -> SCREW | V433: =IF(T433="","(blank)",IF(COUNTIF('STANDARD COMM'!A:A,T433)>0,"OK","OUT OF SCOPE")) -> OK
A434: OF0039875 | B434: 45560.447 | D434: F600780 | E434: GULBAK BAKALIT METAL VE TEKSTIL SAN. ve TIC. LTD. STI | F434: 26AFF000047 | G434: 46081 | I434: 000281710003 | J434: MANICO AC.SOLE CORTO C/LOGO MC AISI 430 SABBIATO CAS.433 16 | K434: manigliame | L434: =VLOOKUP(K434,'COMM ITY- ENG'!A:B,2,FALSE) -> handles | N434: 4000 | O434: NR | Q434: =+R434/N434 -> 1.137 | R434: 4548 | S434: =IFERROR(VLOOKUP(J434,'DESC ITY - ENG'!B:C,2,FALSE),VLOOKUP(I434,'DESC ITY - ENG'!A:C,3,FALSE)) -> Steel Handle AC.SOLE Short w/Logo MC AISI 430 Casserole 433-16 Sandblasted [cite: 4] | T434: =IFERROR(VLOOKUP(S434,'DESC ITY - ENG'!C:D,2,FALSE),VLOOKUP(J434,'DESC ITY - ENG'!B:D,3,FALSE)) -> SHDL- | U434: =VLOOKUP(T434,'STANDARD COMM'!A:B,2,FALSE) -> #N/A | V434: =IF(T434="","(blank)",IF(COUNTIF('STANDARD COMM'!A:A,T434)>0,"OK","OUT OF SCOPE")) -> OUT OF SCOPE
A435: OF0040544 | B435: 45580.643 | D435: F014980 | E435: INDUSTRIAL SERVICE Srl | F435: 26AFI000443 | G435: 46081 | I435: 009100002001 | J435: BOBINA POMERCART GR 40 (KG 4) | K435: materiali di consumo | L435: =VLOOKUP(K435,'COMM ITY- ENG'!A:B,2,FALSE) -> consumable materials | N435: 18 | O435: NR | Q435: =+R435/N435 -> 17.2 | R435: 309.6 | S435: =IFERROR(VLOOKUP(J435,'DESC ITY - ENG'!B:C,2,FALSE),VLOOKUP(I435,'DESC ITY - ENG'!A:C,3,FALSE)) -> Paper Roll Pomercart 40g 4kg | T435: =IFERROR(VLOOKUP(S435,'DESC ITY - ENG'!C:D,2,FALSE),VLOOKUP(J435,'DESC ITY - ENG'!B:D,3,FALSE)) -> PAP- | U435: =VLOOKUP(T435,'STANDARD COMM'!A:B,2,FALSE) -> PAPER FOR BOX | V435: =IF(T435="","(blank)",IF(COUNTIF('STANDARD COMM'!A:A,T435)>0,"OK","OUT OF SCOPE")) -> OK
A436: OF0040100 | B436: 45582.527 | D436: F600361 | E436: ARCONIC- KOFEM MILL PRODUCTS HUNGARY KFT. | F436: 26AFC000035 | G436: 46081 | I436: 000050220032R | J436: DISCO AL.L.GREEN 220/32 RIC | K436: alluminio | L436: =VLOOKUP(K436,'COMM ITY- ENG'!A:B,2,FALSE) -> aluminium | N436: 2233 | O436: kg | Q436: =+R436/N436 -> 3.6420018 | R436: 8132.59 | S436: =IFERROR(VLOOKUP(J436,'DESC ITY - ENG'!B:C,2,FALSE),VLOOKUP(I436,'DESC ITY - ENG'!A:C,3,FALSE)) -> Aluminum Disc L. Green Series 220mm x 3.2mm Replacement Part [cite: 3] | T436: =IFERROR(VLOOKUP(S436,'DESC ITY - ENG'!C:D,2,FALSE),VLOOKUP(J436,'DESC ITY - ENG'!B:D,3,FALSE)) -> ALM- | U436: =VLOOKUP(T436,'STANDARD COMM'!A:B,2,FALSE) -> ALUM MATERIAL | V436: =IF(T436="","(blank)",IF(COUNTIF('STANDARD COMM'!A:A,T436)>0,"OK","OUT OF SCOPE")) -> OK
A437: OF0040100 | B437: 45582.527 | D437: F600361 | E437: ARCONIC- KOFEM MILL PRODUCTS HUNGARY KFT. | F437: 26AFC000035 | G437: 46081 | I437: 000050305029R | J437: DISCO AL.L.GREEN 305/29 RIC | K437: alluminio | L437: =VLOOKUP(K437,'COMM ITY- ENG'!A:B,2,FALSE) -> aluminium | N437: 2246 | O437: kg | Q437: =+R437/N437 -> 3.6419991 | R437: 8179.93 | S437: =IFERROR(VLOOKUP(J437,'DESC ITY - ENG'!B:C,2,FALSE),VLOOKUP(I437,'DESC ITY - ENG'!A:C,3,FALSE)) -> Aluminum Disc L. Green Series 305mm x 2.9mm Replacement Part [cite: 3] | T437: =IFERROR(VLOOKUP(S437,'DESC ITY - ENG'!C:D,2,FALSE),VLOOKUP(J437,'DESC ITY - ENG'!B:D,3,FALSE)) -> ALM- | U437: =VLOOKUP(T437,'STANDARD COMM'!A:B,2,FALSE) -> ALUM MATERIAL | V437: =IF(T437="","(blank)",IF(COUNTIF('STANDARD COMM'!A:A,T437)>0,"OK","OUT OF SCOPE")) -> OK
A438: OF0040100 | B438: 45582.527 | D438: F600361 | E438: ARCONIC- KOFEM MILL PRODUCTS HUNGARY KFT. | F438: 26AFC000035 | G438: 46081 | I438: 000050315032R | J438: DISCO AL.L.GREEN 315/32 RIC | K438: alluminio | L438: =VLOOKUP(K438,'COMM ITY- ENG'!A:B,2,FALSE) -> aluminium | N438: 2250 | O438: kg | Q438: =+R438/N438 -> 3.642 | R438: 8194.5 | S438: =IFERROR(VLOOKUP(J438,'DESC ITY - ENG'!B:C,2,FALSE),VLOOKUP(I438,'DESC ITY - ENG'!A:C,3,FALSE)) -> Aluminum Disc L. Green Series 315mm x 3.2mm Replacement Part [cite: 3] | T438: =IFERROR(VLOOKUP(S438,'DESC ITY - ENG'!C:D,2,FALSE),VLOOKUP(J438,'DESC ITY - ENG'!B:D,3,FALSE)) -> ALM- | U438: =VLOOKUP(T438,'STANDARD COMM'!A:B,2,FALSE) -> ALUM MATERIAL | V438: =IF(T438="","(blank)",IF(COUNTIF('STANDARD COMM'!A:A,T438)>0,"OK","OUT OF SCOPE")) -> OK
A439: OF0040508 | B439: 45582.527 | D439: F502625 | E439: INTERNATIONAL COOKWARE S.A.S. | F439: 26AFC000033 | G439: 46081 | I439: 000750000003 | J439: OVALE VET.BORO.26X18 REF.6/360 | K439: accessori finiti | L439: =VLOOKUP(K439,'COMM ITY- ENG'!A:B,2,FALSE) -> finished accessories | N439: 1002 | O439: NR | Q439: =+R439/N439 -> 2.4 | R439: 2404.8 | S439: =IFERROR(VLOOKUP(J439,'DESC ITY - ENG'!B:C,2,FALSE),VLOOKUP(I439,'DESC ITY - ENG'!A:C,3,FALSE)) -> Oval Baking Dish Borosilicate Glass 26x18 cm | T439: =IFERROR(VLOOKUP(S439,'DESC ITY - ENG'!C:D,2,FALSE),VLOOKUP(J439,'DESC ITY - ENG'!B:D,3,FALSE)) -> PAN- | U439: =VLOOKUP(T439,'STANDARD COMM'!A:B,2,FALSE) -> BODY | V439: =IF(T439="","(blank)",IF(COUNTIF('STANDARD COMM'!A:A,T439)>0,"OK","OUT OF SCOPE")) -> OK
A440: OF0040508 | B440: 45582.527 | D440: F502625 | E440: INTERNATIONAL COOKWARE S.A.S. | F440: 26AFC000033 | G440: 46081 | I440: 000750000005 | J440: TEGLIA RET.VET.BORO.39X24 REF.6/216 | K440: accessori finiti | L440: =VLOOKUP(K440,'COMM ITY- ENG'!A:B,2,FALSE) -> finished accessories | N440: 900 | O440: NR | Q440: =+R440/N440 -> 2.95 | R440: 2655 | S440: =IFERROR(VLOOKUP(J440,'DESC ITY - ENG'!B:C,2,FALSE),VLOOKUP(I440,'DESC ITY - ENG'!A:C,3,FALSE)) -> Rectangular Baking Dish Borosilicate Glass 39x24 cm | T440: =IFERROR(VLOOKUP(S440,'DESC ITY - ENG'!C:D,2,FALSE),VLOOKUP(J440,'DESC ITY - ENG'!B:D,3,FALSE)) -> PAN- | U440: =VLOOKUP(T440,'STANDARD COMM'!A:B,2,FALSE) -> BODY | V440: =IF(T440="","(blank)",IF(COUNTIF('STANDARD COMM'!A:A,T440)>0,"OK","OUT OF SCOPE")) -> OK
A441: OF0040508 | B441: 45582.527 | D441: F502625 | E441: INTERNATIONAL COOKWARE S.A.S. | F441: 26AFC000033 | G441: 46081 | I441: 000750000006 | J441: TEGLIA RET.VET.BORO.32X20 REF.7/308 | K441: accessori finiti | L441: =VLOOKUP(K441,'COMM ITY- ENG'!A:B,2,FALSE) -> finished accessories | N441: 1232 | O441: NR | Q441: =+R441/N441 -> 2.3 | R441: 2833.6 | S441: =IFERROR(VLOOKUP(J441,'DESC ITY - ENG'!B:C,2,FALSE),VLOOKUP(I441,'DESC ITY - ENG'!A:C,3,FALSE)) -> Rectangular Baking Dish Borosilicate Glass 32x20 cm | T441: =IFERROR(VLOOKUP(S441,'DESC ITY - ENG'!C:D,2,FALSE),VLOOKUP(J441,'DESC ITY - ENG'!B:D,3,FALSE)) -> PAN- | U441: =VLOOKUP(T441,'STANDARD COMM'!A:B,2,FALSE) -> BODY | V441: =IF(T441="","(blank)",IF(COUNTIF('STANDARD COMM'!A:A,T441)>0,"OK","OUT OF SCOPE")) -> OK
...

Sheet STANDARD COMM
A1: Commodity Code | B1: Commodity Description | C1: Commodity Group (MIL)
A2: ALM- | B2: ALUM MATERIAL | C2: Metal | D2: =_xlfn.TRANSLATE(C2,"en","zh-cht") -> 金屬
A3: BAG- | B3: BAG PACK | C3: Plastic | D3: =_xlfn.TRANSLATE(C3,"en","zh-cht") -> 塑膠
A4: BAKT | B4: BASKET | C4: Kitchen Tools | D4: =_xlfn.TRANSLATE(C4,"en","zh-cht") -> 廚房工具
A5: BFIT | B5: ELE BULK FITG | C5: Electric Material | D5: =_xlfn.TRANSLATE(C5,"en","zh-cht") -> 電材料
A6: BHRE | B6: BROCHURE / LEAFLET / RECIPE | C6: Paper Material | D6: =_xlfn.TRANSLATE(C6,"en","zh-cht") -> 紙張材料
A7: BOX- | B7: BOX / CARTON | C7: Paper Material | D7: =_xlfn.TRANSLATE(C7,"en","zh-cht") -> 紙張材料
A8: BRKT | B8: BRACKET | C8: Fastener | D8: =_xlfn.TRANSLATE(C8,"en","zh-cht") -> 緊固件
A9: CAPS | B9: END CAP SS | C9: Fastener | D9: =_xlfn.TRANSLATE(C9,"en","zh-cht") -> 緊固件
A10: CBS- | B10: CARD BOARD INSERT | C10: Paper Material | D10: =_xlfn.TRANSLATE(C10,"en","zh-cht") -> 紙張材料
A11: CDM- | B11: CLAD MATERIAL | C11: Metal | D11: =_xlfn.TRANSLATE(C11,"en","zh-cht") -> 金屬
A12: CORD | B12: POWER CORD | C12: Electric Material | D12: =_xlfn.TRANSLATE(C12,"en","zh-cht") -> 電材料
A13: CUM- | B13: COPPER MATERIAL | C13: Metal | D13: =_xlfn.TRANSLATE(C13,"en","zh-cht") -> 金屬
... A79: WIRE | B79: LEAD WIRE | C79: Electric Material | D79: =_xlfn.TRANSLATE(C79,"en","zh-cht") -> 電材料
A80: Showing 1 to 78 of 78 entries
A81: Previous
A82: 1
A83: Next
A84: Copyright © 2026 Meyer Manufacturing Company Ltd. All rights reserved.

Sheet COMM ITY- ENG
A2: Italian | B2: English
A3: accessori di confez. | B3: packaging accessories
A4: accessori finiti | B4: finished accessories
A5: accessori x manigl. | B5: accessories for handles
A6: acciaio | B6: steel
A7: Acciaio multistrato (5PLY) | B7: multilayer steel (5PLY)
A8: alluminio | B8: aluminium
A9: cartoni e casse | B9: cartons and boxes
A10: manigliame | B10: handles
A11: mater. di confezion. | B11: packaging material
A12: mater.aus.varie acq. | B12: various auxiliary materials purchased
A13: materiali di consumo | B13: consumable materials
... A16: semilavorato | B16: semi-finished product

Sheet DESC ITY - ENG
A1: Jan - Feb 26 | B1: Part Description | C1: Translated Part Description (English) | D1: Commodity
A2: 000288100051 | B2: 1-5-HSI103C-Y SI HANDLE 16CM SAUCEPAN... | C2: 1-5 SI Handle 16cm Saucepan (6.5mm hole) | D2: HDL--
A3: 000288100051 | B3: 1-5-HSI103C-Y SI HANDLE 16CM SAUCEPAN... | C3: 1-5 SI Handle 16cm Saucepan (6.5mm hole) | D3: HDL--
A4: 000288100052 | B4: 1-5-HSI105C-Y SI HANDLE 20CM SAUCEPAN... | C4: 1-5 SI Handle 20cm Saucepan (6.5mm hole) | D4: HDL--
A5: 000288100052 | B5: 1-5-HSI105C-Y SI HANDLE 20CM SAUCEPAN... | C5: 1-5 SI Handle 20cm Saucepan (6.5mm hole) | D5: HDL--
A6: 000288100055 | B6: 1-5-HSI203C-Y SI HANDLE 20CM SKILLET... | C6: 1-5 SI Handle 20cm Skillet (6.5mm hole) | D6: HDL--
A7: 000288100055 | B7: 1-5-HSI203C-Y SI HANDLE 20CM SKILLET... | C7: 1-5 SI Handle 20cm Skillet (6.5mm hole) | D7: HDL--
A8: 000288100053 | B8: 1-5-HSI107C-Y SI HANDLE 24CM SAUCIER... | C8: 1-5 SI Handle 24cm Saucier (6.5mm hole) | D8: HDL--
A9: 000288100053 | B9: 1-5-HSI107C-Y SI HANDLE 24CM SAUCIER... | C9: 1-5 SI Handle 24cm Saucier (6.5mm hole) | D9: HDL--
A10: 000288100054 | B10: 1-5-HSI108C-Y SI HANDLE 26CM SAUTE'... | C10: 1-5 SI Handle 26cm Saute (6.5mm hole) | D10: HDL--
A11: 000288100054 | B11: 1-5-HSI108C-Y SI HANDLE 26CM SAUTE'... | C11: 1-5 SI Handle 26cm Saute (6.5mm hole) | D11: HDL--
A12: 000288100056 | B12: 1-5-HSI206C-Y SI HANDLE 26CM SKILLET... | C12: 1-5 SI Handle 26cm Skillet (6.5mm hole) | D12: HDL--
... A819: 000730414004 | B819: COPERCHIO SS WOK 32 CM OQC3210AS-001 | C819: Stainless Steel Wok Lid 32cm OQC3210AS-001 | D819: LID-
A820: 1760000324 | B820: FASCIA LIT.MONTAGNE BASIC 279 24 8721381150369 | C820: Litho Sleeve Montagne Basic 279 24 | D820: SHTS
A821: 001760000326 | B821: FASCIA LIT.MONTAGNE BASIC 380 28 8721381150390 | C821: Litho Sleeve Montagne Basic 380 28 | D821: SHTS
A822: 001760000600 | B822: FASCIA LITOGRAFTA CREPE PAN 179Ø 25 8000807075227 | C822: Litho Sleeve Crepe Pan 179 Dia. 25 | D822: SHTS
A823: 001760057800 | B823: FASCIA LIT.TEG.24 MONTANA RESTYLYNG 3522-346 | C823: Litho Sleeve Montana Restyling Pan 24 | D823: SHTS
A824: 001760057801 | B824: FASCIA LIT.TEG.28 MONTANA RESTYLYNG 3524-346 | C824: Litho Sleeve Montana Restyling Pan 28 | D824: SHTS
A825: 001761029103 | B825: FASCIA LIT.MIGROS STAR 2023 PAD.207 Ø20 7035.831-899466 | C825: Litho Sleeve Migros Star 2023 Pan Dia. 20 | D825: SHTS
A826: 001761029105 | B826: FASCIA LIT.MIGROS STAR 2023 PAD.207 Ø28 7035.839-899480 | C826: Litho Sleeve Migros Star 2023 Pan Dia. 28 | D826: SHTS
A827: 001761029109 | B827: FASCIA LIT.MIGROS STAR 2023 TEG.311 Ø28 7035.842-899619 | C827: Litho Sleeve Migros Star 2023 Pan Dia. 28 (Ref. 311) | D827: SHTS
A828: 001761029230 | B828: FASCIA LIT.MIGROS PRO CER.IN.2025 PAD.125Ø20 7038.359-663029 | C828: Litho Sleeve Migros Pro Cer.In. 2025 Pan Dia. 20 | D828: SHTS
A829: 001761029231 | B829: FASCIA LIT.MIGROS PRO CER.IN.2025 PAD.125Ø24 7038.360-663036 | C829: Litho Sleeve Migros Pro Cer.In. 2025 Pan Dia. 24 | D829: SHTS
A830: 001761029232 | B830: FASCIA LIT.MIGROS PRO CER.IN.2025 PAD.125Ø28 7038.361-663043 | C830: Litho Sleeve Migros Pro Cer.In. 2025 Pan Dia. 28 | D830: SHTS
A831: 001761029232 | B831: FASCIA LIT.MIGROS PRO CER.IN.2025 PAD.125Ø28 7038.361-663043 | C831: Litho Sleeve Migros Pro Cer.In. 2025 Pan Dia. 30 | D831: SHTS
A832: 001761029233 | B832: FASCIA LIT.MIGROS PRO CER.IN.2025 PAD.125Ø30 7038.362-663050 | C832: Litho Sleeve Migros Pro Cer.In. 2025 Pan Dia. 28 (Ref. 126) | D832: SHTS
... A930: 000110496001 | B930: GHIERA AR 0400 17/20,5 | C930: Ring Nut AR 0400 17/20.5mm | D930: NUT-
A931: 110520001 | B931: GHIERA AR 0400 16,5/20,5 R100 | C931: Ring Nut AR 0400 16.5/20.5 R100 | D931: NUT-
A932: 110521001 | B932: GHIERA AR 0400 16/19 R110 | C932: Ring Nut AR 0400 16/19 R110 | D932: NUT-
A933: 110559001 | B933: GHIERA L1500 11/30 R58 F90 A-8° | C933: Ring Nut L1500 11/30 R58 F90 A-8° | D933: NUT-
A934: 110593001 | B934: GHIERA P075 11,5/28 R70 F90 A-8° | C934: Ring Nut P075 11.5/28 R70 F90 A-8° | D934: NUT-
A935: 110594001 | B935: GHIERA P075 11,5/26 R55 F100 A-8° | C935: Ring Nut P075 11.5/26 R55 F100 A-8° | D935: NUT-
A936: 110595001 | B936: GHIERA P075 11,5/25 R55 F120 A-8° | C936: Ring Nut P075 11.5/25 R55 F120 A-8° | D936: NUT-
A937: 110635001 | B937: GHIERA AR 0400 17,5/20,5 R100 F140 | C937: Ring Nut AR 0400 17.5/20.5 R100 F140 | D937: NUT-
A938: 110636001 | B938: GHIERA AR 0400 18/20,5 R90 F140 | C938: Ring Nut AR 0400 18/20.5 R90 F140 | D938: NUT-
A939: 110636001 | B939: GHIERA AR 0400 18/20,5 R90 F140 | C939: Ring Nut AR 0400 18/20.5 R90 F140 | D939: NUT-
A940: 110645001 | B940: GHIERA AR 0400 18,5/25,5 R48 F110 | C940: Ring Nut AR 0400 18.5/25.5 R48 F110 | D940: NUT-
A941: 110646001 | B941: GHIERA AR 0400 19/24 R55 F140 A-0° | C941: Ring Nut AR 0400 19/24 R55 F140 A-0° | D941: NUT-
A942: 110649001 | B942: GHIERA AR 0400 15/21,5 R90 F140 A-0° | C942: Ring Nut AR 0400 15/21.5 R90 F140 A-0° | D942: NUT-
... A961: 112370001 | B961: GHIERA P089 15X23 R120 F140 A-8° X 125 28 | C961: Ring Nut P089 15X23 R120 F140 A-8° for 125 28 | D961: NUT-
...

Sheet 工作表2
A3: Commodity Italian | B3: Commodity English
A4: accessori di confez. | B4: packaging accessories
A5: accessori finiti | B5: finished accessories
A6: accessori x manigl. | B6: accessories for handles
A7: acciaio | B7: steel
A8: Acciaio multistrato (5PLY) | B8: multilayer steel (5PLY)
A9: alluminio | B9: aluminium
A10: cartoni e casse | B10: cartons and boxes
A11: manigliame | B11: handles
A12: mater. di confezion. | B12: packaging material
A13: mater.aus.varie acq. | B13: various auxiliary materials purchased
A14: materiali di consumo | B14: consumable materials
... A18: (空白) | B18: (空白)
A19: 總計

Sheet By Gemini
A1: Item Code | B1: Part Description | C1: Commodity Italian | D1: Commodity English | E1: Translated Part Description (English) | F1: Unified Commodity Code
A2: 002300020064 | B2: "DIVISORIO FUST.""B""X PAD.24+28" | C2: cartoni e casse | D2: cartons and boxes | E2: "DIVISORIO FUST.""B""X PAD.24+28" | F2: BOX-
A3: 002490149001 | B3: 1008335 PS UMB EP-62 Blue Oltremare | C3: prodotti chimici | D3: chemical products | E3: 1008335 PS UMB EP-62 Blue Oltremare | F3: CBS-
A4: 003040104009 | B4: 1224-002 DURIT Professional P Primer Black | C4: prodotti chimici | D4: chemical products | E4: 1224-002 DURIT Professional P Primer Black | F4: PRIM
A5: 000288100051 | B5: 1-5-HSI103C-Y SI HANDLE 16CM SAUCEPAN (6.5mm hole) | C5: manigliame | D5: handles | E5: =VLOOKUP(Tabella3[[#This Row],[Item Code]],'DESC ITY - ENG'!A:C,3,FALSE) -> 1-5 SI Handle 16cm Saucepan (6.5mm hole) | F5: =VLOOKUP(Tabella3[[#This Row],[Item Code]],Foglio8!A:C,3,FALSE) -> #N/A
A6: 000288100052 | B6: 1-5-HSI105C-Y SI HANDLE 20CM SAUCEPAN (6.5mm hole) | C6: manigliame | D6: handles | E6: =VLOOKUP(Tabella3[[#This Row],[Item Code]],'DESC ITY - ENG'!A:C,3,FALSE) -> 1-5 SI Handle 20cm Saucepan (6.5mm hole) | F6: =VLOOKUP(Tabella3[[#This Row],[Item Code]],Foglio8!A:C,3,FALSE) -> #N/A
A7: 000288100055 | B7: 1-5-HSI203C-Y SI HANDLE 20CM SKILLET (6.5mm hole) | C7: manigliame | D7: handles | E7: =VLOOKUP(Tabella3[[#This Row],[Item Code]],'DESC ITY - ENG'!A:C,3,FALSE) -> 1-5 SI Handle 20cm Skillet (6.5mm hole) | F7: =VLOOKUP(Tabella3[[#This Row],[Item Code]],Foglio8!A:C,3,FALSE) -> #N/A
A8: 000288100053 | B8: 1-5-HSI107C-Y SI HANDLE 24CM SAUCIER (6.5mm hole) | C8: manigliame | D8: handles | E8: =VLOOKUP(Tabella3[[#This Row],[Item Code]],'DESC ITY - ENG'!A:C,3,FALSE) -> 1-5 SI Handle 24cm Saucier (6.5mm hole) | F8: =VLOOKUP(Tabella3[[#This Row],[Item Code]],Foglio8!A:C,3,FALSE) -> #N/A
A9: 000288100054 | B9: 1-5-HSI108C-Y SI HANDLE 26CM SAUTE' (6.5mm hole) | C9: manigliame | D9: handles | E9: =VLOOKUP(Tabella3[[#This Row],[Item Code]],'DESC ITY - ENG'!A:C,3,FALSE) -> 1-5 SI Handle 26cm Saute (6.5mm hole) | F9: =VLOOKUP(Tabella3[[#This Row],[Item Code]],Foglio8!A:C,3,FALSE) -> #N/A
A10: 000288100056 | B10: 1-5-HSI206C-Y SI HANDLE 26CM SKILLET (6.5mm hole) | C10: manigliame | D10: handles | E10: =VLOOKUP(Tabella3[[#This Row],[Item Code]],'DESC ITY - ENG'!A:C,3,FALSE) -> 1-5 SI Handle 26cm Skillet (6.5mm hole) | F10: =VLOOKUP(Tabella3[[#This Row],[Item Code]],Foglio8!A:C,3,FALSE) -> #N/A
A11: 000288100057 | B11: 1-5-HSI208C-Y SI HANDLE 30CM SKILLET (6.5mm hole) | C11: manigliame | D11: handles | E11: =VLOOKUP(Tabella3[[#This Row],[Item Code]],'DESC ITY - ENG'!A:C,3,FALSE) -> 1-5 SI Handle 30cm Skillet (6.5mm hole) | F11: =VLOOKUP(Tabella3[[#This Row],[Item Code]],Foglio8!A:C,3,FALSE) -> #N/A
A12: 000288000051 | B12: 1-5-HSI103CAY SI HANDLE PVD GOLD 16CM SAUCEPAN (6.5mm hole) | C12: manigliame | D12: handles | E12: =VLOOKUP(Tabella3[[#This Row],[Item Code]],'DESC ITY - ENG'!A:C,3,FALSE) -> 1-5 SI Handle PVD Gold 16cm Saucepan (6.5mm hole) | F12: =VLOOKUP(Tabella3[[#This Row],[Item Code]],Foglio8!A:C,3,FALSE) -> #N/A
A13: 000288000052 | B13: 1-5-HSI105CAY SI HANDLE PVD GOLD 20CM SAUCEPAN (6.5mm hole) | C13: manigliame | D13: handles | E13: =VLOOKUP(Tabella3[[#This Row],[Item Code]],'DESC ITY - ENG'!A:C,3,FALSE) -> 1-5 SI Handle PVD Gold 20cm Saucepan (6.5mm hole) | F13: =VLOOKUP(Tabella3[[#This Row],[Item Code]],Foglio8!A:C,3,FALSE) -> #N/A
A14: 000288000055 | B14: 1-5-HSI203CAY SI HANDLE PVD GOLD 20CM SKILLET (6.5mm hole) | C14: manigliame | D14: handles | E14: =VLOOKUP(Tabella3[[#This Row],[Item Code]],'DESC ITY - ENG'!A:C,3,FALSE) -> 1-5 SI Handle PVD Gold 20cm Skillet (6.5mm hole) | F14: =VLOOKUP(Tabella3[[#This Row],[Item Code]],Foglio8!A:C,3,FALSE) -> #N/A
A15: 000288000053 | B15: 1-5-HSI107CAY SI HANDLE PVD GOLD 24CM SAUCIER (6.5mm hole) | C15: manigliame | D15: handles | E15: =VLOOKUP(Tabella3[[#This Row],[Item Code]],'DESC ITY - ENG'!A:C,3,FALSE) -> 1-5 SI Handle PVD Gold 24cm Saucier (6.5mm hole) | F15: =VLOOKUP(Tabella3[[#This Row],[Item Code]],Foglio8!A:C,3,FALSE) -> #N/A
A16: 000288000054 | B16: 1-5-HSI108CAY SI HANDLE PVD GOLD 26CM SAUTE' (6.5mm hole) | C16: manigliame | D16: handles | E16: =VLOOKUP(Tabella3[[#This Row],[Item Code]],'DESC ITY - ENG'!A:C,3,FALSE) -> 1-5 SI Handle PVD Gold 26cm Saute (6.5mm hole) | F16: =VLOOKUP(Tabella3[[#This Row],[Item Code]],Foglio8!A:C,3,FALSE) -> #N/A
... A20: 000289000052 | B20: 1-5-SSI108CAY SI SIDE IHANDLE PVD GOLD 26CM STOCK.(6.5mm ho) | C20: manigliame | D20: handles | E20: =VLOOKUP(Tabella3[[#This Row],[Item Code]],'DESC ITY - ENG'!A:C,3,FALSE) -> 1-5 SI Side Handle PVD Gold 26cm Stock (6.5mm hole) | F20: =VLOOKUP(Tabella3[[#This Row],[Item Code]],Foglio8!A:C,3,FALSE) -> #N/A
A21: 000288000001 | B21: 1-5-HSI103BAY SI HANDLE PVD GOLD 16CM SAUCEPAN (6.5mm hole) | C21: manigliame | D21: handles | E21: 1-5-HSI103BAY SI HANDLE PVD GOLD 16CM SAUCEPAN (6.5mm hole) | F21: HDL-
A22: 000288100001 | B22: 1-5-HSI103B-Y SI HANDLE 16CM SAUCEPAN (6.5mm hole) | C22: manigliame | D22: handles | E22: 1-5-HSI103B-Y SI HANDLE 16CM SAUCEPAN (6.5mm hole) | F22: HDL-
A23: 000288000002 | B23: 1-5-HSI105BAY SI HANDLE PVD GOLD 20CM SAUCEPAN (6.5mm hole) | C23: manigliame | D23: handles | E23: 1-5-HSI105BAY SI HANDLE PVD GOLD 20CM SAUCEPAN (6.5mm hole) | F23: HDL-
A24: 000288100002 | B24: 1-5-HSI105B-Y SI HANDLE 20CM SAUCEPAN (6.5mm hole) | C24: manigliame | D24: handles | E24: 1-5-HSI105B-Y SI HANDLE 20CM SAUCEPAN (6.5mm hole) | F24: HDL-
A25: 000288000003 | B25: 1-5-HSI107BAY SI HANDLE PVD GOLD 24CM SAUCIER (6.5mm hole) | C25: manigliame | D25: handles | E25: 1-5-HSI107BAY SI HANDLE PVD GOLD 24CM SAUCIER (6.5mm hole) | F25: HDL-
A26: 000288100003 | B26: 1-5-HSI107B-Y SI HANDLE 24CM SAUCIER (6.5mm hole) | C26: manigliame | D26: handles | E26: 1-5-HSI107B-Y SI HANDLE 24CM SAUCIER (6.5mm hole) | F26: HDL-
A27: 000288000004 | B27: 1-5-HSI108BAY SI HANDLE PVD GOLD 26CM SAUTE' (6.5mm hole) | C27: manigliame | D27: handles | E27: 1-5-HSI108BAY SI HANDLE PVD GOLD 26CM SAUTE' (6.5mm hole) | F27: HDL-
A28: 000288100004 | B28: 1-5-HSI108B-Y SI HANDLE 26CM SAUTE' (6.5mm hole) | C28: manigliame | D28: handles | E28: 1-5-HSI108B-Y SI HANDLE 26CM SAUTE' (6.5mm hole) | F28: HDL-
A29: 000288000005 | B29: 1-5-HSI203BAY SI HANDLE PVD GOLD 20CM SKILLET (6.5mm hole) | C29: manigliame | D29: handles | E29: 1-5-HSI203BAY SI HANDLE PVD GOLD 20CM SKILLET (6.5mm hole) | F29: HDL-
A30: 000288100005 | B30: 1-5-HSI203B-Y SI HANDLE 20CM SKILLET (6.5mm hole) | C30: manigliame | D30: handles | E30: 1-5-HSI203B-Y SI HANDLE 20CM SKILLET (6.5mm hole) | F30: HDL-
A31: 000288000006 | B31: 1-5-HSI206BAY SI HANDLE PVD GOLD 26CM SKILLET (6.5mm hole) | C31: manigliame | D31: handles | E31: 1-5-HSI206BAY SI HANDLE PVD GOLD 26CM SKILLET (6.5mm hole) | F31: HDL-
A32: 000288100006 | B32: 1-5-HSI206B-Y SI HANDLE 26CM SKILLET (6.5mm hole) | C32: manigliame | D32: handles | E32: 1-5-HSI206B-Y SI HANDLE 26CM SKILLET (6.5mm hole) | F32: HDL-
... A55: 000030470023 | B55: DISCO 5PLY 470/23 SS304 0,4 + Al1,4 + SS439 0,5 TOT 23/10 | C55: Acciaio multistrato (5PLY) | D55: multilayer steel (5PLY) | E55: 5PLY DISC 470/23 SS304 0,4 + Al1,4 + SS439 0,5 TOT 23/10 | F55: uncl
A56: 000390103024 | B56: VITE 5MAX14 AC.AUTOM.ZIG.C/TORX T25 | C56: accessori x manigl. | D56: accessories for handles | E56: =VLOOKUP(Tabella3[[#This Row],[Item Code]],'DESC ITY - ENG'!A:C,3,FALSE) -> 5x14 Auto Steel Knurled Screw w/ Torx T25 | F56: PRIM
A57: 003160081019 | B57: 7343/V5949Z SILVER Q. CONSTEL. 1P | C57: prodotti chimici | D57: chemical products | E57: 7343/V5949Z SILVER Q. CONSTEL. 1P | F57: uncl
A58: 003481003001 | B58: 750.20 S LACCA R.TER.NERO2978000015 | C58: prodotti chimici | D58: chemical products | E58: 750.20 S LACCA R.TER.NERO2978000015 | F58: SHTS
A59: 009430060001 | B59: 770 PRIMER LOCT0016777 GR.10 | C59: materiali di consumo | D59: consumable materials | E59: 770 PRIMER LOCT0016777 GR.10 | F59: PRIM
A60: 000320212001 | B60: POMOLO 810 STUDIO NERO SATINATO | C60: manigliame | D60: handles | E60: 810 STUDIO SATIN BLACK KNOB | F60: KNOB
A61: 000283490001 | B61: MANIGLIA AC.LEVANTE SABBIATA CASS.D.20 | C61: manigliame | D61: handles | E61: AC.LEVANTE SANDBLASTED HANDLE POT D.20 (472) | F61: HDL-
A62: 000283490001 | B62: MANIGLIA AC.LEVANTE SABBIATA CASS.D.20 (472) | C62: manigliame | D62: handles | E62: AC.LEVANTE SANDBLASTED HANDLE POT D.20 (472) | F62: HDL-
A63: 000281710007 | B63: MANIGLIA AC.SOLE C/LOGO MC AISI 430 SABBIATA CAS.480 20 | C63: manigliame | D63: handles | E63: AC.SOLE HANDLE W/LOGO MC AISI 430 SANDBLASTED CAS.480 20 | F63: HDL-
A64: 000320380001 | B64: POMOLO AC.SOLE C/LOGO MC AISI 430 SABBIATO | C64: manigliame | D64: handles | E64: AC.SOLE KNOB W/LOGO MC AISI 430 SANDBLASTED | F64: KNOB
A65: 000281710005 | B65: MANICO AC.SOLE LUNGO C/LOGO MC AISI 430 SABBIATO PAD.279 30 | C65: manigliame | D65: handles | E65: AC.SOLE LONG HANDLE W/LOGO MC AISI 430 SANDBLASTED PAD.279 30 | F65: HDL-
...

Sheet Foglio8
A1: Item Code | B1: Part Description (English) | C1: UCC Category | D1: SHTS Code
A2: 660202007 | B2: Die-cast Grill Pan Greblon Black 26x17 | C2: ALM- | D2: 7615.10.7100
A3: 660202008 | B3: Die-cast Grill Pan Greblon Black 42x27 | C3: ALM- | D3: 7615.10.7100
A4: 660202009 | B4: Die-cast Pan w/ Ceramic Housing 35x22 | C4: ALM- | D4: 7615.10.7100
A5: 00010315014R | B5: Recycled Aluminum Disc 99.5 315/14 | C5: ALM- | D5: 7606.91.0000
A6: 000040300029R | B6: Recycled Aluminum Disc 4006 300/29 | C6: ALM- | D6: 7606.91.0000
A7: 288000051 | B7: SI Handle PVD Gold 16cm Saucepan | C7: HDL- | D7: 7323.93.0030
A8: 289000051 | B8: SI Side Handle PVD Gold 20cm Saucepan | C8: SHDL | D8: 7323.93.0030
A9: 250517107 | B9: Titano/2 Handle Wood Effect V.0013 | C9: HDL- | D9: 3924.10.4000
A10: 250003001 | B10: Victory/2 Handle - Satin Black | C10: HDL- | D10: 3924.10.4000
A11: 320471001 | B11: Polished Ice Investment Cast Steel Knob | C11: KNOB | D11: 7323.93.0030
A12: 283409001 | B12: Cast Steel Handle for Casserole/Skillet | C12: HDL- | D12: 7323.93.0030
A13: 1717797001 | B13: Flexo Box 7797 + Divider Kit | C13: BOX- | D13: 4819.10.0040
A14: 1761052030 | B14: Litho Band TVS Segno Induction | C14: PAP- | D14: 4821.10.0000
A15: 800017068 | B15: Satin "Made In" Label 60x24 | C15: LABL | D15: 4821.10.0000
A16: 1761150350 | B16: Litho Band Ugnar 472 + Glass Lid | C16: PAP- | D16: 4821.10.0000
A17: 2300004001 | B17: Die-cut Divider Flexo Box 7804-7805 | C17: PAP- | D17: 4819.10.0040
A18: 1880103072 | B18: Paper Divider 103x72cm | C18: PAP- | D18: 4819.10.0040
... A28: 200160004 | B28: Stud Bolt 10x10x17 80° 5MA Thread | C28: STUD | D28: 7318.15.2000
A29: 0001A0140005 | B29: Steel Disc 140/05 AISI430 Smooth/Satin | C29: SM-- | D29: 7210.70.6030

Sheet Foglio4
A1: Purchase Order Date | B1: (più elementi)
A2: Invoice Date | B2: (Tutto)
A4: Commodity English | B4: VendorName | C4: Somma di Total_PO_Price_PO CUR
A5: aluminium | B5: PROFILGLASS SPA | C5: 5499548.8
B6: ALMESAN ALUMINYUM SAN.VE TIC. A.S | C6: 2155038
B7: ARCONIC- KOFEM MILL PRODUCTS HUNGARY KFT. | C7: 583340.65
B8: ZHEJIANG CHICHENG iNDUSTRY & TRADE CO.LTD. | C8: 12372.58
A9: aluminium Totale | C9: 8250300.1
A10: chemical products | B10: WHITFORD SRL | C10: 748582.21
B11: KOREA FINE CERAMIC CO., LTD | C11: 452919.74
B12: EVONIK OPERATIONS GMBH | C12: 244204.5
B13: ILAG INDUSTRIELACK AG | C13: 151565.94
B14: GUJARAT FLUOROCHEMICALS GMBH | C14: 149486.4
B15: CHEMOURS BELGIUM BVBA | C15: 86073
B16: DN CHEMICALS SRL | C16: 37065.09
B17: GENERAL ABRASIVI SRL | C17: 35222.5
B18: ELANTAS EUROPE GMBH | C18: 32589
B19: KRAHN ITALIA SPA | C19: 27680.75
B20: EIGENMANN & VERONELLI SPA | C20: 23439.5
B21: VIBRANTZ ITALY SRL | C21: 23054.88
B22: MERCK SRL | C22: 19490
... B36: MERCK LIFE SCIENCE SRL | C36: 705
A37: chemical products Totale | C37: 2119512.8
A38: handles | B38: LA TERMOPLASTIC-F.B.M. SRL | C38: 651035.31
B39: SIPEX CAVAGNA S.P.A. | C39: 234160.63
B40: YUHUAN SUNNAR RUBBER&PLASTIC PRODUCTS CO.LTD | C40: 203986.17
B41: A&C SRL | C41: 176784.83
B42: SANMIRO SRL | C42: 141145.28
B43: TVS MED S.A.R.L. | C43: 139187.8
B44: MEYER MANUFACTURING COMPANY LIMITED | C44: 135719.95
B45: GULBAK BAKALIT METAL VE TEKSTIL SAN. ve TIC. LTD. STI | C45: 91983
B46: TEKNIKEL MAKINA KALIP IMALAT SAN. VE TIC. LTD STI. | C46: 79476.3
B47: MUTLU METAL DIS TICARET LTD.STI | C47: 78283.93
B48: TECNORESIN SRL | C48: 53880.26
B49: DOLCI EGIDIO SNC DI DOLCI MATTIA E PAOLA | C49: 18898.16
B50: BAUMGARTEN HANDLE SYSTEM KG | C50: 15283.28
... B60: FISCALETTI FAUSTO | C60: 1600
A61: handles Totale | C61: 2104241
A62: cartons and boxes | B62: BOX MARCHE SPA | C62: 898166.33
B63: SCATOLIFICIO I.S.A. SRL | C63: 247749.43
...
