Workbook

Sheet Sheet1
A1: 1st MIL ; 2nd STC ; 3rd MHK ; 4th MZQ ; 5th RACO
A3: VENDOR_NAME | B3: VENDOR_ID | C3: DB | D3: Vend_ID + DB | E3: Std Vend Name
A4: RACO | B4: R017 | C4: MZQ | D4: MZQR017 | E4: RACO
A5: A.I. TOOLS TECH SUPPORT CO., LTD. | B5: A0318 | C5: MIL | D5: MILA0318 | E5: A.I.TOOLS
A6: A.P. INDUSTRY CO., LTD. | B6: A0306 | C6: MIL | D6: MILA0306 | E6: A.P. INDUSTRY
A7: A.R.E. TRADING CO., LTD. | B7: A0017 | C7: MIL | D7: MILA0017 | E7: A.R.E.
A8: ACCESS BUSINESS GROUP | B8: A0184 | C8: MIL | D8: MILA0184 | E8: ABG
A9: ACCESS BUSINESS GROUP | B9: A0232 | C9: MIL | D9: MILA0232 | E9: ABG
A10: ACCESS BUSINESS GROUP (EMS) | B10: A0287 | C10: MIL | D10: MILA0287 | E10: ABG
A11: ACCESS BUSINESS GROUP (MHK) | B11: A0315 | C11: MIL | D11: MILA0315 | E11: ABG
A12: ACCESS BUSINESS GROUP (STC) | B12: A0335 | C12: MIL | D12: MILA0335 | E12: ABG
A13: ACCESS BUSINESS GROUP NSSS (M) | B13: A0139 | C13: MIL | D13: MILA0139 | E13: ABG
A14: ADVANCED TARGETS MATERIALS CO.,LTD. | B14: A0269 | C14: MIL | D14: MILA0269 | E14: ADVANCED TARGETS
... A683: ZHUHAISHIHENGXINNAMIKEJIYOUXIANGONGSI | B683: H104 | C683: RACO | D683: RACOH104 | E683: HENGXIN
A684: Grand Total

Sheet Std Vendor Name
A1: VENDOR_NAME | B1: VENDOR_ID | C1: DB | D1: Vend_ID + DB | E1: Std Vend Name | F1: Remark | G1: 1st MIL ; 2nd STC ; 3rd MHK ; 4th MZQ ; 5th RACO
A2: RACO | B2: R017 | C2: MZQ | D2: MZQR017 | E2: RACO
A3: A.I. TOOLS TECH SUPPORT CO., LTD. | B3: A0318 | C3: MIL | D3: MILA0318 | E3: A.I.TOOLS
A4: A.P. INDUSTRY CO., LTD. | B4: A0306 | C4: MIL | D4: MILA0306 | E4: A.P. INDUSTRY
A5: A.R.E. TRADING CO., LTD. | B5: A0017 | C5: MIL | D5: MILA0017 | E5: A.R.E.
A6: ACCESS BUSINESS GROUP | B6: A0184 | C6: MIL | D6: MILA0184 | E6: ABG
A7: ACCESS BUSINESS GROUP | B7: A0232 | C7: MIL | D7: MILA0232 | E7: ABG
A8: ACCESS BUSINESS GROUP (EMS) | B8: A0287 | C8: MIL | D8: MILA0287 | E8: ABG
A9: ACCESS BUSINESS GROUP (MHK) | B9: A0315 | C9: MIL | D9: MILA0315 | E9: ABG
A10: ACCESS BUSINESS GROUP (STC) | B10: A0335 | C10: MIL | D10: MILA0335 | E10: ABG
A11: ACCESS BUSINESS GROUP NSSS (M) | B11: A0139 | C11: MIL | D11: MILA0139 | E11: ABG
A12: ADVANCED TARGETS MATERIALS CO.,LTD. | B12: A0269 | C12: MIL | D12: MILA0269 | E12: ADVANCED TARGETS
A13: AGC FLAT GLASS (THAILAND) PUBLIC COMPANY LIMITED | B13: A0279 | C13: MIL | D13: MILA0279 | E13: AGC FLAT GLASS (THAILAND)
... A562: TIAN JIN KA XU BAO HUI TU LIAO CO.,LTD. | B562: KX05 | C562: MZQ | D562: MZQKX05 | E562: KA XU BAO HUI
A563: TISCO FOSHAN SALES COMPANY LTD. | B563: TA087 | C563: STC | D563: STCTA087 | E563: TISCO FOSHAN | F563: 飛彼慕
A564: TKS CHEMICAL (THAILAND) CO., LTD. | B564: T0474 | C564: MIL | D564: MILT0474 | E564: TKS | F564: 唐山標先電子
A565: TOMATEC(XIAMEN)FINE MATERIAL CO.,LTD. | B565: TA078 | C565: STC | D565: STCTA078 | E565: TOMATEC | F565: 加利
A566: TOOLS SOLUTION SERVICE CO., LTD. | B566: T0485 | C566: MIL | D566: MILT0485 | E566: TOOLS SOLUTION
A567: TOZZHIN ENTERPRISE SDN,BHD | B567: T0320 | C567: MIL | D567: MILT0320 | E567: TOZZHIN
A568: TVS S.P.A. | B568: T0477 | C568: MIL | D568: MILT0477 | E568: TVS S.P.A.
A569: TVS S.P.A. | B569: T073 | C569: MST | D569: MSTT073 | E569: TVS S.P.A.
A570: ULTIMATE PLUS SUPPLY CO.,LTD. | B570: U0058 | C570: MIL | D570: MILU0058 | E570: ULTIMATE
A571: UNION PETROCHEMICAL PUBLIC CO., LTD. | B571: U0084 | C571: MIL | D571: MILU0084 | E571: UNION
A572: UNION-TECH MACHINERY CO., LTD. | B572: U0016 | C572: MIL | D572: MILU0016 | E572: UNION TECH
A573: UNITED PRECISION ENGINEERING CO., LTD. | B573: U0069 | C573: MIL | D573: MILU0069 | E573: UNITED PRECISION ENGINEERING
A574: UNITEK S.R.L. | B574: U0024 | C574: MIL | D574: MILU0024 | E574: UNITEK S.R.L.
A575: UNITY PROGRESS CO., LTD. | B575: U0062 | C575: MIL | D575: MILU0062 | E575: UNITY
A576: VISION INDUSTRIAL LTD | B576: W018 | C576: RACO | D576: RACOW018 | E576: VISION
A577: VISY PAPER PTY LTD | B577: V0022 | C577: MIL | D577: MILV0022 | E577: VISY
... A584: WEI DA CAI YIN COM.LTD. | B584: WD01 | C584: MZQ | D584: MZQWD01 | E584: WEI DA
A585: WEI XIN BAI WU JIN ZHE PIN | B585: W024 | C585: RACO | D585: RACOW024 | E585: WEI XIN BAI | F585: 理尚 / 維格
A586: WEI XIN BO STAINLESS STEEL Mfg.Ltd. | B586: WS01 | C586: MZQ | D586: MZQWS01 | E586: WEI XIN BO | F586: 銳利
A587: WEI YI PAO MO CAI LIAO | B587: W019 | C587: RACO | D587: RACOW019 | E587: WEI YI
A588: WENZHOU WINNING FLUID EQUIPMENT CO.,LTD | B588: TA071 | C588: STC | D588: STCTA071 | E588: WINNING
A589: WHITFORD (JIANGMEN) LTD.V | B589: W0094 | C589: MIL | D589: MILW0094 | E589: WHITFORD
A590: Whitford Ltd | B590: HF06 | C590: MZQ | D590: MZQHF06 | E590: WHITFORD
A591: WHITFORD LTD. | B591: W0006 | C591: MIL | D591: MILW0006 | E591: WHITFORD
A592: Win &Best Hardware Co.,Ltd . | B592: WS001 | C592: STC | D592: STCWS001 | E592: WIN & BEST
A593: WINNER HI-TECH LIMITED | B593: W504 | C593: MST | D593: MSTW504 | E593: WINNER HI-TECH
A594: WINNER HI-TECH LTD. | B594: W504 | C594: MHK | D594: MHKW504 | E594: WINNER HI-TECH
...

Sheet DATA
A1: VENDOR_ID | B1: VENDOR_NAME | C1: DB | D1: Std Vend Name | E1: VENDOR_NAME | F1: VENDOR_ID | G1: Vend_ID + DB | H1: Std Vend Name
A2: C071 | B2: CHUNG PAK BATTERY WORKS LTD. | C2: MHK | D2: =IF(A2="","",IFERROR(VLOOKUP(CONCATENATE(C2,A2),'Std Vendor Name'!D:E,2,FALSE),"NEW VENDOR")) -> CHUNG PAK | E2: =IF(B2="","",B2) -> CHUNG PAK BATTERY WORKS LTD. | F2: =IF(A2="","",A2) -> C071 | G2: =C2&F2 -> MHKC071 | H2: =D2 -> CHUNG PAK
A3: E036 | B3: E-ANDE (HK) LTD. | C3: MHK | D3: =IF(A3="","",IFERROR(VLOOKUP(CONCATENATE(C3,A3),'Std Vendor Name'!D:E,2,FALSE),"NEW VENDOR")) -> E-ANDE | E3: =IF(B3="","",B3) -> E-ANDE (HK) LTD. | F3: =IF(A3="","",A3) -> E036 | G3: =C3&F3 -> MHKE036 | H3: =D3 -> E-ANDE
A4: M036 | B4: MEYER INDUSTRIES LTD. | C4: MHK | D4: =IF(A4="","",IFERROR(VLOOKUP(CONCATENATE(C4,A4),'Std Vendor Name'!D:E,2,FALSE),"NEW VENDOR")) -> MIL | E4: =IF(B4="","",B4) -> MEYER INDUSTRIES LTD. | F4: =IF(A4="","",A4) -> M036 | G4: =C4&F4 -> MHKM036 | H4: =D4 -> MIL
A5: M044 | B5: MEYER EUROPE SRL (LTD.) | C5: MHK | D5: =IF(A5="","",IFERROR(VLOOKUP(CONCATENATE(C5,A5),'Std Vendor Name'!D:E,2,FALSE),"NEW VENDOR")) -> MES | E5: =IF(B5="","",B5) -> MEYER EUROPE SRL (LTD.) | F5: =IF(A5="","",A5) -> M044 | G5: =C5&F5 -> MHKM044 | H5: =D5 -> MES
A6: M050 | B6: MEYER (ZHAOQING) METAL PRODUCTS CO., LTD. | C6: MHK | D6: =IF(A6="","",IFERROR(VLOOKUP(CONCATENATE(C6,A6),'Std Vendor Name'!D:E,2,FALSE),"NEW VENDOR")) -> MZQ | E6: =IF(B6="","",B6) -> MEYER (ZHAOQING) METAL PRODUCTS CO., LTD. | F6: =IF(A6="","",A6) -> M050 | G6: =C6&F6 -> MHKM050 | H6: =D6 -> MZQ
A7: M056 | B7: MAZAL CORP S.A. | C7: MHK | D7: =IF(A7="","",IFERROR(VLOOKUP(CONCATENATE(C7,A7),'Std Vendor Name'!D:E,2,FALSE),"NEW VENDOR")) -> MAZAL | E7: =IF(B7="","",B7) -> MAZAL CORP S.A. | F7: =IF(A7="","",A7) -> M056 | G7: =C7&F7 -> MHKM056 | H7: =D7 -> MAZAL
A8: R022 | B8: RACO METALWARE INDUSTRIES LTD. | C8: MHK | D8: =IF(A8="","",IFERROR(VLOOKUP(CONCATENATE(C8,A8),'Std Vendor Name'!D:E,2,FALSE),"NEW VENDOR")) -> RACO | E8: =IF(B8="","",B8) -> RACO METALWARE INDUSTRIES LTD. | F8: =IF(A8="","",A8) -> R022 | G8: =C8&F8 -> MHKR022 | H8: =D8 -> RACO
A9: W504 | B9: WINNER HI-TECH LTD. | C9: MHK | D9: =IF(A9="","",IFERROR(VLOOKUP(CONCATENATE(C9,A9),'Std Vendor Name'!D:E,2,FALSE),"NEW VENDOR")) -> WINNER HI-TECH | E9: =IF(B9="","",B9) -> WINNER HI-TECH LTD. | F9: =IF(A9="","",A9) -> W504 | G9: =C9&F9 -> MHKW504 | H9: =D9 -> WINNER HI-TECH
A10: Z012 | B10: ZHAOQING SILVERSTONE TRADING CO., LTD. | C10: MHK | D10: CHUANGMENG | E10: =IF(B10="","",B10) -> ZHAOQING SILVERSTONE TRADING CO., LTD. | F10: =IF(A10="","",A10) -> Z012 | G10: =C10&F10 -> MHKZ012 | H10: =D10 -> CHUANGMENG
A11: DY006 | B11: JIANGMEN DEYIBAO METAL &PLASTIC MFG CO.,LTD | C11: STC | D11: =IF(A11="","",IFERROR(VLOOKUP(CONCATENATE(C11,A11),'Std Vendor Name'!D:E,2,FALSE),"NEW VENDOR")) -> DEYIBAO | E11: =IF(B11="","",B11) -> JIANGMEN DEYIBAO METAL &PLASTIC MFG CO.,LTD | F11: =IF(A11="","",A11) -> DY006 | G11: =C11&F11 -> STCDY006 | H11: =D11 -> DEYIBAO
A12: G0057 | B12: NANNING INDUSTRIAL INVESTMENT ALU FOIL CO.,LTD | C12: STC | D12: =IF(A12="","",IFERROR(VLOOKUP(CONCATENATE(C12,A12),'Std Vendor Name'!D:E,2,FALSE),"NEW VENDOR")) -> ALNAN | E12: =IF(B12="","",B12) -> NANNING INDUSTRIAL INVESTMENT ALU FOIL CO.,LTD | F12: =IF(A12="","",A12) -> G0057 | G12: =C12&F12 -> STCG0057 | H12: =D12 -> ALNAN
A13: GY009 | B13: FOSHAN GUYANG HARDWARE PRODUCTS CO.LTD | C13: STC | D13: =IF(A13="","",IFERROR(VLOOKUP(CONCATENATE(C13,A13),'Std Vendor Name'!D:E,2,FALSE),"NEW VENDOR")) -> GUYANG | E13: =IF(B13="","",B13) -> FOSHAN GUYANG HARDWARE PRODUCTS CO.LTD | F13: =IF(A13="","",A13) -> GY009 | G13: =C13&F13 -> STCGY009 | H13: =D13 -> GUYANG
A14: H0113 | B14: HENAN MINTAI AL. INDUSTRIAL CO.,LTD | C14: STC | D14: =IF(A14="","",IFERROR(VLOOKUP(CONCATENATE(C14,A14),'Std Vendor Name'!D:E,2,FALSE),"NEW VENDOR")) -> HENAN MINTAI | E14: =IF(B14="","",B14) -> HENAN MINTAI AL. INDUSTRIAL CO.,LTD | F14: =IF(A14="","",A14) -> H0113 | G14: =C14&F14 -> STCH0113 | H14: =D14 -> HENAN MINTAI
A15: HQ001 | B15: FOSHAN SHUNDE HUA CHUANG PACKAGING PRINTING FTY | C15: STC | D15: =IF(A15="","",IFERROR(VLOOKUP(CONCATENATE(C15,A15),'Std Vendor Name'!D:E,2,FALSE),"NEW VENDOR")) -> HUA CHUANG | E15: =IF(B15="","",B15) -> FOSHAN SHUNDE HUA CHUANG PACKAGING PRINTING FTY | F15: =IF(A15="","",A15) -> HQ001 | G15: =C15&F15 -> STCHQ001 | H15: =D15 -> HUA CHUANG
A16: J0023 | B16: JOYFU PRECISION CASTING(SHANTOU) CO.,LTD | C16: STC | D16: =IF(A16="","",IFERROR(VLOOKUP(CONCATENATE(C16,A16),'Std Vendor Name'!D:E,2,FALSE),"NEW VENDOR")) -> JOY FU | E16: =IF(B16="","",B16) -> JOYFU PRECISION CASTING(SHANTOU) CO.,LTD | F16: =IF(A16="","",A16) -> J0023 | G16: =C16&F16 -> STCJ0023 | H16: =D16 -> JOY FU
A17: JN003 | B17: XINXING COUNTY JIANENG METAL PRODUCTS CO.,LTD | C17: STC | D17: CIXI | E17: =IF(B17="","",B17) -> XINXING COUNTY JIANENG METAL PRODUCTS CO.,LTD | F17: =IF(A17="","",A17) -> JN003 | G17: =C17&F17 -> STCJN003 | H17: =D17 -> CIXI
A18: LJ011 | B18: NINGBO LIANJIN HARDWARE PRODUCTS CO.,LTD | C18: STC | D18: =IF(A18="","",IFERROR(VLOOKUP(CONCATENATE(C18,A18),'Std Vendor Name'!D:E,2,FALSE),"NEW VENDOR")) -> LIAN JIN | E18: =IF(B18="","",B18) -> NINGBO LIANJIN HARDWARE PRODUCTS CO.,LTD | F18: =IF(A18="","",A18) -> LJ011 | G18: =C18&F18 -> STCLJ011 | H18: =D18 -> LIAN JIN
A19: MX003 | B19: ZHONGSHAN MINGXIN HARDWARE PRODUCTS CO.,LTD | C19: STC | D19: =IF(A19="","",IFERROR(VLOOKUP(CONCATENATE(C19,A19),'Std Vendor Name'!D:E,2,FALSE),"NEW VENDOR")) -> MING XIN | E19: =IF(B19="","",B19) -> ZHONGSHAN MINGXIN HARDWARE PRODUCTS CO.,LTD | F19: =IF(A19="","",A19) -> MX003 | G19: =C19&F19 -> STCMX003 | H19: =D19 -> MING XIN
A20: R0017 | B20: RACO METALWARE INDUSTRIES LIMITED | C20: STC | D20: =IF(A20="","",IFERROR(VLOOKUP(CONCATENATE(C20,A20),'Std Vendor Name'!D:E,2,FALSE),"NEW VENDOR")) -> RACO | E20: =IF(B20="","",B20) -> RACO METALWARE INDUSTRIES LIMITED | F20: =IF(A20="","",A20) -> R0017 | G20: =C20&F20 -> STCR0017 | H20: =D20 -> RACO
A21: TA021 | B21: FOSHAN KUILOON METAL PRODUCTS CO.,LTD | C21: STC | D21: =IF(A21="","",IFERROR(VLOOKUP(CONCATENATE(C21,A21),'Std Vendor Name'!D:E,2,FALSE),"NEW VENDOR")) -> KUILOON | E21: =IF(B21="","",B21) -> FOSHAN KUILOON METAL PRODUCTS CO.,LTD | F21: =IF(A21="","",A21) -> TA021 | G21: =C21&F21 -> STCTA021 | H21: =D21 -> KUILOON
A22: TA025 | B22: FOSHAN SANSHUI LUJIANG HW PRODUCTS CO.,LTD | C22: STC | D22: =IF(A22="","",IFERROR(VLOOKUP(CONCATENATE(C22,A22),'Std Vendor Name'!D:E,2,FALSE),"NEW VENDOR")) -> LU JIANG | E22: =IF(B22="","",B22) -> FOSHAN SANSHUI LUJIANG HW PRODUCTS CO.,LTD | F22: =IF(A22="","",A22) -> TA025 | G22: =C22&F22 -> STCTA025 | H22: =D22 -> LU JIANG
A23: TA026 | B23: ZHAOQING GAOYAO ZHAODE METAL PRODUCTS CO.,LTD | C23: STC | D23: =IF(A23="","",IFERROR(VLOOKUP(CONCATENATE(C23,A23),'Std Vendor Name'!D:E,2,FALSE),"NEW VENDOR")) -> ZHAO DE | E23: =IF(B23="","",B23) -> ZHAOQING GAOYAO ZHAODE METAL PRODUCTS CO.,LTD | F23: =IF(A23="","",A23) -> TA026 | G23: =C23&F23 -> STCTA026 | H23: =D23 -> ZHAO DE
A24: TA027 | B24: FOSHAN SANSHUI SOUTHWEST STREET ZHUOYING HW FTY | C24: STC | D24: =IF(A24="","",IFERROR(VLOOKUP(CONCATENATE(C24,A24),'Std Vendor Name'!D:E,2,FALSE),"NEW VENDOR")) -> ZHUO YING | E24: =IF(B24="","",B24) -> FOSHAN SANSHUI SOUTHWEST STREET ZHUOYING HW FTY | F24: =IF(A24="","",A24) -> TA027 | G24: =C24&F24 -> STCTA027 | H24: =D24 -> ZHUO YING
A25: TA035 | B25: FOSHAN E-YOUN COOKWARE LTD | C25: STC | D25: RUYI | E25: =IF(B25="","",B25) -> FOSHAN E-YOUN COOKWARE LTD | F25: =IF(A25="","",A25) -> TA035 | G25: =C25&F25 -> STCTA035 | H25: =D25 -> RUYI
A26: TA041 | B26: HENGYU METAL PRODUCTS (GUANGDONG) CO.,LTD | C26: STC | D26: =IF(A26="","",IFERROR(VLOOKUP(CONCATENATE(C26,A26),'Std Vendor Name'!D:E,2,FALSE),"NEW VENDOR")) -> HENG XIN / HANG SENG | E26: =IF(B26="","",B26) -> HENGYU METAL PRODUCTS (GUANGDONG) CO.,LTD | F26: =IF(A26="","",A26) -> TA041 | G26: =C26&F26 -> STCTA041 | H26: =D26 -> HENG XIN / HANG SENG
A27: TA042 | B27: SAFE POWER PRINTING & BOX (DONG GUAN) MFG CO., LTD | C27: STC | D27: =IF(A27="","",IFERROR(VLOOKUP(CONCATENATE(C27,A27),'Std Vendor Name'!D:E,2,FALSE),"NEW VENDOR")) -> SAFE POWER PRINTING | E27: =IF(B27="","",B27) -> SAFE POWER PRINTING & BOX (DONG GUAN) MFG CO., LTD | F27: =IF(A27="","",A27) -> TA042 | G27: =C27&F27 -> STCTA042 | H27: =D27 -> SAFE POWER PRINTING
A28: TA047 | B28: JINHUA HENG XIN COOKWARE CO.,LTD | C28: STC | D28: =IF(A28="","",IFERROR(VLOOKUP(CONCATENATE(C28,A28),'Std Vendor Name'!D:E,2,FALSE),"NEW VENDOR")) -> JINHUA HENGXIN | E28: =IF(B28="","",B28) -> JINHUA HENG XIN COOKWARE CO.,LTD | F28: =IF(A28="","",A28) -> TA047 | G28: =C28&F28 -> STCTA047 | H28: =D28 -> JINHUA HENGXIN
A29: TA067 | B29: FLORAL SEASON HOME FASHIONS CO.,LTD | C29: STC | D29: =IF(A29="","",IFERROR(VLOOKUP(CONCATENATE(C29,A29),'Std Vendor Name'!D:E,2,FALSE),"NEW VENDOR")) -> FLORAL SEASON | E29: =IF(B29="","",B29) -> FLORAL SEASON HOME FASHIONS CO.,LTD | F29: =IF(A29="","",A29) -> TA067 | G29: =C29&F29 -> STCTA067 | H29: =D29 -> FLORAL SEASON
A30: TA077 | B30: FOSHAN SHUNDE JIWEI PLASTIC PRDS CO. LTD (ENTHEOS) | C30: STC | D30: =IF(A30="","",IFERROR(VLOOKUP(CONCATENATE(C30,A30),'Std Vendor Name'!D:E,2,FALSE),"NEW VENDOR")) -> JIWEI | E30: =IF(B30="","",B30) -> FOSHAN SHUNDE JIWEI PLASTIC PRDS CO. LTD (ENTHEOS) | F30: =IF(A30="","",A30) -> TA077 | G30: =C30&F30 -> STCTA077 | H30: =D30 -> JIWEI
A31: TA082 | B31: FOSHAN TAIPERS KITCHEN PRODUCTS DEVT CO., LTD | C31: STC | D31: =IF(A31="","",IFERROR(VLOOKUP(CONCATENATE(C31,A31),'Std Vendor Name'!D:E,2,FALSE),"NEW VENDOR")) -> TAIPERS | E31: =IF(B31="","",B31) -> FOSHAN TAIPERS KITCHEN PRODUCTS DEVT CO., LTD | F31: =IF(A31="","",A31) -> TA082 | G31: =C31&F31 -> STCTA082 | H31: =D31 -> TAIPERS
A32: TA084 | B32: GLOBAL CLAD TECHNICAL CO., LTD. | C32: STC | D32: =IF(A32="","",IFERROR(VLOOKUP(CONCATENATE(C32,A32),'Std Vendor Name'!D:E,2,FALSE),"NEW VENDOR")) -> GLOBAL CLAD | E32: =IF(B32="","",B32) -> GLOBAL CLAD TECHNICAL CO., LTD. | F32: =IF(A32="","",A32) -> TA084 | G32: =C32&F32 -> STCTA084 | H32: =D32 -> GLOBAL CLAD
A33: TA086 | B33: ZHEJIANG CHENGDE METAL PRODUCTS CO., LTD | C33: STC | D33: =IF(A33="","",IFERROR(VLOOKUP(CONCATENATE(C33,A33),'Std Vendor Name'!D:E,2,FALSE),"NEW VENDOR")) -> CHENGDE | E33: =IF(B33="","",B33) -> ZHEJIANG CHENGDE METAL PRODUCTS CO., LTD | F33: =IF(A33="","",A33) -> TA086 | G33: =C33&F33 -> STCTA086 | H33: =D33 -> CHENGDE
A34: TA087 | B34: TISCO FOSHAN SALES COMPANY LTD. | C34: STC | D34: =IF(A34="","",IFERROR(VLOOKUP(CONCATENATE(C34,A34),'Std Vendor Name'!D:E,2,FALSE),"NEW VENDOR")) -> TISCO FOSHAN | E34: =IF(B34="","",B34) -> TISCO FOSHAN SALES COMPANY LTD. | F34: =IF(A34="","",A34) -> TA087 | G34: =C34&F34 -> STCTA087 | H34: =D34 -> TISCO FOSHAN
A35: TA088 | B35: ZHEJIANG CHICHENG INDUSTRY AND TRADE CO., LTD | C35: STC | D35: =IF(A35="","",IFERROR(VLOOKUP(CONCATENATE(C35,A35),'Std Vendor Name'!D:E,2,FALSE),"NEW VENDOR")) -> CHICHENG | E35: =IF(B35="","",B35) -> ZHEJIANG CHICHENG INDUSTRY AND TRADE CO., LTD | F35: =IF(A35="","",A35) -> TA088 | G35: =C35&F35 -> STCTA088 | H35: =D35 -> CHICHENG
A36: WH003 | B36: WUHA WEIHUA ALUMINUM INDUSTRY CO.,LTD | C36: STC | D36: =IF(A36="","",IFERROR(VLOOKUP(CONCATENATE(C36,A36),'Std Vendor Name'!D:E,2,FALSE),"NEW VENDOR")) -> WEIHUA | E36: =IF(B36="","",B36) -> WUHA WEIHUA ALUMINUM INDUSTRY CO.,LTD | F36: =IF(A36="","",A36) -> WH003 | G36: =C36&F36 -> STCWH003 | H36: =D36 -> WEIHUA
A37: WS001 | B37: WIN &BEST HARDWARE CO.,LTD | C37: STC | D37: =IF(A37="","",IFERROR(VLOOKUP(CONCATENATE(C37,A37),'Std Vendor Name'!D:E,2,FALSE),"NEW VENDOR")) -> WIN & BEST | E37: =IF(B37="","",B37) -> WIN &BEST HARDWARE CO.,LTD | F37: =IF(A37="","",A37) -> WS001 | G37: =C37&F37 -> STCWS001 | H37: =D37 -> WIN & BEST
... A60: YD11 | B60: YI DA FENG XIANG SHU WU JING | C60: MZQ | D60: =IF(A60="","",IFERROR(VLOOKUP(CONCATENATE(C60,A60),'Std Vendor Name'!D:E,2,FALSE),"NEW VENDOR")) -> YI DA FENG | E60: =IF(B60="","",B60) -> YI DA FENG XIANG SHU WU JING | F60: =IF(A60="","",A60) -> YD11 | G60: =C60&F60 -> MZQYD11 | H60: =D60 -> YI DA FENG
A61: J023 | C61: MZQ | D61: =IF(A61="","",IFERROR(VLOOKUP(CONCATENATE(C61,A61),'Std Vendor Name'!D:E,2,FALSE),"NEW VENDOR")) -> JOY FU | E61: =IF(B61="","",B61) | F61: =IF(A61="","",A61) -> J023 | G61: =C61&F61 -> MZQJ023 | H61: =D61 -> JOY FU
A62: HY25 | B62: ZHAO QING SHI HENG YING WU JING HUA GONG CO.,LTD | C62: MZQ | D62: =IF(A62="","",IFERROR(VLOOKUP(CONCATENATE(C62,A62),'Std Vendor Name'!D:E,2,FALSE),"NEW VENDOR")) -> HENG YING | E62: =IF(B62="","",B62) -> ZHAO QING SHI HENG YING WU JING HUA GONG CO.,LTD | F62: =IF(A62="","",A62) -> HY25 | G62: =C62&F62 -> MZQHY25 | H62: =D62 -> HENG YING
...
