Workbook
Name DATA: 'Hoja1 (2)'!$N$11:$O$53

Sheet Hoja1
A3: Etiquetas de fila | B3: Part Description | C3: Commodity
A4: 19041 | B4: 16CM RIM GASKET | C4: GSKT
A5: 19042 | B5: 20CM RIM GASKET | C5: GSKT
A6: 19043 | B6: 26CM RIM GASKET | C6: GSKT
A7: 19046 | B7: 35CM RIM GASKET - NEW MODEL | C7: GSKT
A8: 19047 | B8: 26CM RIM GASKET - NEW MODEL | C8: GSKT
A9: 22095 | B9: STRECH FILM DE 20" X 12MIC X 2 KG (TRANSPARENT) | C9: BAG-
A10: 22389 | B10: CO4600 - BOX 5PC ESS.COOK SYSTEM | C10: CBS-
A11: 22390 | B11: CO4600 - CARDBOARD COVER AT THE BOTTOM 5PC ESS.COOK SYSTEM | C11: CBS-
A12: 22391 | B12: CO4600 - CARDBOARD LID HOLDER 16CM - 5PC S.C.S. | C12: CBS-
A13: 22392 | B13: CO4600 - CARDBOARD LID HOLDER 20CM - 5PC S.C.S. | C13: CBS-
A14: 22393 | B14: CO4600 - CARDBOARD SHEET FOR TOP COVERING - 5PC S.C.S. | C14: CBS-
A15: 22394 | B15: CO4600 - CARDBOARD COVER N°2 | C15: CBS-
... A17: 22396 | B17: CO4610 - BOTTOM CARDBOARD PROTECTOR FOR 5PC C.C.S. | C17: CBS-
B18: CO4610 - CARDBOARD COVER AT THE BOTTOM - 5PC C.C.S. | C18: CBS-
A19: 22397 | B19: CO4610 - CARDBOAR SUPPORT 1 | C19: CBS-
B20: CO4610 - CARDBOARD SUPPORT 1 | C20: CBS-
A21: 22398 | B21: CO4610 - CARDBOAR SUPPORT 2 | C21: CBS-
B22: CO4610 - CARDBOARD SUPPORT 2 | C22: CBS-
A23: 22399 | B23: CO4610 - CARDBOARD SHEET FOR TOP COVERING - 5PC CCS | C23: CBS-
A24: 22400 | B24: CO4610 - CARDBOARD RING TO PROTECT THE LID 20CM | C24: CBS-
A25: 22401 | B25: CO4805 - BOX FOR 10"/24CM GOURMET COVER | C25: CBS-
A26: 22402 | B26: CO4705 - BOX FOR 2QT/16CM SAUCEPAN ONLY | C26: CBS-
A27: 22403 | B27: CO4705 - CARDBOARD SUPPORT PIECE FOR/HANDLE | C27: CBS-
A28: 22404 | B28: CO4705 - CARDBOARD SUPPORT PIECE FOR/BOWL | C28: CBS-
A29: 22405 | B29: CO4710 - BOX FOR 3QT/20CM SAUCEPAN ONLY | C29: CBS-
A30: 22406 | B30: CO4710 - CARDBOARD SUPPORT PIECE FOR BOWL P/3QT | C30: CBS-
A31: 22407 | B31: CO4710 - CARDBOARD SUPPORT PIECE FOR HANDLE P/3QT | C31: CBS-
A32: 22408 | B32: CO4715 - BOX 4QT/20CM DUTCH OVEN W/COVER | C32: CBS-
A33: 22409 | B33: CO4715 - CORNER PIECE 4QT/20CM DUTCH OVEN - JGO X 2 UNDS | C33: CBS-
A34: 22410 | B34: CO4715 - CARDBOARD SHEET FOR TOP COVERING 4QT/20CM DUTCH OVEN | C34: CBS-
... A112: 241133 | B112: WHEEL ASAFLAP GRANO 40 DE 6" X 1.1/2 X 1" | C112: POLW
A113: RP4900 | B113: MEDIUM OVER MOLDED KNOB | C113: KNOB
A114: RP4901 | B114: LARGE OVERMOLDED KNOB | C114: KNOB
A115: RP4902 | B115: WHISTLE | C115: uncl
A116: RP4903 | B116: HANDLE FOR 1.5QT AND 2QT SAUCE PAN | C116: HDL-
A117: RP4904 | B117: HANDLE FOR 3QT SAUCE PAN AND 20CM/8 INCH SKILLET | C117: HDL-
A118: RP4905 | B118: SIDE HANDLE FOR 4QT DUTCH OVEN AND 20CM/8" SKILLET | C118: SHDL
A119: RP4906 | B119: HANDLE FOR 26CM/10.5" SKILLET | C119: HDL-
A120: RP4907 | B120: SIDE HANDLE FOR 6QT D.OVEN, 8QT D.OVEN AND 26CM/10.5" SK | C120: SHDL
...

Sheet Hoja2
A1: Etiquetas de fila | B1: Part Description | C1: Commodity
A2: 19041 | B2: 16CM RIM GASKET | C2: GSKT
A3: 19042 | B3: 20CM RIM GASKET | C3: GSKT
A4: 19043 | B4: 26CM RIM GASKET | C4: GSKT
A5: 19046 | B5: 35CM RIM GASKET - NEW MODEL | C5: GSKT
A6: 19047 | B6: 26CM RIM GASKET - NEW MODEL | C6: GSKT
A7: 22095 | B7: STRECH FILM DE 20" X 12MIC X 2 KG (TRANSPARENT) | C7: BAG-
A8: 22389 | B8: CO4600 - BOX 5PC ESS.COOK SYSTEM | C8: CBS-
A9: 22390 | B9: CO4600 - CARDBOARD COVER AT THE BOTTOM 5PC ESS.COOK SYSTEM | C9: CBS-
A10: 22391 | B10: CO4600 - CARDBOARD LID HOLDER 16CM - 5PC S.C.S. | C10: CBS-
A11: 22392 | B11: CO4600 - CARDBOARD LID HOLDER 20CM - 5PC S.C.S. | C11: CBS-
A12: 22393 | B12: CO4600 - CARDBOARD SHEET FOR TOP COVERING - 5PC S.C.S. | C12: CBS-
A13: 22394 | B13: CO4600 - CARDBOARD COVER N°2 | C13: CBS-
... A107: 241133 | B107: WHEEL ASAFLAP GRANO 40 DE 6" X 1.1/2 X 1" | C107: POLW
A108: RP4900 | B108: MEDIUM OVER MOLDED KNOB | C108: KNOB
A109: RP4901 | B109: LARGE OVERMOLDED KNOB | C109: KNOB
A110: RP4902 | B110: WHISTLE | C110: uncl
A111: RP4903 | B111: HANDLE FOR 1.5QT AND 2QT SAUCE PAN | C111: HDL-
A112: RP4904 | B112: HANDLE FOR 3QT SAUCE PAN AND 20CM/8 INCH SKILLET | C112: HDL-
A113: RP4905 | B113: SIDE HANDLE FOR 4QT DUTCH OVEN AND 20CM/8" SKILLET | C113: SHDL
A114: RP4906 | B114: HANDLE FOR 26CM/10.5" SKILLET | C114: HDL-
A115: RP4907 | B115: SIDE HANDLE FOR 6QT D.OVEN, 8QT D.OVEN AND 26CM/10.5" SK | C115: SHDL
A116: RP4909 | B116: HANDLE FOR 8" GOURMET SKILLET | C116: HDL-
A117: RP4910 | B117: HANDLE FOR 10" GOURMET SKILLET | C117: HDL-
A118: RP4913 | B118: SIDE HANDLE FOR 20CM STEAMER/COLANDOR | C118: SHDL
A119: RP4921 | B119: SIDE HANDLE FOR 10" PAELLA PAN | C119: SHDL

Sheet MHK
A1: Purchase Order Number | B1: Purchase Order Date | C1: Purchase order issue date | D1: Vendor ID | E1: VendorName | F1: Vendor_Invoice_No | G1: REF_NO | H1: Item Code | I1: Part Description | J1: Commodity | K1: Division | L1: Quantity | M1: Unit | N1: PO_Price_PO CUR | O1: PO UNIT PRICE PO_CUR | P1: Total_PO_Price_PO CUR
A2: OC-14027 | B2: 46259 | C2: 46204.491 | D2: 203 | E2: INGENIERIA EN CARTONES Y PAPELES S.A.C. | F2: FACTURA ELECTRÓNICA: F001-00097535 | G2: NI:17031 | H2: 22389 | I2: CO4600 - BOX 5PC ESS.COOK SYSTEM | J2: CBS- | K2: 1 | L2: 935 | M2: UN | N2: USD | O2: 4.543 | P2: 4247.705
A3: OC-14027 | B3: 46259 | C3: 46204.491 | D3: 203 | E3: INGENIERIA EN CARTONES Y PAPELES S.A.C. | F3: FACTURA ELECTRÓNICA: F001-00097535 | G3: NI:17031 | H3: 22411 | I3: CO4720 - BOX 6QT/26CM DUTCH OVN ONLY | J3: CBS- | K3: 1 | L3: 2107 | M3: UN | N3: USD | O3: 2.836 | P3: 5975.452
A4: OC-14027 | B4: 46259 | C4: 46204.491 | D4: 203 | E4: INGENIERIA EN CARTONES Y PAPELES S.A.C. | F4: FACTURA ELECTRÓNICA: F001-00097535 | G4: NI:17031 | H4: 22413 | I4: CO4730 - BOX 8"/20CM SKILLET ONLY | J4: CBS- | K4: 1 | L4: 2100 | M4: UN | N4: USD | O4: 2.374 | P4: 4985.4
A5: OC-14027 | B5: 46259 | C5: 46204.491 | D5: 203 | E5: INGENIERIA EN CARTONES Y PAPELES S.A.C. | F5: FACTURA ELECTRÓNICA: F001-00097535 | G5: NI:17031 | H5: 22420 | I5: CO4746 - BOX 8"/20CM GOURMET SKILLET ONLY | J5: CBS- | K5: 1 | L5: 2115 | M5: UN | N5: USD | O5: 2.314 | P5: 4894.11
A6: OC-14027 | B6: 46259 | C6: 46204.491 | D6: 203 | E6: INGENIERIA EN CARTONES Y PAPELES S.A.C. | F6: FACTURA ELECTRÓNICA: F001-00097536 | G6: NI:17032 | H6: 22391 | I6: CO4600 - CARDBOARD LID HOLDER 16CM - 5PC S.C.S. | J6: CBS- | K6: 1 | L6: 548 | M6: UN | N6: USD | O6: 0.176 | P6: 96.448
A7: OC-14027 | B7: 46259 | C7: 46204.491 | D7: 203 | E7: INGENIERIA EN CARTONES Y PAPELES S.A.C. | F7: FACTURA ELECTRÓNICA: F001-00097536 | G7: NI:17032 | H7: 22390 | I7: CO4600 - CARDBOARD COVER AT THE BOTTOM 5PC ESS.COOK SYSTEM | J7: CBS- | K7: 1 | L7: 1086 | M7: UN | N7: USD | O7: 0.337 | P7: 365.982
A8: OC-14027 | B8: 46259 | C8: 46204.491 | D8: 203 | E8: INGENIERIA EN CARTONES Y PAPELES S.A.C. | F8: FACTURA ELECTRÓNICA: F001-00097536 | G8: NI:17032 | H8: 22490 | I8: CO4600 - SMALL CARDBOARD CORNER / JGO X 02 UNDS | J8: CBS- | K8: 1 | L8: 1100 | M8: UN | N8: USD | O8: 0.322 | P8: 354.2
A9: OC-14027 | B9: 46259 | C9: 46204.491 | D9: 203 | E9: INGENIERIA EN CARTONES Y PAPELES S.A.C. | F9: FACTURA ELECTRÓNICA: F001-00097536 | G9: NI:17032 | H9: 22488 | I9: CO4600 - CARDBOARD LID HOLDER | J9: CBS- | K9: 1 | L9: 1100 | M9: UN | N9: USD | O9: 0.101 | P9: 111.1
A10: OC-14027 | B10: 46259 | C10: 46204.491 | D10: 203 | E10: INGENIERIA EN CARTONES Y PAPELES S.A.C. | F10: FACTURA ELECTRÓNICA: F001-00097536 | G10: NI:17032 | H10: 22489 | I10: CO4600 - CARDBOARD COVER N°3 | J10: CBS- | K10: 1 | L10: 1100 | M10: UN | N10: USD | O10: 0.322 | P10: 354.2
A11: OC-14027 | B11: 46259 | C11: 46204.491 | D11: 203 | E11: INGENIERIA EN CARTONES Y PAPELES S.A.C. | F11: FACTURA ELECTRÓNICA: F001-00097536 | G11: NI:17032 | H11: 22491 | I11: CO4600 - LARGE CARDBOARD CORNER | J11: CBS- | K11: 1 | L11: 1100 | M11: UN | N11: USD | O11: 0.213 | P11: 234.3
A12: OC-14027 | B12: 46259 | C12: 46204.491 | D12: 203 | E12: INGENIERIA EN CARTONES Y PAPELES S.A.C. | F12: FACTURA ELECTRÓNICA: F001-00097536 | G12: NI:17032 | H12: 22393 | I12: CO4600 - CARDBOARD SHEET FOR TOP COVERING - 5PC S.C.S. | J12: CBS- | K12: 1 | L12: 1086 | M12: UN | N12: USD | O12: 0.176 | P12: 191.136
A13: OC-14027 | B13: 46259 | C13: 46204.491 | D13: 203 | E13: INGENIERIA EN CARTONES Y PAPELES S.A.C. | F13: FACTURA ELECTRÓNICA: F001-00097536 | G13: NI:17032 | H13: 22392 | I13: CO4600 - CARDBOARD LID HOLDER 20CM - 5PC S.C.S. | J13: CBS- | K13: 1 | L13: 1100 | M13: UN | N13: USD | O13: 0.2 | P13: 220
... A52: OC-13870 | B52: 46234 | C52: 46133.441 | D52: 3580 | E52: GEOLINK PERU E.I.R.L. | F52: FACTURA ELECTRÓNICA: E001-200 | G52: NI:16994 | H52: 23373 | I52: STAINLESS STEEL DISC 1PLY SS316L Ø405*1.0 - CO4803/CO4808 | J52: SM-- | K52: 1 | L52: 1002 | M52: KG | N52: USD | O52: 5.7884232 | P52: 5800
A53: OI-1094 | B53: 46230 | C53: 46050.569 | D53: 2953 | E53: MEYER MANUFACTURING COMPANY LIMITED | F53: INVOICE: 2J260008 | G53: NI:16987 | H53: RP4906 | I53: HANDLE FOR 26CM/10.5" SKILLET | J53: HDL- | K53: 1 | L53: 1955 | M53: UN | N53: USD | O53: 3.45 | P53: 6744.75
A54: OI-1094 | B54: 46230 | C54: 46050.569 | D54: 2953 | E54: MEYER MANUFACTURING COMPANY LIMITED | F54: INVOICE: 2J260008 | G54: NI:16987 | H54: RP4904 | I54: HANDLE FOR 3QT SAUCE PAN AND 20CM/8 INCH SKILLET | J54: HDL- | K54: 1 | L54: 3385 | M54: UN | N54: USD | O54: 3.45 | P54: 11678.25
A55: OI-1094 | B55: 46230 | C55: 46050.569 | D55: 2953 | E55: MEYER MANUFACTURING COMPANY LIMITED | F55: INVOICE: 7J260009 | G55: NI:16988 | H55: RP4921 | I55: SIDE HANDLE FOR 10" PAELLA PAN | J55: SHDL | K55: 1 | L55: 6380 | M55: UN | N55: USD | O55: 2.11 | P55: 13461.8
A56: OI-1094 | B56: 46230 | C56: 46050.569 | D56: 2953 | E56: MEYER MANUFACTURING COMPANY LIMITED | F56: INVOICE: 7J260009 | G56: NI:16988 | H56: RP4907 | I56: SIDE HANDLE FOR 6QT D.OVEN, 8QT D.OVEN AND 26CM/10.5" SK | J56: SHDL | K56: 1 | L56: 7940 | M56: UN | N56: USD | O56: 2.11 | P56: 16753.4
A57: OI-1094 | B57: 46230 | C57: 46050.569 | D57: 2953 | E57: MEYER MANUFACTURING COMPANY LIMITED | F57: INVOICE: 7J260009 | G57: NI:16988 | H57: RP4905 | I57: SIDE HANDLE FOR 4QT DUTCH OVEN AND 20CM/8" SKILLET | J57: SHDL | K57: 1 | L57: 4200 | M57: UN | N57: USD | O57: 2.11 | P57: 8862
A58: OI-1095 | B58: 46230 | C58: 46133.436 | D58: 2953 | E58: MEYER MANUFACTURING COMPANY LIMITED | F58: INVOICE: 7J260009 | G58: NI:16989 | H58: RP4905 | I58: SIDE HANDLE FOR 4QT DUTCH OVEN AND 20CM/8" SKILLET | J58: SHDL | K58: 1 | L58: 1000 | M58: UN | N58: USD | O58: 2.11 | P58: 2110
A59: OI-1095 | B59: 46230 | C59: 46133.436 | D59: 2953 | E59: MEYER MANUFACTURING COMPANY LIMITED | F59: INVOICE: 7J260009 | G59: NI:16989 | H59: RP4921 | I59: SIDE HANDLE FOR 10" PAELLA PAN | J59: SHDL | K59: 1 | L59: 3000 | M59: UN | N59: USD | O59: 2.11 | P59: 6330
A60: OC-13963 | B60: 46230 | C60: 46177.481 | D60: 3852 | E60: UNION CARTONERA S.R.L | F60: FACTURA ELECTRÓNICA: FT01-00008808 | G60: NI:16990 | H60: 22396 | I60: CO4610 - BOTTOM CARDBOARD PROTECTOR FOR 5PC C.C.S. | J60: CBS- | K60: 1 | L60: 1100 | M60: UN | N60: PEN | O60: 1.34 | P60: 1474
A61: OC-13963 | B61: 46230 | C61: 46177.481 | D61: 3852 | E61: UNION CARTONERA S.R.L | F61: FACTURA ELECTRÓNICA: FT01-00008808 | G61: NI:16990 | H61: 22397 | I61: CO4610 - CARDBOAR SUPPORT 1 | J61: CBS- | K61: 1 | L61: 1100 | M61: UN | N61: PEN | O61: 1.5 | P61: 1650
A62: OC-13963 | B62: 46230 | C62: 46177.481 | D62: 3852 | E62: UNION CARTONERA S.R.L | F62: FACTURA ELECTRÓNICA: FT01-00008808 | G62: NI:16990 | H62: 22399 | I62: CO4610 - CARDBOARD SHEET FOR TOP COVERING - 5PC CCS | J62: CBS- | K62: 1 | L62: 1100 | M62: UN | N62: PEN | O62: 0.76 | P62: 836
A63: OC-13963 | B63: 46230 | C63: 46177.481 | D63: 3852 | E63: UNION CARTONERA S.R.L | F63: FACTURA ELECTRÓNICA: FT01-00008808 | G63: NI:16990 | H63: 22492 | I63: CO4610 - CORNER PIECE / JGO X 02 UNDS | J63: CBS- | K63: 1 | L63: 1100 | M63: UN | N63: PEN | O63: 1.02 | P63: 1122
A64: OC-13963 | B64: 46230 | C64: 46177.481 | D64: 3852 | E64: UNION CARTONERA S.R.L | F64: FACTURA ELECTRÓNICA: FT01-00008808 | G64: NI:16990 | H64: 22395 | I64: CO4610 - BOX 5PC COMPLEMENT COOK SYSTEM | J64: CBS- | K64: 1 | L64: 1071 | M64: UN | N64: PEN | O64: 9.3 | P64: 9960.3
A65: OC-13963 | B65: 46230 | C65: 46177.481 | D65: 3852 | E65: UNION CARTONERA S.R.L | F65: FACTURA ELECTRÓNICA: FT01-00008808 | G65: NI:16990 | H65: 22398 | I65: CO4610 - CARDBOAR SUPPORT 2 | J65: CBS- | K65: 1 | L65: 1100 | M65: UN | N65: PEN | O65: 0.66 | P65: 726
A66: OC-13963 | B66: 46230 | C66: 46177.481 | D66: 3852 | E66: UNION CARTONERA S.R.L | F66: FACTURA ELECTRÓNICA: FT01-00008808 | G66: NI:16990 | H66: 22400 | I66: CO4610 - CARDBOARD RING TO PROTECT THE LID 20CM | J66: CBS- | K66: 1 | L66: 1100 | M66: UN | N66: PEN | O66: 0.07 | P66: 77
A67: OC-14053 | B67: 46230 | C67: 46225.592 | D67: 3044 | E67: J & L AGROPLASTIC E.I.R.L. | F67: FACTURA ELECTRÓNICA: FPP1-007457 | G67: NI:16991 | H67: 22533 | I67: STRECH FILM (BLACK) | J67: BAG- | K67: 1 | L67: 20 | M67: UN | N67: PEN | O67: 25.424 | P67: 508.48
A68: OC-14041 | B68: 46223 | C68: 46212.362 | D68: 3908 | E68: PACKAGING SERVICE PERU S.A.C | F68: FACTURA ELECTRÓNICA: F001-0005832 | G68: NI:16983 | H68: 22095 | I68: STRECH FILM DE 20" X 12MIC X 2 KG (TRANSPARENT) | J68: BAG- | K68: 1 | L68: 200 | M68: UN | N68: USD | O68: 5.6 | P68: 1120
A69: OC-14031 | B69: 46217 | C69: 46205.478 | D69: 3044 | E69: J & L AGROPLASTIC E.I.R.L. | F69: FACTURA ELECTRÓNICA: FPP1-007423 | G69: NI:16974 | H69: 22533 | I69: STRECH FILM (BLACK) | J69: BAG- | K69: 1 | L69: 12 | M69: UN | N69: PEN | O69: 25.424 | P69: 305.088
A70: OC-14038 | B70: 46212 | C70: 46209.394 | D70: 2098 | E70: IMPORTADORA FERRETERA BONIFAZ S.A.C. | F70: FACTURA ELECTRÓNICA: F001-0024801 | G70: NI:16973 | H70: 241133 | I70: WHEEL ASAFLAP GRANO 40 DE 6" X 1.1/2 X 1" | J70: POLW | K70: 1 | L70: 100 | M70: UN | N70: PEN | O70: 56.7797 | P70: 5677.97
A71: OI-1094 | B71: 46210 | C71: 46050.569 | D71: 2953 | E71: MEYER MANUFACTURING COMPANY LIMITED | F71: INVOICE: 2J260005 | G71: NI:16975 | H71: 19047 | I71: 26CM RIM GASKET - NEW MODEL | J71: GSKT | K71: 1 | L71: 24000 | M71: UN | N71: USD | O71: 2.24 | P71: 53760
A72: OI-1094 | B72: 46210 | C72: 46050.569 | D72: 2953 | E72: MEYER MANUFACTURING COMPANY LIMITED | F72: INVOICE: 2J260005 | G72: NI:16975 | H72: 19046 | I72: 35CM RIM GASKET - NEW MODEL | J72: GSKT | K72: 1 | L72: 11010 | M72: UN | N72: USD | O72: 3.43 | P72: 37764.3
A73: OI-1094 | B73: 46210 | C73: 46050.569 | D73: 2953 | E73: MEYER MANUFACTURING COMPANY LIMITED | F73: INVOICE: 2J260005 | G73: NI:16975 | H73: RP4902 | I73: WHISTLE | J73: uncl | K73: 1 | L73: 55200 | M73: UN | N73: USD | O73: 1.51 | P73: 83352
A74: OI-1095 | B74: 46210 | C74: 46133.436 | D74: 2953 | E74: MEYER MANUFACTURING COMPANY LIMITED | F74: INVOICE: 2J260005 | G74: NI:16976 | H74: 19044 | I74: 26CM DOME COVER RIM GASKET | J74: GSKT | K74: 1 | L74: 1000 | M74: UN | N74: USD | O74: 2.24 | P74: 2240
A75: OC-13842 | B75: 46207 | C75: 46120.425 | D75: 3852 | E75: UNION CARTONERA S.R.L | F75: FACTURA ELECTRÓNICA: FT01-00008714 | G75: NI:16967 | H75: 22439 | I75: CO4801 - BOX 20CM MEDIUM COVER | J75: CBS- | K75: 1 | L75: 2331 | M75: UN | N75: PEN | O75: 3.5 | P75: 8158.5
A76: OC-13842 | B76: 46207 | C76: 46120.425 | D76: 3852 | E76: UNION CARTONERA S.R.L | F76: FACTURA ELECTRÓNICA: FT01-00008714 | G76: NI:16967 | H76: 22445 | I76: CO4802 - BOX 26CM LARGE COVER | J76: CBS- | K76: 1 | L76: 2105 | M76: UN | N76: PEN | O76: 4.3 | P76: 9051.5
A77: OC-14019 | B77: 46207 | C77: 46203.403 | D77: 2098 | E77: IMPORTADORA FERRETERA BONIFAZ S.A.C. | F77: FACTURA ELECTRÓNICA: F001-0024750 | G77: NI:16965 | H77: 241133 | I77: WHEEL ASAFLAP GRANO 40 DE 6" X 1.1/2 X 1" | J77: POLW | K77: 1 | L77: 50 | M77: UN | N77: PEN | O77: 56.7796 | P77: 2838.98
A78: OC-14011 | B78: 46206 | C78: 46196.424 | D78: 98 | E78: CORPORACION DE INDUSTRIAS PLASTICAS S.A. | F78: FACTURA ELECTRÓNICA: F204-62945 | G78: NI:16962 | H78: 22528 | I78: ADHESIVE LABEL 10.16X10.16CM S/IMP | J78: LABL | K78: 1 | L78: 30 | M78: UN | N78: USD | O78: 9 | P78: 270
...

Sheet IVR032
A1: COMPANY | B1: INVOICE | C1: PRO_INVOICE | D1: INV_DATE | E1: MAX_INV | F1: CUST_ID | G1: CUST_NAME | H1: PART_ID | I1: PART_DESC | J1: COMM_CODE | K1: QTY | L1: UNIT_PRICE | M1: PRIME_COST | N1: MATL_COST | O1: LABOR_COST | P1: MATL_BRDN | Q1: LABOR_BRDN | R1: SUBCONCOST | S1: CURR | T1: DIV | U1: RATE | V1: SALESHKD | W1: PRIMEHKD | X1: MATLHKD | Y1: LABORHKD | Z1: MATBRDNHKD | AA1: LBRBRDNHKD | AB1: SUBCONHKD | AC1: CONTHKD | AD1: CONTPER | AE1: REGION | AF1: DESCR | AG1: FAMILY | AH1: BRAND | AI1: NO_OF_PANS | AJ1: INTR_CODE | AK1: VEND_ID | AL1: VEND_NAME | AM1: PO_CURR | AN1: LST_RCP_PR | AO1: SO_NO | AP1: SO_LINE | AQ1: PO_NO | AR1: PO_LINE | AS1: CUS_PO_NBR | AT1: SHIP_CODE | AU1: COUNTRY | AV1: MFGC_CODE | AW1: MFGC_DESC | AX1: MAZAL_PART_ID
A2: MHK | B2: 7J260001 | D2: 46025 | F2: M074 | G2: MAZAL CORP. S.A. | H2: 7-5-MAZAL00005 | I2: SHDL FOR 4QT DUTCH OVEN & 20cm/8 IN SKILLET | J2: SHDL | K2: 21000 | L2: 2.11 | M2: 12.8544 | N2: 12.8544 | O2: 0 | P2: 0 | Q2: 0 | R2: 0 | S2: USD | T2: 7J | U2: 7.8 | V2: 345618 | W2: 269942.4 | X2: 269942.4 | Y2: 0 | Z2: 0 | AA2: 0 | AB2: 0 | AC2: 75675.6 | AD2: 21.8957 | AE2: 4F | AF2: S-HDL FOR 4QT DUTCH OVEN&20CM/8" SKILLET MAZAL NO.RP4905 | AI2: 0 | AK2: Z012 | AL2: ZHAOQING SILVERSTONE TRADING CO., LTD. | AM2: USD | AN2: 1.648 | AO2: 60272 | AP2: 1 | AQ2: 1010215 | AR2: 1 | AS2: NRO.1092-MAZAL | AT2: DM074-0001 | AU2: PERU | AV2: FICSR | AW2: FICSR | AX2: =IF($G2="MAZAL CORP. S.A.",IF(ISNUMBER(VALUE(RIGHT($AF2,5))),RIGHT($AF2,5),RIGHT($AF2,6)),"") -> RP4905
A3: MHK | B3: 7J260001 | D3: 46025 | F3: M074 | G3: MAZAL CORP. S.A. | H3: 7-5-MAZAL00007 | I3: SHDL FOR 6QT & 8QT D.OVEN & 26cm/10.5 IN SKILLET | J3: SHDL | K3: 10 | L3: 2.11 | M3: 12.8544 | N3: 12.8544 | O3: 0 | P3: 0 | Q3: 0 | R3: 0 | S3: USD | T3: 7J | U3: 7.8 | V3: 164.58 | W3: 128.544 | X3: 128.544 | Y3: 0 | Z3: 0 | AA3: 0 | AB3: 0 | AC3: 36.036 | AD3: 21.8957 | AE3: 4F | AF3: S-HDL FOR 6QT&8QT D.OVEN&26CM/10.5" SKILLET MAZAL NO.RP4907 | AI3: 0 | AK3: Z012 | AL3: ZHAOQING SILVERSTONE TRADING CO., LTD. | AM3: USD | AN3: 1.648 | AO3: 60272 | AP3: 2 | AQ3: 1010215 | AR3: 2 | AS3: NRO.1092-MAZAL | AT3: DM074-0001 | AU3: PERU | AV3: FICSR | AW3: FICSR | AX3: =IF($G3="MAZAL CORP. S.A.",IF(ISNUMBER(VALUE(RIGHT($AF3,5))),RIGHT($AF3,5),RIGHT($AF3,6)),"") -> RP4907
A4: MHK | B4: 7J260001 | D4: 46025 | F4: M074 | G4: MAZAL CORP. S.A. | H4: 7-5-MAZAL00007 | I4: SHDL FOR 6QT & 8QT D.OVEN & 26cm/10.5 IN SKILLET | J4: SHDL | K4: 10990 | L4: 2.11 | M4: 12.8544 | N4: 12.8544 | O4: 0 | P4: 0 | Q4: 0 | R4: 0 | S4: USD | T4: 7J | U4: 7.8 | V4: 180873.42 | W4: 141269.86 | X4: 141269.86 | Y4: 0 | Z4: 0 | AA4: 0 | AB4: 0 | AC4: 39603.564 | AD4: 21.8957 | AE4: 4F | AF4: S-HDL FOR 6QT&8QT D.OVEN&26CM/10.5" SKILLET MAZAL NO.RP4907 | AI4: 0 | AK4: Z012 | AL4: ZHAOQING SILVERSTONE TRADING CO., LTD. | AM4: USD | AN4: 1.648 | AO4: 60272 | AP4: 2 | AQ4: 1010215 | AR4: 2 | AS4: NRO.1092-MAZAL | AT4: DM074-0001 | AU4: PERU | AV4: FICSR | AW4: FICSR | AX4: =IF($G4="MAZAL CORP. S.A.",IF(ISNUMBER(VALUE(RIGHT($AF4,5))),RIGHT($AF4,5),RIGHT($AF4,6)),"") -> RP4907
A5: MHK | B5: 7J260001 | D5: 46025 | F5: M074 | G5: MAZAL CORP. S.A. | H5: 7-5-MAZAL00014 | I5: SHDL FOR 10IN PAELLA PAN | J5: SHDL | K5: 50 | L5: 2.11 | M5: 12.8544 | N5: 12.8544 | O5: 0 | P5: 0 | Q5: 0 | R5: 0 | S5: USD | T5: 7J | U5: 7.8 | V5: 822.9 | W5: 642.72 | X5: 642.72 | Y5: 0 | Z5: 0 | AA5: 0 | AB5: 0 | AC5: 180.18 | AD5: 21.8957 | AE5: 4F | AF5: SIDE HANDLE FOR 10" PAELLA PAN MAZAL NO.RP4921 | AI5: 0 | AK5: Z012 | AL5: ZHAOQING SILVERSTONE TRADING CO., LTD. | AM5: USD | AN5: 1.648 | AO5: 60272 | AP5: 3 | AQ5: 1010215 | AR5: 3 | AS5: NRO.1092-MAZAL | AT5: DM074-0001 | AU5: PERU | AV5: FICSR | AW5: FICSR | AX5: =IF($G5="MAZAL CORP. S.A.",IF(ISNUMBER(VALUE(RIGHT($AF5,5))),RIGHT($AF5,5),RIGHT($AF5,6)),"") -> RP4921
A6: MHK | B6: 7J260001 | D6: 46025 | F6: M074 | G6: MAZAL CORP. S.A. | H6: 7-5-MAZAL00014 | I6: SHDL FOR 10IN PAELLA PAN | J6: SHDL | K6: 40950 | L6: 2.11 | M6: 12.8544 | N6: 12.8544 | O6: 0 | P6: 0 | Q6: 0 | R6: 0 | S6: USD | T6: 7J | U6: 7.8 | V6: 673955.1 | W6: 526387.68 | X6: 526387.68 | Y6: 0 | Z6: 0 | AA6: 0 | AB6: 0 | AC6: 147567.42 | AD6: 21.8957 | AE6: 4F | AF6: SIDE HANDLE FOR 10" PAELLA PAN MAZAL NO.RP4921 | AI6: 0 | AK6: Z012 | AL6: ZHAOQING SILVERSTONE TRADING CO., LTD. | AM6: USD | AN6: 1.648 | AO6: 60272 | AP6: 3 | AQ6: 1010215 | AR6: 3 | AS6: NRO.1092-MAZAL | AT6: DM074-0001 | AU6: PERU | AV6: FICSR | AW6: FICSR | AX6: =IF($G6="MAZAL CORP. S.A.",IF(ISNUMBER(VALUE(RIGHT($AF6,5))),RIGHT($AF6,5),RIGHT($AF6,6)),"") -> RP4921
A7: MHK | B7: 7J260002 | D7: 46025 | F7: M074 | G7: MAZAL CORP. S.A. | H7: 7-5-MAZAL00006 | I7: HDL FOR 26cm/10.5 IN SKILLET | J7: HDL- | K7: 30 | L7: 3.45 | M7: 23.7284 | N7: 23.7284 | O7: 0 | P7: 0 | Q7: 0 | R7: 0 | S7: USD | T7: 7J | U7: 7.8 | V7: 807.3 | W7: 711.852 | X7: 711.852 | Y7: 0 | Z7: 0 | AA7: 0 | AB7: 0 | AC7: 95.448 | AD7: 11.8231 | AE7: 4F | AF7: HANDLE FOR 26CM/10.5" SKILLET MAZAL NO.RP4906 | AI7: 0 | AK7: Z012 | AL7: ZHAOQING SILVERSTONE TRADING CO., LTD. | AM7: USD | AN7: 3.0421 | AO7: 60273 | AP7: 2 | AQ7: 1010216 | AR7: 2 | AS7: NRO.1092-MAZAL | AT7: DM074-0001 | AU7: PERU | AV7: FICSR | AW7: FICSR | AX7: =IF($G7="MAZAL CORP. S.A.",IF(ISNUMBER(VALUE(RIGHT($AF7,5))),RIGHT($AF7,5),RIGHT($AF7,6)),"") -> RP4906
A8: MHK | B8: 7J260002 | D8: 46025 | F8: M074 | G8: MAZAL CORP. S.A. | H8: 7-5-MAZAL00006 | I8: HDL FOR 26cm/10.5 IN SKILLET | J8: HDL- | K8: 2970 | L8: 3.45 | M8: 23.7284 | N8: 23.7284 | O8: 0 | P8: 0 | Q8: 0 | R8: 0 | S8: USD | T8: 7J | U8: 7.8 | V8: 79922.7 | W8: 70473.348 | X8: 70473.348 | Y8: 0 | Z8: 0 | AA8: 0 | AB8: 0 | AC8: 9449.352 | AD8: 11.8231 | AE8: 4F | AF8: HANDLE FOR 26CM/10.5" SKILLET MAZAL NO.RP4906 | AI8: 0 | AK8: Z012 | AL8: ZHAOQING SILVERSTONE TRADING CO., LTD. | AM8: USD | AN8: 3.0421 | AO8: 60273 | AP8: 2 | AQ8: 1010216 | AR8: 2 | AS8: NRO.1092-MAZAL | AT8: DM074-0001 | AU8: PERU | AV8: FICSR | AW8: FICSR | AX8: =IF($G8="MAZAL CORP. S.A.",IF(ISNUMBER(VALUE(RIGHT($AF8,5))),RIGHT($AF8,5),RIGHT($AF8,6)),"") -> RP4906
A9: MHK | B9: 7J260002 | D9: 46025 | F9: M074 | G9: MAZAL CORP. S.A. | H9: 7-5-MAZAL00004 | I9: HDL FOR 3QT SAUCEPAN & 20cm/8 IN SKILLET | J9: HDL- | K9: 9000 | L9: 3.45 | M9: 23.7284 | N9: 23.7284 | O9: 0 | P9: 0 | Q9: 0 | R9: 0 | S9: USD | T9: 7J | U9: 7.8 | V9: 242190 | W9: 213555.6 | X9: 213555.6 | Y9: 0 | Z9: 0 | AA9: 0 | AB9: 0 | AC9: 28634.4 | AD9: 11.8231 | AE9: 4F | AF9: HDL FOR 3QT SAUCE PAN&20CM/8" SKILLET MAZAL NO.RP4904 | AI9: 0 | AK9: Z012 | AL9: ZHAOQING SILVERSTONE TRADING CO., LTD. | AM9: USD | AN9: 3.0421 | AO9: 60273 | AP9: 1 | AQ9: 1010216 | AR9: 1 | AS9: NRO.1092-MAZAL | AT9: DM074-0001 | AU9: PERU | AV9: FICSR | AW9: FICSR | AX9: =IF($G9="MAZAL CORP. S.A.",IF(ISNUMBER(VALUE(RIGHT($AF9,5))),RIGHT($AF9,5),RIGHT($AF9,6)),"") -> RP4904
A10: MHK | B10: 7J260003 | D10: 46066 | F10: M074 | G10: MAZAL CORP. S.A. | H10: 7-5-MAZAL00007 | I10: SHDL FOR 6QT & 8QT D.OVEN & 26cm/10.5 IN SKILLET | J10: SHDL | K10: 20 | L10: 2.11 | M10: 12.8544 | N10: 12.8544 | O10: 0 | P10: 0 | Q10: 0 | R10: 0 | S10: USD | T10: 7J | U10: 7.8 | V10: 329.16 | W10: 257.088 | X10: 257.088 | Y10: 0 | Z10: 0 | AA10: 0 | AB10: 0 | AC10: 72.072 | AD10: 21.8957 | AE10: 4F | AF10: S-HDL FOR 6QT&8QT D.OVEN&26CM/10.5" SKILLET MAZAL NO.RP4907 | AI10: 0 | AK10: Z012 | AL10: ZHAOQING SILVERSTONE TRADING CO., LTD. | AM10: USD | AN10: 1.648 | AO10: 60876 | AP10: 1 | AQ10: 1010819 | AR10: 1 | AS10: NRO.1093-MAZAL | AT10: DM074-0001 | AU10: PERU | AV10: FICSR | AW10: FICSR | AX10: =IF($G10="MAZAL CORP. S.A.",IF(ISNUMBER(VALUE(RIGHT($AF10,5))),RIGHT($AF10,5),RIGHT($AF10,6)),"") -> RP4907
A11: MHK | B11: 7J260003 | D11: 46066 | F11: M074 | G11: MAZAL CORP. S.A. | H11: 7-5-MAZAL00007 | I11: SHDL FOR 6QT & 8QT D.OVEN & 26cm/10.5 IN SKILLET | J11: SHDL | K11: 7980 | L11: 2.11 | M11: 12.8544 | N11: 12.8544 | O11: 0 | P11: 0 | Q11: 0 | R11: 0 | S11: USD | T11: 7J | U11: 7.8 | V11: 131334.84 | W11: 102578.11 | X11: 102578.11 | Y11: 0 | Z11: 0 | AA11: 0 | AB11: 0 | AC11: 28756.728 | AD11: 21.8957 | AE11: 4F | AF11: S-HDL FOR 6QT&8QT D.OVEN&26CM/10.5" SKILLET MAZAL NO.RP4907 | AI11: 0 | AK11: Z012 | AL11: ZHAOQING SILVERSTONE TRADING CO., LTD. | AM11: USD | AN11: 1.648 | AO11: 60876 | AP11: 1 | AQ11: 1010819 | AR11: 1 | AS11: NRO.1093-MAZAL | AT11: DM074-0001 | AU11: PERU | AV11: FICSR | AW11: FICSR | AX11: =IF($G11="MAZAL CORP. S.A.",IF(ISNUMBER(VALUE(RIGHT($AF11,5))),RIGHT($AF11,5),RIGHT($AF11,6)),"") -> RP4907
A12: MHK | B12: 2J260001 | D12: 46075 | F12: M074 | G12: MAZAL CORP. S.A. | H12: 7-6-MAZAL00003 | I12: 20CM RIM GASKET | J12: GSKT | K12: 5430 | L12: 1.86 | M12: 13.416 | N12: 13.416 | O12: 0 | P12: 0 | Q12: 0 | R12: 0 | S12: USD | T12: 2J | U12: 7.8 | V12: 78778.44 | W12: 72848.88 | X12: 72848.88 | Y12: 0 | Z12: 0 | AA12: 0 | AB12: 0 | AC12: 5929.56 | AD12: 7.5268 | AE12: 4F | AF12: 20CM RIM GASKET MAZAL NO.19042 | AI12: 0 | AK12: A039 | AL12: AXA INTERNATIONAL LTD. | AM12: USD | AN12: 1.72 | AO12: 60874 | AP12: 2 | AQ12: 1010817 | AR12: 2 | AS12: NRO.1093-MAZAL | AT12: DM074-0001 | AU12: PERU | AV12: COGKS | AW12: COGKS | AX12: =IF($G12="MAZAL CORP. S.A.",IF(ISNUMBER(VALUE(RIGHT($AF12,5))),RIGHT($AF12,5),RIGHT($AF12,6)),"") -> 19042
A13: MHK | B13: 2J260001 | D13: 46075 | F13: M074 | G13: MAZAL CORP. S.A. | H13: 7-6-MAZAL00004 | I13: 26CM RIM GASKET | J13: GSKT | K13: 3000 | L13: 2.24 | M13: 16.302 | N13: 16.302 | O13: 0 | P13: 0 | Q13: 0 | R13: 0 | S13: USD | T13: 2J | U13: 7.8 | V13: 52416 | W13: 48906 | X13: 48906 | Y13: 0 | Z13: 0 | AA13: 0 | AB13: 0 | AC13: 3510 | AD13: 6.6964 | AE13: 4F | AF13: 26CM RIM GASKET MAZAL NO.19043 | AI13: 0 | AK13: A039 | AL13: AXA INTERNATIONAL LTD. | AM13: USD | AN13: 2.09 | AO13: 60874 | AP13: 3 | AQ13: 1010817 | AR13: 3 | AS13: NRO.1093-MAZAL | AT13: DM074-0001 | AU13: PERU | AV13: COGKS | AW13: COGKS | AX13: =IF($G13="MAZAL CORP. S.A.",IF(ISNUMBER(VALUE(RIGHT($AF13,5))),RIGHT($AF13,5),RIGHT($AF13,6)),"") -> 19043
... A79: MHK | B79: 2J260007 | D79: 46231 | F79: M074 | G79: MAZAL CORP. S.A. | H79: 7-9-MAZAL24992 | I79: EXCLUSIVE DILUENT OIL (DRAW-WN501) | J79: MISC | K79: 26 | L79: 231.58 | M79: 1716 | N79: 1716 | O79: 0 | P79: 0 | Q79: 0 | R79: 0 | S79: USD | T79: 2J | U79: 7.8 | V79: 46964.424 | W79: 44616 | X79: 44616 | Y79: 0 | Z79: 0 | AA79: 0 | AB79: 0 | AC79: 2348.424 | AD79: 5.0004 | AE79: 4F | AF79: EXCLUSIVE DILUENT OIL (DRAW-WN501) MAZAL NO.24992 | AI79: 0 | AK79: N020 | AL79: NIC INTERNATIONAL CO., LTD. | AM79: USD | AN79: 220 | AO79: 62079 | AP79: 1 | AQ79: 1012021 | AR79: 1 | AS79: NRO.1098-MAZAL | AT79: DM074-0001 | AU79: PERU | AV79: COOTH | AW79: COOTH | AX79: =IF($G79="MAZAL CORP. S.A.",IF(ISNUMBER(VALUE(RIGHT($AF79,5))),RIGHT($AF79,5),RIGHT($AF79,6)),"") -> 24992

Sheet Hoja1 (2)
A2: Product Family Description.xls ------ received from Anthony Man (These lines provide the closest description)
A3: ProdFamilyCode | B3: ProdFamilyDesc | C3: ProdFamilyHandleCode | D3: ProdFamilySideHdlCode | E3: ProdFamilyLidHdlCode | F3: ProdFamilyKnobCode | G3: CreateTS | H3: CreateUser | I3: LstUpdTS | J3: LstUpdUser | K3: ProdFamilyDesc
A4: RPC | B4: ROYAL PRESTIGE 5-PLY CLAD | C4: DG | D4: DG | F4: DG | G4: 2003-07-17 | H4: WILLIAM | I4: 2004-04-23 | J4: cmchan | K4: ROYAL PRESTIGE 5-PLY CLAD
A5: RPS | B5: ROYAL PRESTIGE SS | C5: DG | D5: DG | F5: DG | G5: 2003-07-17 | H5: WILLIAM | I5: 2011-01-28 | J5: cmchan | K5: ROYAL PRESTIGE SS
A7: MAZALCORP S.A. ------- OUR DATA INFO
A8: PROD FAMILY DESC | B8: PROD FAMILY DESC | C8: CODE IN MMC | D8: CODE IN MAZALCORP | E8: DESCRIPTION
A9: RPC | B9: ROYAL PRESTIGE 5-PLY CLAD | C9: 35015-R | D9: CO4600 | E9: ESSENTIAL COOK SYSTEM - 5PC
A10: RPC | B10: ROYAL PRESTIGE 5-PLY CLAD | C10: 35016-R | D10: CO4610 | E10: COMPLEMENT C/S - 5PC SET
A11: RPC | B11: ROYAL PRESTIGE 5-PLY CLAD | C11: 35017-R | D11: CO4620 | E11: CLASSIC COOKING SYST - 7PC
A12: RPC | B12: ROYAL PRESTIGE 5-PLY CLAD | C12: 35019-R | D12: CO4640 | E12: FAMILY COOKING SYSTM - 10PC
A13: RPC | B13: ROYAL PRESTIGE 5-PLY CLAD | C13: 35020-R | D13: CO4680 | E13: SPECIAL COOKING SYST - 8PC
A14: RPC | B14: ROYAL PRESTIGE 5-PLY CLAD | C14: 35003-R | D14: CO4700 | E14: 1.5QT/16CM SAUCEPAN ONLY
A15: RPC | B15: ROYAL PRESTIGE 5-PLY CLAD | C15: 35004-R | D15: CO4705 | E15: 2 QT/16CM SAUCEPAN ONLY
A16: RPC | B16: ROYAL PRESTIGE 5-PLY CLAD | C16: 35005-R | D16: CO4710 | E16: 3 QT/20CM SAUCEPAN ONLY
A17: RPC | B17: ROYAL PRESTIGE 5-PLY CLAD | C17: 35011-R | D17: CO4715 | E17: 4 QT/20CM DTCH OVN WITH COVER
A18: RPC | B18: ROYAL PRESTIGE 5-PLY CLAD | C18: 35006-R | D18: CO4720 | E18: 6 QT/26CM DUTCH OVN ONLY
A19: RPC | B19: ROYAL PRESTIGE 5-PLY CLAD | C19: 35012-R | D19: CO4725 | E19: 8 QT/26CM DTCH OVN WITH COVER
... A33: RPS | B33: ROYAL PRESTIGE SS | C33: 78038-R | D33: CO4808 | E33: 26CM SR STEAMER/COLANDR
C34: ='IVR032'!H2 -> 7-5-MAZAL00005 | D34: ='IVR032'!AX2 -> RP4905 | E34: ='IVR032'!I2 -> SHDL FOR 4QT DUTCH OVEN & 20cm/8 IN SKILLET
C35: ='IVR032'!H3 -> 7-5-MAZAL00007 | D35: ='IVR032'!AX3 -> RP4907 | E35: ='IVR032'!I3 -> SHDL FOR 6QT & 8QT D.OVEN & 26cm/10.5 IN SKILLET
C36: ='IVR032'!H4 -> 7-5-MAZAL00007 | D36: ='IVR032'!AX4 -> RP4907 | E36: ='IVR032'!I4 -> SHDL FOR 6QT & 8QT D.OVEN & 26cm/10.5 IN SKILLET
C37: ='IVR032'!H5 -> 7-5-MAZAL00014 | D37: ='IVR032'!AX5 -> RP4921 | E37: ='IVR032'!I5 -> SHDL FOR 10IN PAELLA PAN
C38: ='IVR032'!H6 -> 7-5-MAZAL00014 | D38: ='IVR032'!AX6 -> RP4921 | E38: ='IVR032'!I6 -> SHDL FOR 10IN PAELLA PAN
C39: ='IVR032'!H7 -> 7-5-MAZAL00006 | D39: ='IVR032'!AX7 -> RP4906 | E39: ='IVR032'!I7 -> HDL FOR 26cm/10.5 IN SKILLET
C40: ='IVR032'!H8 -> 7-5-MAZAL00006 | D40: ='IVR032'!AX8 -> RP4906 | E40: ='IVR032'!I8 -> HDL FOR 26cm/10.5 IN SKILLET
C41: ='IVR032'!H9 -> 7-5-MAZAL00004 | D41: ='IVR032'!AX9 -> RP4904 | E41: ='IVR032'!I9 -> HDL FOR 3QT SAUCEPAN & 20cm/8 IN SKILLET
C42: ='IVR032'!H10 -> 7-5-MAZAL00007 | D42: ='IVR032'!AX10 -> RP4907 | E42: ='IVR032'!I10 -> SHDL FOR 6QT & 8QT D.OVEN & 26cm/10.5 IN SKILLET
C43: ='IVR032'!H11 -> 7-5-MAZAL00007 | D43: ='IVR032'!AX11 -> RP4907 | E43: ='IVR032'!I11 -> SHDL FOR 6QT & 8QT D.OVEN & 26cm/10.5 IN SKILLET
C44: ='IVR032'!H12 -> 7-6-MAZAL00003 | D44: ='IVR032'!AX12 -> 19042 | E44: ='IVR032'!I12 -> 20CM RIM GASKET
C45: ='IVR032'!H13 -> 7-6-MAZAL00004 | D45: ='IVR032'!AX13 -> 19043 | E45: ='IVR032'!I13 -> 26CM RIM GASKET
... C111: ='IVR032'!H79 -> 7-9-MAZAL24992 | D111: ='IVR032'!AX79 -> 24992 | E111: ='IVR032'!I79 -> EXCLUSIVE DILUENT OIL (DRAW-WN501)

Sheet Product Family (2)
A1: ProdFamilyCode | B1: ProdFamilyDesc | C1: ProdFamilyHandleCode | D1: ProdFamilySideHdlCode | E1: ProdFamilyLidHdlCode | F1: ProdFamilyKnobCode | G1: CreateTS | H1: CreateUser | I1: LstUpdTS | J1: LstUpdUser | K1: ProdFamilyDesc
A2: A03 | B2: ANOLON RAYMOND BLANC BY ANOLON OVEN TO TABLE | G2: 2010-03-23 | H2: wfcheng | I2: 2014-07-09 | J2: wfcheng | K2: ANOLON RAYMOND BLANC BY ANOLON OVEN TO TABLE
A3: A04 | B3: ANOLON RAYMOND BLANC BY ANOLON MOCHA | C3: IG | D3: IG | E3: IG | G3: 2011-10-13 | H3: wfcheng | K3: ANOLON RAYMOND BLANC BY ANOLON MOCHA
A4: A1F | B4: PAULA DEEN ALUM EXCESS | G4: 2015-07-08 | H4: wfcheng | I4: 2015-07-08 | J4: wfcheng | K4: PAULA DEEN ALUM EXCESS
A5: A2F | B5: FARBERWARE ALUM EXCESS | G5: 2015-07-08 | H5: wfcheng | I5: 2015-07-08 | J5: wfcheng | K5: FARBERWARE ALUM EXCESS
A6: A2M | B6: RACHAEL RAY ALUM EXCESS | G6: 2015-07-08 | H6: wfcheng | I6: 2015-07-08 | J6: wfcheng | K6: RACHAEL RAY ALUM EXCESS
A7: A3M | B7: ANOLON HA EXCESS | G7: 2015-07-08 | H7: wfcheng | I7: 2015-07-08 | J7: wfcheng | K7: ANOLON HA EXCESS
A8: A5F | B8: FARBERWARE SS EXCESS | G8: 2015-07-08 | H8: wfcheng | I8: 2015-07-08 | J8: wfcheng | K8: FARBERWARE SS EXCESS
A9: A7F | B9: SILVERSTONE AAP EXCESS | G9: 2015-07-08 | H9: wfcheng | I9: 2015-07-08 | J9: wfcheng | K9: SILVERSTONE AAP EXCESS
A10: A7M | B10: CIRCULON HA EXCESS | G10: 2015-07-08 | H10: wfcheng | I10: 2015-07-08 | J10: wfcheng | K10: CIRCULON HA EXCESS
A11: AAA | B11: ANOLON SURE GRIP KNIVES | G11: 2014-08-26 | H11: wfcheng | I11: 2018-07-04 | J11: MSCWFCHENG | K11: ANOLON SURE GRIP KNIVES
A12: AAB | B12: ANOLON GOURMET BAKEWARE | G12: 2003-05-10 | H12: WILLIAM | I12: 2017-04-21 | J12: wfcheng | K12: ANOLON GOURMET BAKEWARE
A13: AAC | B13: ANOLON MISC | C13: BU | D13: BU | E13: BU | G13: 2002-10-03 | H13: WILLIAM | I13: 2010-08-04 | J13: cmchan | K13: ANOLON MISC
A14: AAD | B14: ANOLON ADVANCED CLAD | C14: DG | D14: DG | E14: DG | G14: 2002-11-29 | H14: WILLIAM | I14: 2010-08-04 | J14: cmchan | K14: ANOLON ADVANCED CLAD
A15: AAE | B15: ANOLON ADVANCED BRONZE | C15: DG | D15: DG | E15: DG | G15: 2008-01-11 | H15: wfcheng | I15: 2010-08-04 | J15: cmchan | K15: ANOLON ADVANCED BRONZE
A16: AAF | B16: ANOLON ADVANCED BRONZE TOOLS & GADGETS | G16: 2009-02-05 | H16: wfcheng | I16: 2014-07-09 | J16: wfcheng | K16: ANOLON ADVANCED BRONZE TOOLS & GADGETS
A17: AAG | B17: ANOLON ADVANCED BRONZE CUTLERY | G17: 2009-04-21 | H17: wfcheng | I17: 2014-07-09 | J17: wfcheng | K17: ANOLON ADVANCED BRONZE CUTLERY
A18: AAH | B18: ANOLON ADVANCED HD HA CLAD | C18: DG | D18: DG | E18: DG | G18: 2004-02-19 | H18: WILLIAM | I18: 2010-08-04 | J18: cmchan | K18: ANOLON ADVANCED HD HA CLAD
A19: AAI | B19: ANOLON ADVANCED BAKEWARE | G19: 2009-04-28 | H19: wfcheng | I19: 2014-07-09 | J19: wfcheng | K19: ANOLON ADVANCED BAKEWARE
A20: AAJ | B20: ANOLON CAST IRON | G20: 2011-04-29 | H20: wfcheng | I20: 2014-07-09 | J20: wfcheng | K20: ANOLON CAST IRON
A21: AAK | B21: ANOLON ADVANCED TRIPLY BRONZE | C21: DG | D21: DG | E21: DG | G21: 2017-05-04 | H21: wfcheng | I21: 2021-06-24 | J21: MSCCMCHAN | K21: ANOLON ADVANCED TRIPLY BRONZE
A22: AAL | B22: ANOLON ADVANCED TRIPLY ONYX | C22: DG | D22: DG | E22: DG | G22: 2017-05-04 | H22: wfcheng | I22: 2021-06-24 | J22: MSCCMCHAN | K22: ANOLON ADVANCED TRIPLY ONYX
A23: AAM | B23: ANOLON AUTHORITY MULTI-PLY | C23: PS | D23: PS | E23: PS | G23: 2014-04-17 | H23: wfcheng | I23: 2014-07-09 | J23: wfcheng | K23: ANOLON AUTHORITY MULTI-PLY
A24: AAN | B24: ANOLON AUTHORITY HARD ANODIZED | C24: PS | D24: PS | E24: PS | G24: 2014-04-17 | H24: wfcheng | I24: 2014-07-09 | J24: wfcheng | K24: ANOLON AUTHORITY HARD ANODIZED
A25: AAO | B25: ANOLON ADVANCED ONYX | C25: DG | D25: DG | E25: DG | G25: 2016-10-11 | H25: wfcheng | I25: 2021-06-24 | J25: MSCCMCHAN | K25: ANOLON ADVANCED ONYX
A26: AAP | B26: ANOLON ADVANCED PEWTER | C26: DG | D26: DG | E26: DG | G26: 2013-12-19 | H26: wfcheng | I26: 2014-07-09 | J26: wfcheng | K26: ANOLON ADVANCED PEWTER
A27: AAQ | B27: ANOLON ADVANCED HOME MOONSTONE | C27: DG | D27: DG | E27: DG | G27: 2018-10-03 | H27: MSCWFCHENG | I27: 2019-01-09 | J27: MSCWFCHENG | K27: ANOLON ADVANCED HOME MOONSTONE
A28: AAR | B28: ANOLON ADVANCED HOME BRONZE | C28: DG | D28: DG | E28: DG | G28: 2018-10-03 | H28: MSCWFCHENG | I28: 2019-01-09 | J28: MSCWFCHENG | K28: ANOLON ADVANCED HOME BRONZE
A29: AAS | B29: ANOLON ADVANCED HOME ONYX | C29: DG | D29: DG | E29: DG | G29: 2018-10-03 | H29: MSCWFCHENG | I29: 2019-01-09 | J29: MSCWFCHENG | K29: ANOLON ADVANCED HOME ONYX
A30: AAT | B30: ANOLON ADVANCED HOME INDIGO | C30: DG | D30: DG | E30: DG | G30: 2018-10-03 | H30: MSCWFCHENG | I30: 2019-01-09 | J30: MSCWFCHENG | K30: ANOLON ADVANCED HOME INDIGO
A31: AAU | B31: ANOLON ADVANCED UMBER | C31: DG | D31: DG | E31: DG | G31: 2013-12-24 | H31: wfcheng | I31: 2014-07-09 | J31: wfcheng | K31: ANOLON ADVANCED UMBER
A32: AAV | B32: ANOLON ADVANCED | C32: DG | D32: DG | E32: DG | G32: 2002-05-08 | H32: PMCHOI | I32: 2010-08-04 | J32: cmchan | K32: ANOLON ADVANCED
A33: AAW | B33: ANOLON ALWAYSSHARP™ KNIVES | C33: - | D33: - | E33: - | F33: - | G33: 2019-06-20 | H33: MSCWFCHENG | K33: ANOLON ALWAYSSHARP™ KNIVES
A34: AAX | B34: ANOLON ADVANCED + ONYX | C34: DG | D34: DG | E34: DG | G34: 2017-01-04 | H34: wfcheng | I34: 2017-09-05 | J34: wfcheng | K34: ANOLON ADVANCED + ONYX
A35: AAY | B35: ANOLON ADVANCED + UMBER | C35: DG | D35: DG | E35: DG | G35: 2017-03-22 | H35: wfcheng | K35: ANOLON ADVANCED + UMBER
A36: AAZ | B36: ANOLON ADVANCED INDIGO | C36: DG | D36: DG | E36: DG | G36: 2017-09-05 | H36: wfcheng | I36: 2021-06-24 | J36: MSCCMCHAN | K36: ANOLON ADVANCED INDIGO
A37: ABA | B37: ANOLON ADVANCED CERAMIC | C37: DG | D37: DG | E37: DG | G37: 2024-05-23 | H37: MSCWFCHENG | I37: 2024-06-24 | J37: MSCWFCHENG | K37: ANOLON ADVANCED CERAMIC
A38: ACA | B38: ANOLON COMMERCIAL HA NS | C38: BU | G38: 2003-07-18 | H38: WILLIAM | I38: 2010-11-06 | J38: cmchan | K38: ANOLON COMMERCIAL HA NS
A39: ACB | B39: ANOLON COMMERCIAL BAKEWARE | G39: 2005-04-06 | H39: WILLIAM | I39: 2014-07-09 | J39: wfcheng | K39: ANOLON COMMERCIAL BAKEWARE
A40: ACC | B40: ANOLON COMMERCIAL CLAD | C40: BU | D40: BU | E40: BU | G40: 2002-11-29 | H40: WILLIAM | I40: 2010-08-04 | J40: cmchan | K40: ANOLON COMMERCIAL CLAD
...

Sheet Hoja3
A1: Purchase Order Number | B1: Purchase Order Date | C1: Purchase order issue date | D1: Vendor ID | E1: VendorName | F1: Vendor_Invoice_No | G1: REF_NO | H1: Item Code | I1: Part Description | J1: Commodity | K1: Division | L1: Quantity | M1: Unit | N1: PO_Price_PO CUR | O1: PO UNIT PRICE PO_CUR | P1: Total_PO_Price_PO CUR
A2: OI-1085 | B2: 45748 | C2: 45622.617 | D2: 2953 | E2: MEYER MANUFACTURING COMPANY LIMITED | F2: INVOICE: 2J250001 | G2: NI:16299 | H2: 19047 | I2: 26CM RIM GASKET - NEW MODEL | J2: GSKT | K2: 1 | L2: 25000 | M2: UN | N2: USD | O2: 2.24 | P2: 56000
A3: OC-13103 | B3: 45768 | C3: 45629.454 | D3: 3580 | E3: GEOLINK PERU E.I.R.L. | F3: FACTURA ELECTRÓNICA: E001-116 | G3: NI:16343 | H3: 23351 | I3: STAINLESS STEEL DISC 5PLY Ø270*3MM SS316L - CO4700 | J3: SM-- | K3: 1 | L3: 1775.6 | M3: KG | N3: USD | O3: 4.125 | P3: 7324.35
A4: OC-13103 | B4: 45768 | C4: 45629.454 | D4: 3580 | E4: GEOLINK PERU E.I.R.L. | F4: FACTURA ELECTRÓNICA: E001-116 | G4: NI:16343 | H4: 23363 | I4: STAINLESS STEEL DISC 5PLY Ø365*3MM SS316L - CO4761 | J4: SM-- | K4: 1 | L4: 11392 | M4: KG | N4: USD | O4: 7.372 | P4: 83981.824
A5: OC-13103 | B5: 45768 | C5: 45629.454 | D5: 3580 | E5: GEOLINK PERU E.I.R.L. | F5: FACTURA ELECTRÓNICA: E001-116 | G5: NI:16343 | H5: 23354 | I5: STAINLESS STEEL DISC 5PLY Ø365*3MM SS316L - CO4716 | J5: SM-- | K5: 1 | L5: 8738.52 | M5: KG | N5: USD | O5: 7.645 | P5: 66805.985
A6: OC-13103 | B6: 45768 | C6: 45629.454 | D6: 3580 | E6: GEOLINK PERU E.I.R.L. | F6: FACTURA ELECTRÓNICA: E001-116 | G6: NI:16343 | H6: 23376 | I6: STAINLESS STEEL DISC SINGLE PLY Ø205*1MM SS304-2B - CO4800 | J6: SM-- | K6: 1 | L6: 2032 | M6: KG | N6: USD | O6: 0.76 | P6: 1544.32
A7: OC-13103 | B7: 45775 | C7: 45629.454 | D7: 3580 | E7: GEOLINK PERU E.I.R.L. | F7: FACTURA ELECTRÓNICA: E001-116 | G7: NI:16345 | H7: 23377 | I7: STAINLESS STEEL DISC SINGLE PLY Ø250*1MM SS304-2B - CO4801 | J7: SM-- | K7: 1 | L7: 6785.1 | M7: KG | N7: USD | O7: 1.14 | P7: 7735.014
A8: OC-13103 | B8: 45775 | C8: 45629.454 | D8: 3580 | E8: GEOLINK PERU E.I.R.L. | F8: FACTURA ELECTRÓNICA: E001-116 | G8: NI:16345 | H8: 23354 | I8: STAINLESS STEEL DISC 5PLY Ø365*3MM SS316L - CO4716 | J8: SM-- | K8: 1 | L8: 4239.48 | M8: KG | N8: USD | O8: 7.645 | P8: 32410.825
A9: OC-13103 | B9: 45775 | C9: 45629.454 | D9: 3580 | E9: GEOLINK PERU E.I.R.L. | F9: FACTURA ELECTRÓNICA: E001-116 | G9: NI:16345 | H9: 23357 | I9: STAINLESS STEEL DISC 5PLY Ø305*3MM SS316L - CO4730 | J9: SM-- | K9: 1 | L9: 3625.446 | M9: KG | N9: USD | O9: 5.212 | P9: 18895.825
A10: OC-13103 | B10: 45775 | C10: 45629.454 | D10: 3580 | E10: GEOLINK PERU E.I.R.L. | F10: FACTURA ELECTRÓNICA: E001-116 | G10: NI:16345 | H10: 23363 | I10: STAINLESS STEEL DISC 5PLY Ø365*3MM SS316L - CO4761 | J10: SM-- | K10: 1 | L10: 4272 | M10: KG | N10: USD | O10: 7.372 | P10: 31493.184
A11: OC-13103 | B11: 45775 | C11: 45629.454 | D11: 3580 | E11: GEOLINK PERU E.I.R.L. | F11: FACTURA ELECTRÓNICA: E001-116 | G11: NI:16345 | H11: 23372 | I11: STAINLESS STEEL DISC 1PLY SS316L Ø335*1.0 - CO4807 | J11: SM-- | K11: 1 | L11: 664 | M11: KG | N11: USD | O11: 4.1 | P11: 2722.4
A12: OC-13103 | B12: 45775 | C12: 45629.454 | D12: 3580 | E12: GEOLINK PERU E.I.R.L. | F12: FACTURA ELECTRÓNICA: E001-116 | G12: NI:16345 | H12: 23352 | I12: STAINLESS STEEL DISC 5PLY Ø290*3MM SS316L - CO4705 | J12: SM-- | K12: 1 | L12: 441 | M12: KG | N12: USD | O12: 4.654 | P12: 2052.414
A13: OC-13103 | B13: 45803 | C13: 45629.454 | D13: 3580 | E13: GEOLINK PERU E.I.R.L. | F13: FACTURA ELECTRÓNICA: E001-122 | G13: NI:16379 | H13: 23363 | I13: STAINLESS STEEL DISC 5PLY Ø365*3MM SS316L - CO4761 | J13: SM-- | K13: 1 | L13: 7120 | M13: KG | N13: USD | O13: 7.372 | P13: 52488.64
... A20: OC-13103 | B20: 45838 | C20: 45629.454 | D20: 3580 | E20: GEOLINK PERU E.I.R.L. | F20: FACTURA ELECTRÓNICA: E001-128 | G20: NI:16409 | H20: 23377 | I20: STAINLESS STEEL DISC SINGLE PLY Ø250*1MM SS304-2B - CO4801 | J20: SM-- | K20: 1 | L20: 757.89 | M20: KG | N20: USD | O20: 1.14 | P20: 863.9946
A21: OI-1086 | B21: 45728 | C21: 45631.677 | D21: 2953 | E21: MEYER MANUFACTURING COMPANY LIMITED | F21: INVOICE: 2J250002 | G21: NI:16279 | H21: RP4905 | I21: SIDE HANDLE FOR 4QT DUTCH OVEN AND 20CM/8" SKILLET | J21: SHDL | K21: 1 | L21: 12530 | M21: UN | N21: USD | O21: 2.23 | P21: 27941.9
A22: OI-1086 | B22: 45733 | C22: 45631.677 | D22: 2953 | E22: MEYER MANUFACTURING COMPANY LIMITED | F22: INVOICE: 2J250003 | G22: NI:16283 | H22: RP4903 | I22: HANDLE FOR 1.5QT AND 2QT SAUCE PAN | J22: HDL- | K22: 1 | L22: 1900 | M22: UN | N22: USD | O22: 3.71 | P22: 7049
A23: OI-1086 | B23: 45733 | C23: 45631.677 | D23: 2953 | E23: MEYER MANUFACTURING COMPANY LIMITED | F23: INVOICE: 2J250003 | G23: NI:16283 | H23: RP4900 | I23: MEDIUM OVER MOLDED KNOB | J23: KNOB | K23: 1 | L23: 4840 | M23: UN | N23: USD | O23: 2.13 | P23: 10309.2
A24: OI-1086 | B24: 45748 | C24: 45631.677 | D24: 2953 | E24: MEYER MANUFACTURING COMPANY LIMITED | F24: INVOICE: 2J250001 | G24: NI:16300 | H24: 19041 | I24: 16CM RIM GASKET | J24: GSKT | K24: 1 | L24: 7000 | M24: UN | N24: USD | O24: 1.61 | P24: 11270
A25: OI-1086 | B25: 45748 | C25: 45631.677 | D25: 2953 | E25: MEYER MANUFACTURING COMPANY LIMITED | F25: INVOICE: 2J250001 | G25: NI:16300 | H25: RP4902 | I25: WHISTLE | J25: uncl | K25: 1 | L25: 10000 | M25: UN | N25: USD | O25: 1.51 | P25: 15100
A26: OI-1086 | B26: 45748 | C26: 45631.677 | D26: 2953 | E26: MEYER MANUFACTURING COMPANY LIMITED | F26: INVOICE: 2J250001 | G26: NI:16300 | H26: 19042 | I26: 20CM RIM GASKET | J26: GSKT | K26: 1 | L26: 16000 | M26: UN | N26: USD | O26: 1.86 | P26: 29760
A27: OI-1086 | B27: 45770 | C27: 45631.677 | D27: 2953 | E27: MEYER MANUFACTURING COMPANY LIMITED | F27: INVOICE: 7J250001 | G27: NI:16327 | H27: RP4921 | I27: SIDE HANDLE FOR 10" PAELLA PAN | J27: SHDL | K27: 1 | L27: 15000 | M27: UN | N27: USD | O27: 2.23 | P27: 33450
A28: OI-1086 | B28: 45779 | C28: 45631.677 | D28: 2953 | E28: MEYER MANUFACTURING COMPANY LIMITED | F28: INVOICE: 2J250005 | G28: NI:16341 | H28: RP4902 | I28: WHISTLE | J28: uncl | K28: 1 | L28: 18000 | M28: UN | N28: USD | O28: 1.51 | P28: 27180
A29: OI-1086 | B29: 45785 | C29: 45631.677 | D29: 2953 | E29: MEYER MANUFACTURING COMPANY LIMITED | F29: INVOICE: 2J250004 | G29: NI:16352 | H29: RP4900 | I29: MEDIUM OVER MOLDED KNOB | J29: KNOB | K29: 1 | L29: 20160 | M29: UN | N29: USD | O29: 2.13 | P29: 42940.8
A30: OI-1086 | B30: 45785 | C30: 45631.677 | D30: 2953 | E30: MEYER MANUFACTURING COMPANY LIMITED | F30: INVOICE: 2J250004 | G30: NI:16352 | H30: RP4903 | I30: HANDLE FOR 1.5QT AND 2QT SAUCE PAN | J30: HDL- | K30: 1 | L30: 6100 | M30: UN | N30: USD | O30: 3.71 | P30: 22631
A31: OI-1086 | B31: 45790 | C31: 45631.677 | D31: 2953 | E31: MEYER MANUFACTURING COMPANY LIMITED | F31: INVOICE: 7J250002 | G31: NI:16357 | H31: RP4905 | I31: SIDE HANDLE FOR 4QT DUTCH OVEN AND 20CM/8" SKILLET | J31: SHDL | K31: 1 | L31: 12470 | M31: UN | N31: USD | O31: 2.23 | P31: 27808.1
A32: OI-1086 | B32: 45790 | C32: 45631.677 | D32: 2953 | E32: MEYER MANUFACTURING COMPANY LIMITED | F32: INVOICE: 7J250002 | G32: NI:16357 | H32: RP4921 | I32: SIDE HANDLE FOR 10" PAELLA PAN | J32: SHDL | K32: 1 | L32: 15000 | M32: UN | N32: USD | O32: 2.23 | P32: 33450
A33: OI-1086 | B33: 45790 | C33: 45631.677 | D33: 2953 | E33: MEYER MANUFACTURING COMPANY LIMITED | F33: INVOICE: 7J250003 | G33: NI:16358 | H33: RP4904 | I33: HANDLE FOR 3QT SAUCE PAN AND 20CM/8 INCH SKILLET | J33: HDL- | K33: 1 | L33: 6000 | M33: UN | N33: USD | O33: 3.85 | P33: 23100
A34: OC-13108 | B34: 45665 | C34: 45637.578 | D34: 203 | E34: INGENIERIA EN CARTONES Y PAPELES S.A.C. | F34: FACTURA ELECTRÓNICA: F001-00073688 | G34: NI:16209 | H34: 22398 | I34: CO4610 - CARDBOAR SUPPORT 2 | J34: CBS- | K34: 1 | L34: 1980 | M34: UN | N34: USD | O34: 0.951 | P34: 1882.98
A35: OC-13108 | B35: 45665 | C35: 45637.578 | D35: 203 | E35: INGENIERIA EN CARTONES Y PAPELES S.A.C. | F35: FACTURA ELECTRÓNICA: F001-00073688 | G35: NI:16209 | H35: 22399 | I35: CO4610 - CARDBOARD SHEET FOR TOP COVERING - 5PC CCS | J35: CBS- | K35: 1 | L35: 2085 | M35: UN | N35: USD | O35: 0.245 | P35: 510.825
A36: OC-13108 | B36: 45665 | C36: 45637.578 | D36: 203 | E36: INGENIERIA EN CARTONES Y PAPELES S.A.C. | F36: FACTURA ELECTRÓNICA: F001-00073688 | G36: NI:16209 | H36: 22397 | I36: CO4610 - CARDBOAR SUPPORT 1 | J36: CBS- | K36: 1 | L36: 1980 | M36: UN | N36: USD | O36: 0.224 | P36: 443.52
A37: OC-13108 | B37: 45665 | C37: 45637.578 | D37: 203 | E37: INGENIERIA EN CARTONES Y PAPELES S.A.C. | F37: FACTURA ELECTRÓNICA: F001-00073688 | G37: NI:16209 | H37: 22396 | I37: CO4610 - BOTTOM CARDBOARD PROTECTOR FOR 5PC C.C.S. | J37: CBS- | K37: 1 | L37: 1870 | M37: UN | N37: USD | O37: 0.439 | P37: 820.93
A38: OC-13108 | B38: 45670 | C38: 45637.578 | D38: 203 | E38: INGENIERIA EN CARTONES Y PAPELES S.A.C. | F38: FACTURA ELECTRÓNICA: F001-00073898 | G38: NI:16212 | H38: 22395 | I38: CO4610 - BOX 5PC COMPLEMENT COOK SYSTEM | J38: CBS- | K38: 1 | L38: 1660 | M38: UN | N38: USD | O38: 4.632 | P38: 7689.12
A39: OC-13108 | B39: 45670 | C39: 45637.578 | D39: 203 | E39: INGENIERIA EN CARTONES Y PAPELES S.A.C. | F39: FACTURA ELECTRÓNICA: F001-00073898 | G39: NI:16212 | H39: 22492 | I39: CO4610 - CORNER PIECE / JGO X 02 UNDS | J39: CBS- | K39: 1 | L39: 1760 | M39: UN | N39: USD | O39: 0.18 | P39: 316.8
A40: OC-13108 | B40: 45670 | C40: 45637.578 | D40: 203 | E40: INGENIERIA EN CARTONES Y PAPELES S.A.C. | F40: FACTURA ELECTRÓNICA: F001-00073898 | G40: NI:16212 | H40: 22400 | I40: CO4610 - CARDBOARD RING TO PROTECT THE LID 20CM | J40: CBS- | K40: 1 | L40: 1650 | M40: UN | N40: USD | O40: 0.153 | P40: 252.45
A41: OC-13108 | B41: 45670 | C41: 45637.578 | D41: 203 | E41: INGENIERIA EN CARTONES Y PAPELES S.A.C. | F41: FACTURA ELECTRÓNICA: F001-00073898 | G41: NI:16212 | H41: 22403 | I41: CO4705 - CARDBOARD SUPPORT PIECE FOR/HANDLE | J41: CBS- | K41: 1 | L41: 1100 | M41: UN | N41: USD | O41: 0.2 | P41: 220
A42: OC-13108 | B42: 45670 | C42: 45637.578 | D42: 203 | E42: INGENIERIA EN CARTONES Y PAPELES S.A.C. | F42: FACTURA ELECTRÓNICA: F001-00073898 | G42: NI:16212 | H42: 22411 | I42: CO4720 - BOX 6QT/26CM DUTCH OVN ONLY | J42: CBS- | K42: 1 | L42: 1844 | M42: UN | N42: USD | O42: 2.886 | P42: 5321.784
A43: OC-13108 | B43: 45670 | C43: 45637.578 | D43: 203 | E43: INGENIERIA EN CARTONES Y PAPELES S.A.C. | F43: FACTURA ELECTRÓNICA: F001-00073898 | G43: NI:16212 | H43: 22412 | I43: CO4720 - CORNER PIECE 6QT/26CM DUTCH OVN ONLY - JGO X 2 UNDS | J43: CBS- | K43: 1 | L43: 2100 | M43: UN | N43: USD | O43: 0.192 | P43: 403.2
A44: OC-13108 | B44: 45670 | C44: 45637.578 | D44: 203 | E44: INGENIERIA EN CARTONES Y PAPELES S.A.C. | F44: FACTURA ELECTRÓNICA: F001-00073898 | G44: NI:16212 | H44: 22439 | I44: CO4801 - BOX 20CM MEDIUM COVER | J44: CBS- | K44: 1 | L44: 2200 | M44: UN | N44: USD | O44: 1.494 | P44: 3286.8
A45: OC-13108 | B45: 45670 | C45: 45637.578 | D45: 203 | E45: INGENIERIA EN CARTONES Y PAPELES S.A.C. | F45: FACTURA ELECTRÓNICA: F001-00073898 | G45: NI:16212 | H45: 22445 | I45: CO4802 - BOX 26CM LARGE COVER | J45: CBS- | K45: 1 | L45: 2490 | M45: UN | N45: USD | O45: 1.747 | P45: 4350.03
... A135: OI-1087 | B135: 45832 | C135: 45706.621 | D135: 2953 | E135: MEYER MANUFACTURING COMPANY LIMITED | F135: INVOICE: 2J250006 | G135: NI:16402 | H135: 19041 | I135: 16CM RIM GASKET | J135: GSKT | K135: 1 | L135: 6000 | M135: UN | N135: USD | O135: 1.61 | P135: 9660
...
